Workbook

Sheet Confidential
E1: 0 | H1: 4.75 | J1: 11.65
B2: Moulded | C2: Flush | F2: Moulded | H2: Conmore | J2: Flat Moulded | L2: Flush
A3: Size | B3: HC Slabs | E3: Size | F3: HC Slabs | H3: HC Slabs | J3: HC Slabs | L3: HC Slabs
A4: 12 | B4: 61.3 | C4: 50.9 | E4: 12 | F4: =MROUND(B4*(1+$E$1),0.05) -> 61.3 | H4: =F4+$H$1 -> 66.05 | J4: =F4+$J$1 -> 72.95 | L4: =MROUND(C4*(1+$E$1),0.05) -> 50.9
A5: 14 | B5: 61.3 | C5: 50.9 | E5: 14 | F5: =MROUND(B5*(1+$E$1),0.05) -> 61.3 | H5: =F5+$H$1 -> 66.05 | J5: =F5+$J$1 -> 72.95 | L5: =MROUND(C5*(1+$E$1),0.05) -> 50.9
A6: 16 | B6: 61.3 | C6: 50.9 | E6: 16 | F6: =MROUND(B6*(1+$E$1),0.05) -> 61.3 | H6: =F6+$H$1 -> 66.05 | J6: =F6+$J$1 -> 72.95 | L6: =MROUND(C6*(1+$E$1),0.05) -> 50.9
A7: 18 | B7: 61.3 | C7: 50.9 | E7: 18 | F7: =MROUND(B7*(1+$E$1),0.05) -> 61.3 | H7: =F7+$H$1 -> 66.05 | J7: =F7+$J$1 -> 72.95 | L7: =MROUND(C7*(1+$E$1),0.05) -> 50.9
A8: 20 | B8: 64.65 | C8: 52.05 | E8: 20 | F8: =MROUND(B8*(1+$E$1),0.05) -> 64.65 | H8: =F8+$H$1 -> 69.4 | J8: =F8+$J$1 -> 76.3 | L8: =MROUND(C8*(1+$E$1),0.05) -> 52.05
A9: 22 | B9: 64.65 | C9: 52.05 | E9: 22 | F9: =MROUND(B9*(1+$E$1),0.05) -> 64.65 | H9: =F9+$H$1 -> 69.4 | J9: =F9+$J$1 -> 76.3 | L9: =MROUND(C9*(1+$E$1),0.05) -> 52.05
A10: 24 | B10: 64.65 | C10: 52.05 | E10: 24 | F10: =MROUND(B10*(1+$E$1),0.05) -> 64.65 | H10: =F10+$H$1 -> 69.4 | J10: =F10+$J$1 -> 76.3 | L10: =MROUND(C10*(1+$E$1),0.05) -> 52.05
A11: 26 | B11: 67 | C11: 55.45 | E11: 26 | F11: =MROUND(B11*(1+$E$1),0.05) -> 67 | H11: =F11+$H$1 -> 71.75 | J11: =F11+$J$1 -> 78.65 | L11: =MROUND(C11*(1+$E$1),0.05) -> 55.45
A12: 28 | B12: 67 | C12: 55.45 | E12: 28 | F12: =MROUND(B12*(1+$E$1),0.05) -> 67 | H12: =F12+$H$1 -> 71.75 | J12: =F12+$J$1 -> 78.65 | L12: =MROUND(C12*(1+$E$1),0.05) -> 55.45
A13: 30 | B13: 67 | C13: 55.45 | E13: 30 | F13: =MROUND(B13*(1+$E$1),0.05) -> 67 | H13: =F13+$H$1 -> 71.75 | J13: =F13+$J$1 -> 78.65 | L13: =MROUND(C13*(1+$E$1),0.05) -> 55.45
A14: 32 | B14: 69.3 | C14: 57.4 | E14: 32 | F14: =MROUND(B14*(1+$E$1),0.05) -> 69.3 | H14: =F14+$H$1 -> 74.05 | J14: =F14+$J$1 -> 80.95 | L14: =MROUND(C14*(1+$E$1),0.05) -> 57.4
A15: 34 | B15: 72.7 | C15: 62.2 | E15: 34 | F15: =MROUND(B15*(1+$E$1),0.05) -> 72.7 | H15: =F15+$H$1 -> 77.45 | J15: =F15+$J$1 -> 84.35 | L15: =MROUND(C15*(1+$E$1),0.05) -> 62.2
A16: 36 | B16: 72.7 | C16: 62.2 | E16: 36 | F16: =MROUND(B16*(1+$E$1),0.05) -> 72.7 | H16: =F16+$H$1 -> 77.45 | J16: =F16+$J$1 -> 84.35 | L16: =MROUND(C16*(1+$E$1),0.05) -> 62.2
A17: 38 | B17: 100.6 | C17: 89.9 | E17: 38 | F17: =MROUND(B17*(1+$E$1),0.05) -> 100.6 | H17: N/A | J17: N/A | L17: =MROUND(C17*(1+$E$1),0.05) -> 89.9
D18: Adder | E18: HEIGHT 84" HC | F18: 30.75 | H18: =F18 -> 30.75 | J18: =F18 -> 30.75 | L18: 30.75
D19: Adder | E19: HEIGHT 96" HC | F19: 85.35 | H19: =F19 -> 85.35 | J19: =F19 -> 85.35 | L19: 73.15
D20: Adder | E20: 1 3/8 SC 80'' | F20: 88 | H20: =F20 -> 88 | J20: =F20 -> 88 | L20: 65.2
D21: Adder | E21: 1 3/8 SC 84'' | F21: 104.4 | H21: =F21 -> 104.4 | J21: =F21 -> 104.4 | L21: 84.25
D22: Adder | E22: 1 3/8 SC 96'' | F22: 196.1 | H22: =F22 -> 196.1 | J22: =F22 -> 196.1 | L22: 131.45
D23: Adder | E23: 1 3/4 HC 80" | F23: 31.8 | H23: N/A | J23: N/A | L23: 30.75
D24: Adder | E24: 1 3/4 HC 84" | F24: 36.55 | H24: N/A | J24: N/A | L24: 36.55
D25: Add for Easy-IN 4-9/16 MDF to HC/SC | F25: 65.7 | H25: =F25 -> 65.7 | J25: =F25 -> 65.7 | L25: 65.7
D26: Add for Prehung 4-9/16 FJP to HC/SC | F26: 79.5 | H26: =F26 -> 79.5 | J26: =F26 -> 79.5 | L26: 79.5
F28: Moulded | H28: Conmore | J28: Flat Moulded | L28: Flush
B29: Bifolds (with hard.) | E29: Size | F29: Bifolds (w hard.) | H29: Bifolds (w hard.) | J29: Bifolds (w hard.) | L29: Bifolds (w hard.)
A30: 18 | B30: 78.45 | C30: 71.3 | E30: 18 | F30: =MROUND((B30+$B$41)*(1+$E$1),0.05) -> 78.45 | H30: =F30+$H$1 -> 83.2 | J30: =F30+$J$1 -> 90.1 | L30: =MROUND((C30+$B$41)*(1+$E$1),0.05) -> 71.3
A31: 20 | B31: 78.45 | C31: 71.3 | E31: 20 | F31: =MROUND((B31+$B$41)*(1+$E$1),0.05) -> 78.45 | H31: =F31+$H$1 -> 83.2 | J31: =F31+$J$1 -> 90.1 | L31: =MROUND((C31+$B$41)*(1+$E$1),0.05) -> 71.3
A32: 22 | B32: 78.45 | C32: 71.3 | E32: 22 | F32: =MROUND((B32+$B$41)*(1+$E$1),0.05) -> 78.45 | H32: =F32+$H$1 -> 83.2 | J32: =F32+$J$1 -> 90.1 | L32: =MROUND((C32+$B$41)*(1+$E$1),0.05) -> 71.3
A33: 24 | B33: 78.45 | C33: 71.3 | E33: 24 | F33: =MROUND((B33+$B$41)*(1+$E$1),0.05) -> 78.45 | H33: =F33+$H$1 -> 83.2 | J33: =F33+$J$1 -> 90.1 | L33: =MROUND((C33+$B$41)*(1+$E$1),0.05) -> 71.3
A34: 26 | B34: 86.45 | C34: 77.2 | E34: 26 | F34: =MROUND((B34+$B$41)*(1+$E$1),0.05) -> 86.45 | H34: =F34+$H$1 -> 91.2 | J34: =F34+$J$1 -> 98.1 | L34: =MROUND((C34+$B$41)*(1+$E$1),0.05) -> 77.2
A35: 28 | B35: 86.45 | C35: 77.2 | E35: 28 | F35: =MROUND((B35+$B$41)*(1+$E$1),0.05) -> 86.45 | H35: =F35+$H$1 -> 91.2 | J35: =F35+$J$1 -> 98.1 | L35: =MROUND((C35+$B$41)*(1+$E$1),0.05) -> 77.2
A36: 30 | B36: 86.45 | C36: 77.2 | E36: 30 | F36: =MROUND((B36+$B$41)*(1+$E$1),0.05) -> 86.45 | H36: =F36+$H$1 -> 91.2 | J36: =F36+$J$1 -> 98.1 | L36: =MROUND((C36+$B$41)*(1+$E$1),0.05) -> 77.2
A37: 32 | B37: 91.5 | C37: 82.65 | E37: 32 | F37: =MROUND((B37+$B$41)*(1+$E$1),0.05) -> 91.5 | H37: =F37+$H$1 -> 96.25 | J37: =F37+$J$1 -> 103.15 | L37: =MROUND((C37+$B$41)*(1+$E$1),0.05) -> 82.65
A38: 34 | B38: 91.5 | C38: 82.65 | E38: 34 | F38: =MROUND((B38+$B$41)*(1+$E$1),0.05) -> 91.5 | H38: =F38+$H$1 -> 96.25 | J38: =F38+$J$1 -> 103.15 | L38: =MROUND((C38+$B$41)*(1+$E$1),0.05) -> 82.65
A39: 36 | B39: 91.5 | C39: 82.65 | E39: 36 | F39: =MROUND((B39+$B$41)*(1+$E$1),0.05) -> 91.5 | H39: =F39+$H$1 -> 96.25 | J39: =F39+$J$1 -> 103.15 | L39: =MROUND((C39+$B$41)*(1+$E$1),0.05) -> 82.65
D40: Adder | E40: HEIGHT 84" | F40: =F18 -> 30.75 | H40: =F40 -> 30.75 | J40: =F40 -> 30.75 | L40: =L18 -> 30.75
A41: Hard | D41: Adder | E41: HEIGHT 96" | F41: =F19 -> 85.35 | H41: N/A | J41: =F41 -> 85.35 | L41: =L19 -> 73.15
...

Sheet Molded
B2: NET PRICE LIST (April 4, 2025)
B3: Customer Name & Number
B4: AA-Dealer Central
B12: SLAB | C12: COLONIST TEXT | D12: CAMDEN | E12: PRIMED HARDB
B13: 12" | C13: =Confidential!F4 -> 61.3 | D13: =C13 -> 61.3 | E13: =Confidential!L4 -> 50.9
B14: 14" | C14: =Confidential!F5 -> 61.3 | D14: =C14 -> 61.3 | E14: =Confidential!L5 -> 50.9
B15: 16" | C15: =Confidential!F6 -> 61.3 | D15: =C15 -> 61.3 | E15: =Confidential!L6 -> 50.9
B16: 18" | C16: =Confidential!F7 -> 61.3 | D16: =C16 -> 61.3 | E16: =Confidential!L7 -> 50.9
B18: 20" | C18: =Confidential!F8 -> 64.65 | D18: =C18 -> 64.65 | E18: =Confidential!L8 -> 52.05
B19: 22" | C19: =Confidential!F9 -> 64.65 | D19: =C19 -> 64.65 | E19: =Confidential!L9 -> 52.05
B20: 24" | C20: =Confidential!F10 -> 64.65 | D20: =C20 -> 64.65 | E20: =Confidential!L10 -> 52.05
B22: 26" | C22: =Confidential!F11 -> 67 | D22: =C22 -> 67 | E22: =Confidential!L11 -> 55.45
B23: 28" | C23: =Confidential!F12 -> 67 | D23: =C23 -> 67 | E23: =Confidential!L12 -> 55.45
B24: 30" | C24: =Confidential!F13 -> 67 | D24: =C24 -> 67 | E24: =Confidential!L13 -> 55.45
B26: 32" | C26: =Confidential!F14 -> 69.3 | D26: =C26 -> 69.3 | E26: =Confidential!L14 -> 57.4
B27: 34" | C27: =Confidential!F15 -> 72.7 | D27: =C27 -> 72.7 | E27: =Confidential!L15 -> 62.2
B28: 36" | C28: =Confidential!F16 -> 72.7 | D28: =C28 -> 72.7 | E28: =Confidential!L16 -> 62.2
B29: 38" | C29: N/A | D29: N/A | E29: =Confidential!L17 -> 89.9
A30: ** | B30: HEIGHT 84" HC Add only | C30: =Confidential!F18 -> 30.75 | D30: N/A | E30: =Confidential!L18 -> 30.75
A31: ** | B31: HEIGHT 96" HC Add only | C31: =Confidential!F19 -> 85.35 | D31: N/A | E31: =Confidential!L19 -> 73.15
A32: ** | B32: 1 3/8 SC 80'' Add only | C32: =Confidential!F20 -> 88 | D32: =C32 -> 88 | E32: =Confidential!L20 -> 65.2
A33: ** | B33: 1 3/8 SC 84'' Add only | C33: =Confidential!F21 -> 104.4 | D33: N/A | E33: =Confidential!L21 -> 84.25
A34: ** | B34: 1 3/8 SC 96'' Add only | C34: =Confidential!F22 -> 196.1 | D34: N/A | E34: =Confidential!L22 -> 131.45
A35: ** | B35: 1 3/4 HC 80" Add only | C35: =Confidential!F23 -> 31.8 | D35: =C35 -> 31.8 | E35: =Confidential!L23 -> 30.75
A36: ** | B36: 1 3/4 HC 84" Add only | C36: =Confidential!F24 -> 36.55 | D36: N/A | E36: =Confidential!L24 -> 36.55
A37: Add for Easy-IN 4-9/16 MDF to HC/SC | C37: =Confidential!F25 -> 65.7 | D37: =C37 -> 65.7 | E37: =C37 -> 65.7
A38: Add for Prehung 4-9/16 FJP to HC/SC | C38: =Confidential!F26 -> 79.5 | D38: =C38 -> 79.5 | E38: =C38 -> 79.5
B40: BIFOLDS c/w Hard. | C40: COLONIST TEXT | D40: CAMDEN | E40: PRIMED HARDB
B41: 24" | C41: =Confidential!F33 -> 78.45 | D41: =C41 -> 78.45 | E41: =Confidential!L33 -> 71.3
B42: 26" | C42: =Confidential!F34 -> 86.45 | D42: =C42 -> 86.45 | E42: =Confidential!L34 -> 77.2
B43: 28" | C43: =Confidential!F35 -> 86.45 | D43: =C43 -> 86.45 | E43: =Confidential!L35 -> 77.2
B44: 30" | C44: =Confidential!F36 -> 86.45 | D44: =C44 -> 86.45 | E44: =Confidential!L36 -> 77.2
B46: 32" | C46: =Confidential!F37 -> 91.5 | D46: =C46 -> 91.5 | E46: =Confidential!L37 -> 82.65
B47: 34" | C47: =Confidential!F38 -> 91.5 | D47: =C47 -> 91.5 | E47: =Confidential!L38 -> 82.65
B48: 36" | C48: =Confidential!F39 -> 91.5 | D48: =C48 -> 91.5 | E48: =Confidential!L39 -> 82.65
A49: ** | B49: HEIGHT 84" | C49: =Confidential!F40 -> 30.75 | D49: N/A | E49: =Confidential!L40 -> 30.75
A50: ** | B50: HEIGHT 96" | C50: =Confidential!F41 -> 85.35 | D50: N/A | E50: =Confidential!L41 -> 73.15
B52: 1-3/4 SC | C52: COLONIST TEXT | D52: CAMDEN | E52: PRIMED HARDB
B53: 18" | C53: =Confidential!F45 -> 188.5 | D53: =C53 -> 188.5 | E53: =Confidential!L45 -> 136.25
B54: 20" to 24" | C54: =Confidential!F46 -> 191.85 | D54: =C54 -> 191.85 | E54: =Confidential!L46 -> 137.4
...

Sheet Molded 2
B2: =Molded!B2:E2 -> NET PRICE LIST (April 4, 2025)
B3: =Molded!B3:E3 -> Customer Name & Number
B4: =Molded!B4:E4 -> AA-Dealer Central
B12: SLAB | C12: CARRARA | D12: ROCKPORT | E12: SANTA FE
B13: 12" | C13: =Molded!C13 -> 61.3 | D13: =Molded!C13 -> 61.3 | E13: =Molded!C13 -> 61.3
B14: 14" | C14: =Molded!C14 -> 61.3 | D14: =Molded!C14 -> 61.3 | E14: =Molded!C14 -> 61.3
B15: 16" | C15: =Molded!C15 -> 61.3 | D15: =Molded!C15 -> 61.3 | E15: =Molded!C15 -> 61.3
B16: 18" | C16: =Molded!C16 -> 61.3 | D16: =Molded!C16 -> 61.3 | E16: =Molded!C16 -> 61.3
B18: 20" | C18: =Molded!C18 -> 64.65 | D18: =Molded!C18 -> 64.65 | E18: =Molded!C18 -> 64.65
B19: 22" | C19: =Molded!C19 -> 64.65 | D19: =Molded!C19 -> 64.65 | E19: =Molded!C19 -> 64.65
B20: 24" | C20: =Molded!C20 -> 64.65 | D20: =Molded!C20 -> 64.65 | E20: =Molded!C20 -> 64.65
B22: 26" | C22: =Molded!C22 -> 67 | D22: =Molded!C22 -> 67 | E22: =Molded!C22 -> 67
B23: 28" | C23: =Molded!C23 -> 67 | D23: =Molded!C23 -> 67 | E23: =Molded!C23 -> 67
B24: 30" | C24: =Molded!C24 -> 67 | D24: =Molded!C24 -> 67 | E24: =Molded!C24 -> 67
B26: 32" | C26: =Molded!C26 -> 69.3 | D26: =Molded!C26 -> 69.3 | E26: =Molded!C26 -> 69.3
B27: 34" | C27: =Molded!C27 -> 72.7 | D27: =Molded!C27 -> 72.7 | E27: =Molded!C27 -> 72.7
B28: 36" | C28: =Molded!C28 -> 72.7 | D28: =Molded!C28 -> 72.7 | E28: =Molded!C28 -> 72.7
B29: 38" Euro | C29: =Confidential!F17 -> 100.6 | D29: =Molded!C29 -> N/A | E29: =Molded!C29 -> N/A
A30: ** | B30: =Molded!B30 -> HEIGHT 84" HC Add only | C30: =Molded!C30 -> 30.75 | D30: =Molded!C30 -> 30.75 | E30: =Molded!C30 -> 30.75
A31: ** | B31: =Molded!B31 -> HEIGHT 96" HC Add only | C31: =Molded!C31 -> 85.35 | D31: =Molded!C31 -> 85.35 | E31: =Molded!C31 -> 85.35
A32: ** | B32: =Molded!B32 -> 1 3/8 SC 80'' Add only | C32: =Molded!C32 -> 88 | D32: =Molded!C32 -> 88 | E32: =Molded!C32 -> 88
A33: ** | B33: =Molded!B33 -> 1 3/8 SC 84'' Add only | C33: =Molded!C33 -> 104.4 | D33: =Molded!C33 -> 104.4 | E33: =Molded!C33 -> 104.4
A34: ** | B34: =Molded!B34 -> 1 3/8 SC 96'' Add only | C34: =Molded!C34 -> 196.1 | D34: =Molded!C34 -> 196.1 | E34: =Molded!C34 -> 196.1
A35: ** | B35: =Molded!B35 -> 1 3/4 HC 80" Add only | C35: =Molded!C35 -> 31.8 | D35: =Molded!C35 -> 31.8 | E35: =Molded!C35 -> 31.8
A36: ** | B36: =Molded!B36 -> 1 3/4 HC 84" Add only | C36: =Molded!C36 -> 36.55 | D36: =Molded!C36 -> 36.55 | E36: =Molded!C36 -> 36.55
A37: =Molded!A37 -> Add for Easy-IN 4-9/16 MDF to HC/SC | C37: =Molded!C37 -> 65.7 | D37: =Molded!C37 -> 65.7 | E37: =Molded!C37 -> 65.7
A38: =Molded!A38 -> Add for Prehung 4-9/16 FJP to HC/SC | C38: =Molded!C38 -> 79.5 | D38: =Molded!C38 -> 79.5 | E38: =Molded!C38 -> 79.5
B40: =Molded!B40 -> BIFOLDS c/w Hard. | C40: CARRARA | D40: ROCKPORT | E40: SANTA FE
B41: 24" | C41: =Molded!C41 -> 78.45 | D41: =Molded!C41 -> 78.45 | E41: =Molded!C41 -> 78.45
B42: 26" | C42: =Molded!C42 -> 86.45 | D42: =Molded!C42 -> 86.45 | E42: =Molded!C42 -> 86.45
B43: 28" | C43: =Molded!C43 -> 86.45 | D43: =Molded!C43 -> 86.45 | E43: =Molded!C43 -> 86.45
B44: 30" | C44: =Molded!C44 -> 86.45 | D44: =Molded!C44 -> 86.45 | E44: =Molded!C44 -> 86.45
B46: 32" | C46: =Molded!C46 -> 91.5 | D46: =Molded!C46 -> 91.5 | E46: =Molded!C46 -> 91.5
B47: 34" | C47: =Molded!C47 -> 91.5 | D47: =Molded!C47 -> 91.5 | E47: =Molded!C47 -> 91.5
B48: 36" | C48: =Molded!C48 -> 91.5 | D48: =Molded!C48 -> 91.5 | E48: =Molded!C48 -> 91.5
A49: ** | B49: =Molded!B49 -> HEIGHT 84" | C49: =Molded!C49 -> 30.75 | D49: =Molded!C49 -> 30.75 | E49: =Molded!C49 -> 30.75
A50: ** | B50: =Molded!B50 -> HEIGHT 96" | C50: =Molded!C50 -> 85.35 | D50: =Molded!C50 -> 85.35 | E50: =Molded!C50 -> 85.35
B52: =Molded!B52 -> 1-3/4 SC | C52: CARRARA | D52: ROCKPORT | E52: SANTA FE
B53: =Molded!B53 -> 18" | C53: =Molded!C53 -> 188.5 | D53: =Molded!C53 -> 188.5 | E53: =Molded!C53 -> 188.5
B54: =Molded!B54 -> 20" to 24" | C54: =Molded!C54 -> 191.85 | D54: =Molded!C54 -> 191.85 | E54: =Molded!C54 -> 191.85
...

Sheet Flat Panel
B2: =Molded!B2:E2 -> NET PRICE LIST (April 4, 2025)
B3: =Molded!B3:E3 -> Customer Name & Number
B4: =Molded!B4:E4 -> AA-Dealer Central
B12: SLAB | C12: CONMORE | D12: MADISON | E12: MONROE | F12: BIRKDALE | G12: CRAFTSMAN
B13: 12" | C13: =Confidential!H4 -> 66.05 | D13: =Confidential!J4 -> 72.95 | E13: =D13 -> 72.95 | F13: =D13 -> 72.95 | G13: =D13 -> 72.95
B14: 14" | C14: =Confidential!H5 -> 66.05 | D14: =Confidential!J5 -> 72.95 | E14: =D14 -> 72.95 | F14: =D14 -> 72.95 | G14: =D14 -> 72.95
B15: 16" | C15: =Confidential!H6 -> 66.05 | D15: =Confidential!J6 -> 72.95 | E15: =D15 -> 72.95 | F15: =D15 -> 72.95 | G15: =D15 -> 72.95
B16: 18" | C16: =Confidential!H7 -> 66.05 | D16: =Confidential!J7 -> 72.95 | E16: =D16 -> 72.95 | F16: =D16 -> 72.95 | G16: =D16 -> 72.95
B18: 20" | C18: =Confidential!H8 -> 69.4 | D18: =Confidential!J8 -> 76.3 | E18: =D18 -> 76.3 | F18: =D18 -> 76.3 | G18: =D18 -> 76.3
B19: 22" | C19: =Confidential!H9 -> 69.4 | D19: =Confidential!J9 -> 76.3 | E19: =D19 -> 76.3 | F19: =D19 -> 76.3 | G19: =D19 -> 76.3
B20: 24" | C20: =Confidential!H10 -> 69.4 | D20: =Confidential!J10 -> 76.3 | E20: =D20 -> 76.3 | F20: =D20 -> 76.3 | G20: =D20 -> 76.3
B22: 26" | C22: =Confidential!H11 -> 71.75 | D22: =Confidential!J11 -> 78.65 | E22: =D22 -> 78.65 | F22: =D22 -> 78.65 | G22: =D22 -> 78.65
B23: 28" | C23: =Confidential!H12 -> 71.75 | D23: =Confidential!J12 -> 78.65 | E23: =D23 -> 78.65 | F23: =D23 -> 78.65 | G23: =D23 -> 78.65
B24: 30" | C24: =Confidential!H13 -> 71.75 | D24: =Confidential!J13 -> 78.65 | E24: =D24 -> 78.65 | F24: =D24 -> 78.65 | G24: =D24 -> 78.65
B26: 32" | C26: =Confidential!H14 -> 74.05 | D26: =Confidential!J14 -> 80.95 | E26: =D26 -> 80.95 | F26: =D26 -> 80.95 | G26: =D26 -> 80.95
B27: 34" | C27: =Confidential!H15 -> 77.45 | D27: =Confidential!J15 -> 84.35 | E27: =D27 -> 84.35 | F27: =D27 -> 84.35 | G27: =D27 -> 84.35
B28: 36" | C28: =Confidential!H16 -> 77.45 | D28: =Confidential!J16 -> 84.35 | E28: =D28 -> 84.35 | F28: =D28 -> 84.35 | G28: =D28 -> 84.35
A29: ** | B29: =Molded!B30 -> HEIGHT 84" HC Add only | C29: =Confidential!H18 -> 30.75 | D29: =Confidential!J18 -> 30.75 | E29: =D29 -> 30.75 | F29: =D29 -> 30.75 | G29: =D29 -> 30.75
A30: ** | B30: =Molded!B31 -> HEIGHT 96" HC Add only | C30: =Confidential!H19 -> 85.35 | D30: =Confidential!J19 -> 85.35 | E30: =D30 -> 85.35 | F30: =D30 -> 85.35 | G30: N/A
A31: ** | B31: =Molded!B32 -> 1 3/8 SC 80'' Add only | C31: =Confidential!H20 -> 88 | D31: =Confidential!J20 -> 88 | E31: =D31 -> 88 | F31: =D31 -> 88 | G31: =D31 -> 88
A32: ** | B32: =Molded!B33 -> 1 3/8 SC 84'' Add only | C32: =Confidential!H21 -> 104.4 | D32: =Confidential!J21 -> 104.4 | E32: =D32 -> 104.4 | F32: =D32 -> 104.4 | G32: =D32 -> 104.4
A33: ** | B33: =Molded!B34 -> 1 3/8 SC 96'' Add only | C33: =Confidential!H22 -> 196.1 | D33: =Confidential!J22 -> 196.1 | E33: =D33 -> 196.1 | F33: =D33 -> 196.1 | G33: N/A
A34: =Molded!A37 -> Add for Easy-IN 4-9/16 MDF to HC/SC | C34: =Molded!C37 -> 65.7 | D34: =Molded!C37 -> 65.7 | E34: =Molded!C37 -> 65.7 | F34: =Molded!C37 -> 65.7 | G34: =Molded!C37 -> 65.7
A35: =Molded!A38 -> Add for Prehung 4-9/16 FJP to HC/SC | C35: =Molded!C38 -> 79.5 | D35: =Molded!C38 -> 79.5 | E35: =Molded!C38 -> 79.5 | F35: =Molded!C38 -> 79.5 | G35: =Molded!C38 -> 79.5
B37: =Molded!B40 -> BIFOLDS c/w Hard. | C37: CONMORE | D37: MADISON | E37: MONROE | F37: BIRKDALE | G37: CRAFTSMAN
B38: 24" | C38: =Confidential!H33 -> 83.2 | D38: =Confidential!J33 -> 90.1 | E38: =D38 -> 90.1 | F38: =D38 -> 90.1 | G38: =D38 -> 90.1
B39: 26" | C39: =Confidential!H34 -> 91.2 | D39: =Confidential!J34 -> 98.1 | E39: =D39 -> 98.1 | F39: =D39 -> 98.1 | G39: =D39 -> 98.1
B40: 28" | C40: =Confidential!H35 -> 91.2 | D40: =Confidential!J35 -> 98.1 | E40: =D40 -> 98.1 | F40: =D40 -> 98.1 | G40: =D40 -> 98.1
B41: 30" | C41: =Confidential!H36 -> 91.2 | D41: =Confidential!J36 -> 98.1 | E41: =D41 -> 98.1 | F41: =D41 -> 98.1 | G41: =D41 -> 98.1
B43: 32" | C43: =Confidential!H37 -> 96.25 | D43: =Confidential!J37 -> 103.15 | E43: =D43 -> 103.15 | F43: =D43 -> 103.15 | G43: =D43 -> 103.15
B44: 34" | C44: =Confidential!H38 -> 96.25 | D44: =Confidential!J38 -> 103.15 | E44: =D44 -> 103.15 | F44: =D44 -> 103.15 | G44: =D44 -> 103.15
B45: 36" | C45: =Confidential!H39 -> 96.25 | D45: =Confidential!J39 -> 103.15 | E45: =D45 -> 103.15 | F45: =D45 -> 103.15 | G45: =D45 -> 103.15
A46: ** | B46: =Molded!B49 -> HEIGHT 84" | C46: =Confidential!H40 -> 30.75 | D46: =Confidential!J40 -> 30.75 | E46: =D46 -> 30.75 | F46: =D46 -> 30.75 | G46: =D46 -> 30.75
A47: ** | B47: =Molded!B50 -> HEIGHT 96" | C47: =Confidential!H41 -> N/A | D47: =Confidential!J41 -> 85.35 | E47: =D47 -> 85.35 | F47: =C47 -> N/A | G47: N/A
B49: =Molded!B52 -> 1-3/4 SC | C49: CONMORE | D49: MADISON | E49: MONROE | F49: BIRKDALE | G49: CRAFTSMAN
B50: =Molded!B53 -> 18" | C50: =Confidential!H45 -> 193.25 | D50: =Confidential!J45 -> 200.15 | E50: =D50 -> 200.15 | F50: =D50 -> 200.15 | G50: =D50 -> 200.15
B51: =Molded!B54 -> 20" to 24" | C51: =Confidential!H46 -> 196.6 | D51: =Confidential!J46 -> 203.5 | E51: =D51 -> 203.5 | F51: =D51 -> 203.5 | G51: =D51 -> 203.5
B52: =Molded!B55 -> 26" to 30" | C52: =Confidential!H47 -> 198.95 | D52: =Confidential!J47 -> 205.85 | E52: =D52 -> 205.85 | F52: =D52 -> 205.85 | G52: =D52 -> 205.85
B53: =Molded!B56 -> 32" | C53: =Confidential!H48 -> 201.25 | D53: =Confidential!J48 -> 208.15 | E53: =D53 -> 208.15 | F53: =D53 -> 208.15 | G53: =D53 -> 208.15
B54: =Molded!B57 -> 34" to 36" | C54: =Confidential!H49 -> 204.65 | D54: =Confidential!J49 -> 211.55 | E54: =D54 -> 211.55 | F54: =D54 -> 211.55 | G54: =D54 -> 211.55
...

Sheet Adders
A5: =Molded!B2 -> NET PRICE LIST (April 4, 2025)
A6: =Molded!B3 -> Customer Name & Number
A7: =Molded!B4 -> AA-Dealer Central
A9: Adders
A12: Machining for 1 3/8": 3 Hinges and Lock | B12: 9.55
A13: Machining for 1 3/4": 3 Hinges and Lock | B13: 30.2
A14: 20 Minute Fire Rated Slab Only (machining included) | B14: 33.15
A15: 45 Min Fire Rated Flush (includes prep for 3 hinges & cyl lock) | B15: 320.1
A16: 45 Min Fire Rated Moulded (includes prep for 3 hinges & cyl lock) | B16: 473.8
A17: 60 - 90 Min Fire Rated Flush (includes prep for 3 hinges & cyl lock) | B17: 432.5
A18: Machining - Dead Bolt | B18: 7.6
A19: Machining - Viewer | B19: 7.6
A21: Jamb Add-ons: add to Hollow Core or Solid Core Slabs
A22: 4-9/16" MDF jamb for an Easy IN | B22: 65.7
A23: 6-9/16" MDF jamb for an Easy IN | B23: 78.45
A24: 4-9/16" FJP jamb for Easy IN | B24: 79.5
A25: 6-9/16" FJP jamb for Easy IN | B25: 92.75
A26: 4-9/16" FJ Primed for Prehung | B26: 79.5
A27: 4-9/16" FJP jamb Rabbeted Prehung | B27: 79.5
A28: 6-9/16" FJP jamb Rabbeted Prehung | B28: 92.5
A30: Options
A31: Hinge Finish | B31: 9
A32: Ball Catch | B32: 18.55
A33: Flush Bolt | B33: 18.55
A34: BB Hinges | B34: 21.2
A35: Non-Standard Charge (20 of the same size/style or more=$0.00) | B35: 79.5
A36: Double Door = (EASY-IN x 2) + Flushbolt or Ball Catches | B36: 18.55

Sheet Molded Styles
B8: COLONIST TEX | C8: CAMDEN
A10: Slab | B10: 6/8, 7/0, 8/0 | C10: 6/8
A11: Bifold | B11: 6/8, 7/0, 8/0 | C11: 6/8
A13: Smooth
B18: CARRARA | C18: SANTA-FE | D18: ROCKPORT
A20: Slab | B20: 6/8, 7/0, 8/0 | C20: 6/8, 7/0, 8/0 | D20: 6/8, 7/0, 8/0
A21: Bifold | B21: 6/8, 7/0, 8/0 | C21: 6/8, 7/0, 8/0 | D21: 6/8, 7/0, 8/0
A23: Smooth
B28: CRAFTSMAN | C28: MADISON | D28: CONMORE | E28: MONROE | F28: BIRKDALE
A30: Slab | B30: 6/8 & 7/0 | C30: 6/8, 7/0, 8/0 | D30: 6/8, 7/0, 8/0 | E30: 6/8, 7/0, 8/0 | F30: 6/8, 7/0, 8/0
A31: Bifold | B31: 6/8 & 7/0 | C31: 6/8, 7/0, 8/0 | D31: 6/8 & 7/0 | E31: 6/8, 7/0, 8/0 | F31: 6/8 & 7/0

Sheet Doors Availability
D2: Willmar
A3: Doors - sizes available
A4: modèle / model | C4: 12'' | D4: 14'' | E4: 16'' | F4: 18'' | G4: 20'' | H4: 22'' | I4: 24'' | J4: 26'' | K4: 28'' | L4: 30'' | M4: 32'' | N4: 34'' | O4: 36''
A5: BIRKDALE | B5: 80'' | C5: X | D5: X | E5: X | F5: X | G5: X | H5: X | I5: X | J5: X | K5: X | L5: X | M5: X | N5: X | O5: X
B6: 84'' | E6: X | F6: X | G6: X | H6: X | I6: X | J6: X | K6: X | L6: X | M6: X | N6: X | O6: X
B7: 96'' | E7: X | F7: X | G7: X | H7: X | I7: X | J7: X | K7: X | L7: X | M7: X | N7: X | O7: X
A8: CAMDEN | B8: 80'' | C8: X | D8: X | E8: X | F8: X | G8: X | H8: X | I8: X | J8: X | K8: X | L8: X | M8: X | N8: X | O8: X
B9: 84''
B10: 96''
A11: CARRARA | B11: 80'' | C11: X | D11: X | E11: X | F11: X | G11: X | H11: X | I11: X | J11: X | K11: X | L11: X | M11: X | N11: X | O11: X
B12: 84'' | C12: X | D12: X | E12: X | F12: X | G12: X | H12: X | I12: X | J12: X | K12: X | L12: X | M12: X | N12: X | O12: X
B13: 96'' | E13: X | F13: X | G13: X | H13: X | I13: X | J13: X | K13: X | L13: X | M13: X | N13: X | O13: X
A14: COLONIST TEXT | B14: 80'' | C14: X | D14: X | E14: X | F14: X | G14: X | H14: X | I14: X | J14: X | K14: X | L14: X | M14: X | N14: X | O14: X
B15: 84'' | C15: X | D15: X | E15: X | F15: X | G15: X | H15: X | I15: X | J15: X | K15: X | L15: X | M15: X | N15: X | O15: X
B16: 96'' | E16: X | F16: X | G16: X | H16: X | I16: X | J16: X | K16: X | L16: X | M16: X | N16: X | O16: X
A17: CONMORE | B17: 80'' | C17: X | D17: X | E17: X | F17: X | G17: X | H17: X | I17: X | J17: X | K17: X | L17: X | M17: X | N17: X | O17: X
B18: 84'' | C18: X | D18: X | E18: X | F18: X | G18: X | H18: X | I18: X | J18: X | K18: X | L18: X | M18: X | N18: X | O18: X
B19: 96'' | E19: X | F19: X | G19: X | H19: X | I19: X | J19: X | K19: X | L19: X | M19: X | N19: X | O19: X
A20: CRAFTSMAN | B20: 80'' | C20: X | D20: X | E20: X | F20: X | G20: X | H20: X | I20: X | J20: X | K20: X | L20: X | M20: X | N20: X | O20: X
B21: 84'' | C21: X | D21: X | E21: X | F21: X | G21: X | H21: X | I21: X | J21: X | K21: X | L21: X | M21: X | N21: X | O21: X
B22: 96''
A23: MADISON | B23: 80'' | C23: X | D23: X | E23: X | F23: X | G23: X | H23: X | I23: X | J23: X | K23: X | L23: X | M23: X | N23: X | O23: X
B24: 84'' | C24: X | D24: X | E24: X | F24: X | G24: X | H24: X | I24: X | J24: X | K24: X | L24: X | M24: X | N24: X | O24: X
B25: 96'' | E25: X | F25: X | G25: X | H25: X | I25: X | J25: X | K25: X | L25: X | M25: X | N25: X | O25: X
A26: MONROE | B26: 80'' | C26: X | D26: X | E26: X | F26: X | G26: X | H26: X | I26: X | J26: X | K26: X | L26: X | M26: X | N26: X | O26: X
B27: 84'' | C27: X | D27: X | E27: X | F27: X | G27: X | H27: X | I27: X | J27: X | K27: X | L27: X | M27: X | N27: X | O27: X
B28: 96'' | E28: X | F28: X | G28: X | H28: X | I28: X | J28: X | K28: X | L28: X | M28: X | N28: X | O28: X
A29: ROCKPORT | B29: 80'' | C29: X | D29: X | E29: X | F29: X | G29: X | H29: X | I29: X | J29: X | K29: X | L29: X | M29: X | N29: X | O29: X
B30: 84'' | E30: X | F30: X | G30: X | H30: X | I30: X | J30: X | K30: X | L30: X | M30: X | N30: X | O30: X
B31: 96'' | E31: X | F31: X | G31: X | H31: X | I31: X | J31: X | K31: X | L31: X | M31: X | N31: X | O31: X
A32: SANTA FE | B32: 80'' | C32: X | D32: X | E32: X | F32: X | G32: X | H32: X | I32: X | J32: X | K32: X | L32: X | M32: X | N32: X | O32: X
B33: 84'' | F33: X | G33: X | H33: X | I33: X | J33: X | K33: X | L33: X | M33: X | N33: X | O33: X
B34: 96'' | E34: X | F34: X | G34: X | H34: X | I34: X | J34: X | K34: X | L34: X | M34: X | N34: X | O34: X
C35: Non disponible / Not Available size
B36: x | C36: Disponible / Available
C41: notes internes
A43: 43174 | C43: ajot AVA 84'' x 18 à 36 incl, contl 16x84, rock 16x84''
A44: 43047 | C44: ajout carrara 80 84 96'', contl 28 et 32x96 , de 4 a 5, ajout coventry 84 et 96
A45: 42480 | C45: Avalon 26- de cmi à skin JW ( batt de 5,3/16 à 3,3/16)
A46: 42480 | C46: ajout Monroe, enlevé atherton ( Kathya ) , enlevé avalon 84'' ( Kathya )
...

Sheet Bifold Availability
D2: Willmar
A3: Bifolds - sizes available
B4: modèle / model | D4: 18'' | E4: 20'' | F4: 22'' | G4: 24'' | H4: 26'' | I4: 28'' | J4: 30'' | K4: 32'' | L4: 34'' | M4: 36''
B5: BIRKDALE | C5: 79'' | G5: X | H5: X | I5: X | J5: X | K5: X | L5: X | M5: X
C6: 84'' | G6: X | H6: X | I6: X | J6: X | K6: X | L6: X | M6: X
C7: 96''
B8: CAMDEN | C8: 79'' | D8: X | E8: X | F8: X | G8: X | H8: X | I8: X | J8: X | K8: X | L8: X | M8: X
C9: 84''
C10: 96''
B11: CARRARA | C11: 79'' | D11: X | E11: X | F11: X | G11: X | H11: X | I11: X | J11: X | K11: X | L11: X | M11: X
C12: 84'' | D12: X | E12: X | F12: X | G12: X | H12: X | I12: X | J12: X | K12: X | L12: X | M12: X
C13: 96'' | J13: X | K13: X | L13: X | M13: X
B14: COLONIST TEXT | C14: 79'' | D14: X | E14: X | F14: X | G14: X | H14: X | I14: X | J14: X | K14: X | L14: X | M14: X
C15: 84'' | D15: X | E15: X | F15: X | G15: X | H15: X | I15: X | J15: X | K15: X | L15: X | M15: X
C16: 96'' | J16: X | K16: X | L16: X | M16: X
B17: CONMORE | C17: 79'' | D17: X | E17: X | F17: X | G17: X | H17: X | I17: X | J17: X | K17: X | L17: X | M17: X
C18: 84'' | D18: X | E18: X | F18: X | G18: X | H18: X | I18: X | J18: X | K18: X | L18: X | M18: X
C19: 96''
B20: CRAFTSMAN | C20: 79'' | F20: X | G20: X | H20: X | I20: X | J20: X | K20: X | L20: X | M20: X
C21: 84'' | F21: X | G21: X | H21: X | I21: X | J21: X | K21: X | L21: X | M21: X
C22: 96''
B23: MADISON | C23: 79'' | F23: X | G23: X | H23: X | I23: X | J23: X | K23: X | L23: X | M23: X
C24: 84'' | F24: X | G24: X | H24: X | I24: X | J24: X | K24: X | L24: X | M24: X
C25: 96'' | J25: X | K25: X | L25: X | M25: X
B26: MONROE | C26: 79'' | F26: X | G26: X | H26: X | I26: X | J26: X | K26: X | L26: X | M26: X
C27: 84'' | F27: X | G27: X | H27: X | I27: X | J27: X | K27: X | L27: X | M27: X
C28: 96'' | J28: X | K28: X | L28: X | M28: X
B29: ROCKPORT | C29: 79'' | D29: X | E29: X | F29: X | G29: X | H29: X | I29: X | J29: X | K29: X | L29: X | M29: X
C30: 84'' | J30: X | K30: X | L30: X | M30: X
C31: 96'' | J31: X | K31: X | L31: X | M31: X
B32: SANTA FE | C32: 79'' | D32: X | E32: X | F32: X | G32: X | H32: X | I32: X | J32: X | K32: X | L32: X | M32: X
C33: 84'' | J33: X | K33: X | L33: X | M33: X
C34: 96'' | J34: X | K34: X | L34: X | M34: X
D35: Non disponible / Not Available
C36: x | D36: Disponible / Available
B43: 43174
B44: 43047
B45: 42480
B46: 42480
B47: 42376
...
