Workbook

Sheet Door Pricing
B2: Net Pricing (Canadian Dollars)
B3: Specialty Building Products (West)
B4: May 5, 2025 Price List | I4: % Increase | J4: 0.06
B5: FULL TRUCKLOAD PRICING 1000 Doors or more / Full Lifts (same size/style/size)
B6: Slab | C6: Colonial Moulded | D6: Conmore | E6: Flat Moulded (Shaker) | F6: Primed Hardboard | I6: Jan 2025 Price | J6: May 2025 Price | L6: Jan 2025 Price | M6: May 2025 Price | O6: Jan 2025 Price | P6: May 2025 Price | R6: Jan 2025 Price | S6: May 2025 Price
B7: 12" to 18" | C7: =J7 -> 41.6 | D7: =M7 -> 46.45 | E7: =P7 -> 51.3 | F7: =S7 -> 29.05 | I7: 39.25 | J7: =MROUND(I7*(1+$J$4),0.05) -> 41.6 | L7: 43.8 | M7: =MROUND(L7*(1+$J$4),0.05) -> 46.45 | O7: 48.4 | P7: =MROUND(O7*(1+$J$4),0.05) -> 51.3 | R7: 27.4 | S7: =MROUND(R7*(1+$J$4),0.05) -> 29.05
B8: 20" to 24" | C8: =J8 -> 45.1 | D8: =M8 -> 49.95 | E8: =P8 -> 54.8 | F8: =S8 -> 32.65 | I8: 42.55 | J8: =MROUND(I8*(1+$J$4),0.05) -> 45.1 | L8: 47.1 | M8: =MROUND(L8*(1+$J$4),0.05) -> 49.95 | O8: 51.7 | P8: =MROUND(O8*(1+$J$4),0.05) -> 54.8 | R8: 30.8 | S8: =MROUND(R8*(1+$J$4),0.05) -> 32.65
B9: 26" & 28" | C9: =J9 -> 46.25 | D9: =M9 -> 51.1 | E9: =P9 -> 55.95 | F9: =S9 -> 33.15 | I9: 43.65 | J9: =MROUND(I9*(1+$J$4),0.05) -> 46.25 | L9: 48.2 | M9: =MROUND(L9*(1+$J$4),0.05) -> 51.1 | O9: 52.8 | P9: =MROUND(O9*(1+$J$4),0.05) -> 55.95 | R9: 31.25 | S9: =MROUND(R9*(1+$J$4),0.05) -> 33.15
B10: 30" | C10: =J10 -> 46.65 | D10: =M10 -> 51.4 | E10: =P10 -> 56.35 | F10: =S10 -> 35.1 | I10: 44 | J10: =MROUND(I10*(1+$J$4),0.05) -> 46.65 | L10: 48.5 | M10: =MROUND(L10*(1+$J$4),0.05) -> 51.4 | O10: 53.15 | P10: =MROUND(O10*(1+$J$4),0.05) -> 56.35 | R10: 33.1 | S10: =MROUND(R10*(1+$J$4),0.05) -> 35.1
B11: 32" | C11: =J11 -> 48.85 | D11: =M11 -> 53.75 | E11: =P11 -> 58.65 | F11: =S11 -> 35.95 | I11: 46.1 | J11: =MROUND(I11*(1+$J$4),0.05) -> 48.85 | L11: 50.7 | M11: =MROUND(L11*(1+$J$4),0.05) -> 53.75 | O11: 55.35 | P11: =MROUND(O11*(1+$J$4),0.05) -> 58.65 | R11: 33.9 | S11: =MROUND(R11*(1+$J$4),0.05) -> 35.95
B12: 34" | C12: =J12 -> 51.2 | D12: =M12 -> 56.05 | E12: =P12 -> 60.85 | F12: =S12 -> 36.75 | I12: 48.3 | J12: =MROUND(I12*(1+$J$4),0.05) -> 51.2 | L12: 52.9 | M12: =MROUND(L12*(1+$J$4),0.05) -> 56.05 | O12: 57.4 | P12: =MROUND(O12*(1+$J$4),0.05) -> 60.85 | R12: 34.65 | S12: =MROUND(R12*(1+$J$4),0.05) -> 36.75
B13: 36" | C13: =J13 -> 51.2 | D13: =M13 -> 56.05 | E13: =P13 -> 60.85 | F13: =S13 -> 36.75 | I13: 48.3 | J13: =MROUND(I13*(1+$J$4),0.05) -> 51.2 | L13: 52.9 | M13: =MROUND(L13*(1+$J$4),0.05) -> 56.05 | O13: 57.4 | P13: =MROUND(O13*(1+$J$4),0.05) -> 60.85 | R13: 34.65 | S13: =MROUND(R13*(1+$J$4),0.05) -> 36.75
B14: 38'' | C14: NA | D14: NA | E14: NA | F14: =S14 -> 65.65 | R14: 61.95 | S14: =MROUND(R14*(1+$J$4),0.05) -> 65.65
B15: 38" Euro (Carrara) | C15: 83.2 | D15: NA | E15: NA | F15: NA | J15: New
B16: Height 84" | C16: =J16 -> 20.05 | D16: =M16 -> 24.7 | E16: =P16 -> 24.7 | F16: =S16 -> 12.35 | I16: 18.9 | J16: =MROUND(I16*(1+$J$4),0.05) -> 20.05 | L16: 23.3 | M16: =MROUND(L16*(1+$J$4),0.05) -> 24.7 | O16: 23.3 | P16: =MROUND(O16*(1+$J$4),0.05) -> 24.7 | R16: 11.65 | S16: =MROUND(R16*(1+$J$4),0.05) -> 12.35
B17: Height 96" | C17: =J17 -> 35.45 | D17: =M17 -> 46.25 | E17: =P17 -> 46.25 | F17: =S17 -> 24.7 | I17: 33.45 | J17: =MROUND(I17*(1+$J$4),0.05) -> 35.45 | L17: 43.65 | M17: =MROUND(L17*(1+$J$4),0.05) -> 46.25 | O17: 43.65 | P17: =MROUND(O17*(1+$J$4),0.05) -> 46.25 | R17: 23.3 | S17: =MROUND(R17*(1+$J$4),0.05) -> 24.7
B18: 1 3/8 solid core 80'' add | C18: =J18 -> 44.3 | D18: =M18 -> 44.3 | E18: =P18 -> 44.3 | F18: =S18 -> 36.35 | I18: 41.8 | J18: =MROUND(I18*(1+$J$4),0.05) -> 44.3 | L18: 41.8 | M18: =MROUND(L18*(1+$J$4),0.05) -> 44.3 | O18: 41.8 | P18: =MROUND(O18*(1+$J$4),0.05) -> 44.3 | R18: 34.3 | S18: =MROUND(R18*(1+$J$4),0.05) -> 36.35
B19: 1 3/8 solid core 84' add | C19: =J19 -> 52.45 | D19: =M19 -> 52.45 | E19: =P19 -> 52.45 | F19: =S19 -> 41.3 | I19: 49.5 | J19: =MROUND(I19*(1+$J$4),0.05) -> 52.45 | L19: 49.5 | M19: =MROUND(L19*(1+$J$4),0.05) -> 52.45 | O19: 49.5 | P19: =MROUND(O19*(1+$J$4),0.05) -> 52.45 | R19: 38.95 | S19: =MROUND(R19*(1+$J$4),0.05) -> 41.3
B20: 1 3/8 solid core 96' add | C20: =J20 -> 99.1 | D20: =M20 -> 99.1 | E20: =P20 -> 99.1 | F20: =S20 -> 59.85 | I20: 93.5 | J20: =MROUND(I20*(1+$J$4),0.05) -> 99.1 | L20: 93.5 | M20: =MROUND(L20*(1+$J$4),0.05) -> 99.1 | O20: 93.5 | P20: =MROUND(O20*(1+$J$4),0.05) -> 99.1 | R20: 56.45 | S20: =MROUND(R20*(1+$J$4),0.05) -> 59.85
B21: 1 3/4 hollow core 80" add | C21: 20 | D21: NA | E21: NA | F21: =S21 -> 21.1 | R21: 19.9 | S21: =MROUND(R21*(1+$J$4),0.05) -> 21.1
B22: 1 3/4 hollow core 84" add | C22: 25 | D22: NA | E22: NA | F22: 25
B23: For pivot or bypass door add $4.65 | I23: 4.4 | J23: =MROUND(I23*(1+$J$4),0.05) -> 4.65
B24: Bifold 79 in. c/w hardware shrink-wrapped
B25: 18" to 24" | C25: =J25 -> 57.7 | D25: =M25 -> 62.5 | E25: =P25 -> 67.4 | F25: =S25 -> 48.4 | I25: 54.45 | J25: =MROUND(I25*(1+$J$4),0.05) -> 57.7 | L25: 58.95 | M25: =MROUND(L25*(1+$J$4),0.05) -> 62.5 | O25: 63.6 | P25: =MROUND(O25*(1+$J$4),0.05) -> 67.4 | R25: 45.65 | S25: =MROUND(R25*(1+$J$4),0.05) -> 48.4
B26: 26" to 30" | C26: =J26 -> 61.3 | D26: =M26 -> 66.1 | E26: =P26 -> 71 | F26: =S26 -> 52.35 | I26: 57.85 | J26: =MROUND(I26*(1+$J$4),0.05) -> 61.3 | L26: 62.35 | M26: =MROUND(L26*(1+$J$4),0.05) -> 66.1 | O26: 67 | P26: =MROUND(O26*(1+$J$4),0.05) -> 71 | R26: 49.4 | S26: =MROUND(R26*(1+$J$4),0.05) -> 52.35
B27: 32" to 36" | C27: =J27 -> 64.9 | D27: =M27 -> 69.85 | E27: =P27 -> 74.6 | F27: =S27 -> 56.45 | I27: 61.25 | J27: =MROUND(I27*(1+$J$4),0.05) -> 64.9 | L27: 65.9 | M27: =MROUND(L27*(1+$J$4),0.05) -> 69.85 | O27: 70.4 | P27: =MROUND(O27*(1+$J$4),0.05) -> 74.6 | R27: 53.25 | S27: =MROUND(R27*(1+$J$4),0.05) -> 56.45
B28: Height 84" | C28: =J28 -> 23.2 | D28: =M28 -> 23.2 | E28: =P28 -> 23.2 | F28: =S28 -> 23.2 | I28: 21.9 | J28: =MROUND(I28*(1+$J$4),0.05) -> 23.2 | L28: 21.9 | M28: =MROUND(L28*(1+$J$4),0.05) -> 23.2 | O28: 21.9 | P28: =MROUND(O28*(1+$J$4),0.05) -> 23.2 | R28: 21.9 | S28: =MROUND(R28*(1+$J$4),0.05) -> 23.2
B29: Height 96" | C29: =J29 -> 74.05 | D29: 74.05 | E29: 74.05 | F29: =S29 -> 55.5 | I29: 69.85 | J29: =MROUND(I29*(1+$J$4),0.05) -> 74.05 | M29: New | P29: New | R29: 52.36 | S29: =MROUND(R29*(1+$J$4),0.05) -> 55.5
B30: 1 3/4 20 min (no label)
B31: 30" | C31: =J31 -> 134.45 | D31: =M31 -> 155.75 | E31: =P31 -> 155.75 | F31: =S31 -> 82 | I31: 126.85 | J31: =MROUND(I31*(1+$J$4),0.05) -> 134.45 | L31: 146.95 | M31: =MROUND(L31*(1+$J$4),0.05) -> 155.75 | O31: 146.95 | P31: =MROUND(O31*(1+$J$4),0.05) -> 155.75 | R31: 77.35 | S31: =MROUND(R31*(1+$J$4),0.05) -> 82
B32: 32" | C32: =J32 -> 135.95 | D32: =M32 -> 158.8 | E32: =P32 -> 158.8 | F32: =S32 -> 82 | I32: 128.25 | J32: =MROUND(I32*(1+$J$4),0.05) -> 135.95 | L32: 149.8 | M32: =MROUND(L32*(1+$J$4),0.05) -> 158.8 | O32: 149.8 | P32: =MROUND(O32*(1+$J$4),0.05) -> 158.8 | R32: 77.35 | S32: =MROUND(R32*(1+$J$4),0.05) -> 82
B33: 34" | C33: =J33 -> 137.5 | D33: =M33 -> 160.35 | E33: =P33 -> 160.35 | F33: =S33 -> 82.8 | I33: 129.7 | J33: =MROUND(I33*(1+$J$4),0.05) -> 137.5 | L33: 151.25 | M33: =MROUND(L33*(1+$J$4),0.05) -> 160.35 | O33: 151.25 | P33: =MROUND(O33*(1+$J$4),0.05) -> 160.35 | R33: 78.1 | S33: =MROUND(R33*(1+$J$4),0.05) -> 82.8
B34: 36" | C34: =J34 -> 137.5 | D34: =M34 -> 160.35 | E34: =P34 -> 160.35 | F34: =S34 -> 82.8 | I34: 129.7 | J34: =MROUND(I34*(1+$J$4),0.05) -> 137.5 | L34: 151.25 | M34: =MROUND(L34*(1+$J$4),0.05) -> 160.35 | O34: 151.25 | P34: =MROUND(O34*(1+$J$4),0.05) -> 160.35 | R34: 78.1 | S34: =MROUND(R34*(1+$J$4),0.05) -> 82.8
B35: 38'' | C35: NA | D35: NA | E35: NA | F35: =S35 -> 121.2 | R35: 114.35 | S35: =MROUND(R35*(1+$J$4),0.05) -> 121.2
B36: 38" Euro (Carrara) | C36: 172.5 | D36: NA | E36: NA | F36: NA | J36: New
B37: Height 82" or 84" | C37: =J37 -> 27.75 | D37: =M37 -> 46.25 | E37: =P37 -> 46.25 | F37: =S37 -> 18.55 | I37: 26.2 | J37: =MROUND(I37*(1+$J$4),0.05) -> 27.75 | L37: 43.65 | M37: =MROUND(L37*(1+$J$4),0.05) -> 46.25 | O37: 43.65 | P37: =MROUND(O37*(1+$J$4),0.05) -> 46.25 | R37: 17.5 | S37: =MROUND(R37*(1+$J$4),0.05) -> 18.55
B38: Height 96" | C38: =J38 -> 46.25 | D38: =M38 -> 92.5 | E38: =P38 -> 92.5 | F38: =S38 -> 43.15 | I38: 43.65 | J38: =MROUND(I38*(1+$J$4),0.05) -> 46.25 | L38: 87.25 | M38: =MROUND(L38*(1+$J$4),0.05) -> 92.5 | O38: 87.25 | P38: =MROUND(O38*(1+$J$4),0.05) -> 92.5 | R38: 40.7 | S38: =MROUND(R38*(1+$J$4),0.05) -> 43.15
B39: Less than 5 per size (1-4) add $7.00 | I39: 6.6 | J39: =MROUND(I39*(1+$J$4),0.05) -> 7
B40: If Full Truckload rules are met a 5% charge will apply to broken lifts (if order is accepted)
B41: 20 Min Labelled + Machined (3 hinges+Cyl lock): $24.50 | I41: 23.1 | J41: =MROUND(I41*(1+$J$4),0.05) -> 24.5
...

Sheet Door Pricing added 5%
B2: Net Pricing (Canadian Dollars)
B3: Specialty Building Products (West)
B4: May 5, 2025 Price List | I4: Manual Update
B5: LESS THAN TRUCKLOAD - Order Quantity Pricing (200-999) NOTE: MINIMUM ORDER QUANTITY 200
B6: Slab | C6: Colonial Moulded | D6: Conmore | E6: Flat Moulded (Shaker) | F6: Primed Hardboard
B7: 12" to 18" | C7: ='Door Pricing'!C7*1.05 -> 43.68 | D7: ='Door Pricing'!D7*1.05 -> 48.7725 | E7: ='Door Pricing'!E7*1.05 -> 53.865 | F7: ='Door Pricing'!F7*1.05 -> 30.5025
B8: 20" to 24" | C8: ='Door Pricing'!C8*1.05 -> 47.355 | D8: ='Door Pricing'!D8*1.05 -> 52.4475 | E8: ='Door Pricing'!E8*1.05 -> 57.54 | F8: ='Door Pricing'!F8*1.05 -> 34.2825
B9: 26" & 28" | C9: ='Door Pricing'!C9*1.05 -> 48.5625 | D9: ='Door Pricing'!D9*1.05 -> 53.655 | E9: ='Door Pricing'!E9*1.05 -> 58.7475 | F9: ='Door Pricing'!F9*1.05 -> 34.8075
B10: 30" | C10: ='Door Pricing'!C10*1.05 -> 48.9825 | D10: ='Door Pricing'!D10*1.05 -> 53.97 | E10: ='Door Pricing'!E10*1.05 -> 59.1675 | F10: ='Door Pricing'!F10*1.05 -> 36.855
B11: 32" | C11: ='Door Pricing'!C11*1.05 -> 51.2925 | D11: ='Door Pricing'!D11*1.05 -> 56.4375 | E11: ='Door Pricing'!E11*1.05 -> 61.5825 | F11: ='Door Pricing'!F11*1.05 -> 37.7475
B12: 34" | C12: ='Door Pricing'!C12*1.05 -> 53.76 | D12: ='Door Pricing'!D12*1.05 -> 58.8525 | E12: ='Door Pricing'!E12*1.05 -> 63.8925 | F12: ='Door Pricing'!F12*1.05 -> 38.5875
B13: 36" | C13: ='Door Pricing'!C13*1.05 -> 53.76 | D13: ='Door Pricing'!D13*1.05 -> 58.8525 | E13: ='Door Pricing'!E13*1.05 -> 63.8925 | F13: ='Door Pricing'!F13*1.05 -> 38.5875
B14: 38'' | C14: NA | D14: NA | E14: NA | F14: ='Door Pricing'!F14*1.05 -> 68.9325
B15: 38" Euro (Carrara) | C15: ='Door Pricing'!C15*1.05 -> 87.36 | D15: NA | E15: NA | F15: NA
B16: Height 84" | C16: ='Door Pricing'!C16 -> 20.05 | D16: ='Door Pricing'!D16 -> 24.7 | E16: ='Door Pricing'!E16 -> 24.7 | F16: ='Door Pricing'!F16 -> 12.35
B17: Height 96" | C17: ='Door Pricing'!C17 -> 35.45 | D17: ='Door Pricing'!D17 -> 46.25 | E17: ='Door Pricing'!E17 -> 46.25 | F17: ='Door Pricing'!F17 -> 24.7
B18: 1 3/8 solid core 80'' add | C18: ='Door Pricing'!C18 -> 44.3 | D18: ='Door Pricing'!D18 -> 44.3 | E18: ='Door Pricing'!E18 -> 44.3 | F18: ='Door Pricing'!F18 -> 36.35
B19: 1 3/8 solid core 84' add | C19: ='Door Pricing'!C19 -> 52.45 | D19: ='Door Pricing'!D19 -> 52.45 | E19: ='Door Pricing'!E19 -> 52.45 | F19: ='Door Pricing'!F19 -> 41.3
B20: 1 3/8 solid core 96' add | C20: ='Door Pricing'!C20 -> 99.1 | D20: ='Door Pricing'!D20 -> 99.1 | E20: ='Door Pricing'!E20 -> 99.1 | F20: ='Door Pricing'!F20 -> 59.85
B21: 1 3/4 hollow core 80" add | C21: ='Door Pricing'!C21 -> 20 | D21: NA | E21: NA | F21: ='Door Pricing'!F21 -> 21.1
B22: 1 3/4 hollow core 84" add | C22: ='Door Pricing'!C22 -> 25 | D22: NA | E22: NA | F22: ='Door Pricing'!F22 -> 25
B23: For pivot or bypass door add $4.40
B24: Bifold 79 in. c/w hardware shrink-wrapped
B25: 18" to 24" | C25: ='Door Pricing'!C25*1.05 -> 60.585 | D25: ='Door Pricing'!D25*1.05 -> 65.625 | E25: ='Door Pricing'!E25*1.05 -> 70.77 | F25: ='Door Pricing'!F25*1.05 -> 50.82
B26: 26" to 30" | C26: ='Door Pricing'!C26*1.05 -> 64.365 | D26: ='Door Pricing'!D26*1.05 -> 69.405 | E26: ='Door Pricing'!E26*1.05 -> 74.55 | F26: ='Door Pricing'!F26*1.05 -> 54.9675
B27: 32" to 36" | C27: ='Door Pricing'!C27*1.05 -> 68.145 | D27: ='Door Pricing'!D27*1.05 -> 73.3425 | E27: ='Door Pricing'!E27*1.05 -> 78.33 | F27: ='Door Pricing'!F27*1.05 -> 59.2725
B28: Height 84" | C28: ='Door Pricing'!C28 -> 23.2 | D28: ='Door Pricing'!D28 -> 23.2 | E28: ='Door Pricing'!E28 -> 23.2 | F28: ='Door Pricing'!F28 -> 23.2
B29: Height 96" | C29: ='Door Pricing'!C29 -> 74.05 | D29: ='Door Pricing'!D29 -> 74.05 | E29: ='Door Pricing'!E29 -> 74.05 | F29: ='Door Pricing'!F29 -> 55.5
B30: 1 3/4 20 min (no label)
B31: 30" | C31: ='Door Pricing'!C31*1.05 -> 141.1725 | D31: ='Door Pricing'!D31*1.05 -> 163.5375 | E31: ='Door Pricing'!E31*1.05 -> 163.5375 | F31: ='Door Pricing'!F31*1.05 -> 86.1
B32: 32" | C32: ='Door Pricing'!C32*1.05 -> 142.7475 | D32: ='Door Pricing'!D32*1.05 -> 166.74 | E32: ='Door Pricing'!E32*1.05 -> 166.74 | F32: ='Door Pricing'!F32*1.05 -> 86.1
B33: 34" | C33: ='Door Pricing'!C33*1.05 -> 144.375 | D33: ='Door Pricing'!D33*1.05 -> 168.3675 | E33: ='Door Pricing'!E33*1.05 -> 168.3675 | F33: ='Door Pricing'!F33*1.05 -> 86.94
B34: 36" | C34: ='Door Pricing'!C34*1.05 -> 144.375 | D34: ='Door Pricing'!D34*1.05 -> 168.3675 | E34: ='Door Pricing'!E34*1.05 -> 168.3675 | F34: ='Door Pricing'!F34*1.05 -> 86.94
B35: 38'' | C35: NA | D35: NA | E35: NA | F35: ='Door Pricing'!F35*1.05 -> 127.26
B36: 38" Euro (Carrara) | C36: ='Door Pricing'!C36*1.05 -> 181.125 | D36: NA | E36: NA | F36: NA
B37: Height 82" or 84" | C37: ='Door Pricing'!C37 -> 27.75 | D37: ='Door Pricing'!D37 -> 46.25 | E37: ='Door Pricing'!E37 -> 46.25 | F37: ='Door Pricing'!F37 -> 18.55
B38: Height 96" | C38: ='Door Pricing'!C38 -> 46.25 | D38: ='Door Pricing'!D38 -> 92.5 | E38: ='Door Pricing'!E38 -> 92.5 | F38: ='Door Pricing'!F38 -> 43.15
B39: Less than 5 per size (1-4) add $7.00 | I39: Manual update
B40: 20 Min Labelled + Machined (3 hinges+Cyl lock): $24.50 | I40: Manual update
B41: Off standard for slab, bifold & procore 1 3/8 or 13/4 add : $61.70 | I41: Manual update

Sheet Adders
A2: Net Pricing (Canadian Dollars)
A3: Specialty Building Products (West)
A4: May 5, 2025 Price List | F4: Manual Update
A6: ADDERS: | F6: Jan 2025 Price | G6: % Increase | H6: May 2025 Price
A7: Machining 2 or 3 hinges & cyl. Lock (1 3/8) | D7: =H7 -> 4.65 | F7: 4.4 | G7: 0.06 | H7: =MROUND(F7*(1+G7),0.05) -> 4.65
A8: Machining 3 hinges & cyl. Lock (1 3/4) | D8: =H8 -> 16.3 | F8: 15.4 | G8: 0.06 | H8: =MROUND(F8*(1+G8),0.05) -> 16.3
A9: Machining 3 hinges & cyl. Lock (1 3/4) for 20 min | D9: 24.5 | H9: Same as price on page 1
A11: Adder for 45 Min Flush (includes prep for 3 hinges & cyl lock) | D11: 265 | H11: New
A12: Adder for 45 Min Moulded (includes prep for 3 hinges & cyl lock) | D12: 411.3 | H12: New
A14: Adder for 60 - 90 Min Flush (includes prep for 3 hinges & cyl lock) | D14: 379.5 | H14: New
A16: Machining lock 1 side for slider | D16: =H16 -> 5.85 | F16: 5.5 | G16: 0.06 | H16: =MROUND(F16*(1+G16),0.05) -> 5.85
A17: Machining 50K (1 3/4) | D17: =H17 -> 29.15 | F17: 27.5 | G17: 0.06 | H17: =MROUND(F17*(1+G17),0.05) -> 29.15
A18: Machining Flush Bolts top & bottom (13/4) | D18: =H18 -> 40.8 | F18: 38.5 | G18: 0.06 | H18: =MROUND(F18*(1+G18),0.05) -> 40.8
A19: Deadlock or peep hole | D19: =H19 -> 4.65 | F19: 4.4 | G19: 0.06 | H19: =MROUND(F19*(1+G19),0.05) -> 4.65
A20: Pivot or slider | D20: =H20 -> 4.65 | F20: 4.4 | G20: 0.06 | H20: =MROUND(F20*(1+G20),0.05) -> 4.65
A21: Machining Mortice lock | D21: =H21 -> 35 | F21: 33 | G21: 0.06 | H21: =MROUND(F21*(1+G21),0.05) -> 35
A22: Machining bottom closure 1 3/8 (C-201) | D22: =H22 -> 23.3 | F22: 22 | G22: 0.06 | H22: =MROUND(F22*(1+G22),0.05) -> 23.3
A23: Wood rails 3'' (top & bottom) | D23: =H23 -> 14 | F23: 13.2 | G23: 0.06 | H23: =MROUND(F23*(1+G23),0.05) -> 14
A24: Non formaldehyde (moulded 13/8 hc) | D24: On Request
A25: Non formaldehyde bifold (moulded 13/8 ) | D25: On Request
A26: Non formaldehyde (moulded 13/8 solid core) | D26: On Request

Sheet Modèle moulées
B8: COLONIST TEX | C8: CAMDEN
A10: Slab | B10: 6/8, 7/0, 8/0 | C10: 6/8
A11: Bifold | B11: 6/8, 7/0, 8/0 | C11: 6/8
A13: Smooth
B18: CARRARA | C18: SANTA-FE | D18: ROCKPORT
A20: Slab | B20: 6/8, 7/0, 8/0 | C20: 6/8, 7/0, 8/0 | D20: 6/8, 7/0, 8/0
A21: Bifold | B21: 6/8, 7/0, 8/0 | C21: 6/8, 7/0, 8/0 | D21: 6/8, 7/0, 8/0
A23: Smooth
B28: CRAFTSMAN | C28: MADISON | D28: CONMORE | E28: MONROE | F28: BIRKDALE
A30: Slab | B30: 6/8 & 7/0 | C30: 6/8, 7/0, 8/0 | D30: 6/8, 7/0, 8/0 | E30: 6/8, 7/0, 8/0 | F30: 6/8, 7/0, 8/0
A31: Bifold | B31: 6/8 & 7/0 | C31: 6/8, 7/0, 8/0 | D31: 6/8 & 7/0 | E31: 6/8, 7/0, 8/0 | F31: 6/8 & 7/0

Sheet Disponibilité Portes
A3: Portes - dimensions disponibles / Doors - sizes available
A4: modèle / model | C4: 12'' | D4: 14'' | E4: 16'' | F4: 18'' | G4: 20'' | H4: 22'' | I4: 24'' | J4: 26'' | K4: 28'' | L4: 30'' | M4: 32'' | N4: 34'' | O4: 36''
A5: BIRKDALE | B5: 80'' | C5: X | D5: X | E5: X | F5: X | G5: X | H5: X | I5: X | J5: X | K5: X | L5: X | M5: X | N5: X | O5: X
B6: 84'' | E6: X | F6: X | G6: X | H6: X | I6: X | J6: X | K6: X | L6: X | M6: X | N6: X | O6: X
B7: 96'' | E7: X | F7: X | G7: X | H7: X | I7: X | J7: X | K7: X | L7: X | M7: X | N7: X | O7: X
A8: CAMDEN | B8: 80'' | C8: X | D8: X | E8: X | F8: X | G8: X | H8: X | I8: X | J8: X | K8: X | L8: X | M8: X | N8: X | O8: X
B9: 84''
B10: 96''
A11: CARRARA | B11: 80'' | C11: X | D11: X | E11: X | F11: X | G11: X | H11: X | I11: X | J11: X | K11: X | L11: X | M11: X | N11: X | O11: X
B12: 84'' | C12: X | D12: X | E12: X | F12: X | G12: X | H12: X | I12: X | J12: X | K12: X | L12: X | M12: X | N12: X | O12: X
B13: 96'' | E13: X | F13: X | G13: X | H13: X | I13: X | J13: X | K13: X | L13: X | M13: X | N13: X | O13: X
A14: COLONIST TEXT | B14: 80'' | C14: X | D14: X | E14: X | F14: X | G14: X | H14: X | I14: X | J14: X | K14: X | L14: X | M14: X | N14: X | O14: X
B15: 84'' | C15: X | D15: X | E15: X | F15: X | G15: X | H15: X | I15: X | J15: X | K15: X | L15: X | M15: X | N15: X | O15: X
B16: 96'' | E16: X | F16: X | G16: X | H16: X | I16: X | J16: X | K16: X | L16: X | M16: X | N16: X | O16: X
A17: CONMORE | B17: 80'' | C17: X | D17: X | E17: X | F17: X | G17: X | H17: X | I17: X | J17: X | K17: X | L17: X | M17: X | N17: X | O17: X
B18: 84'' | C18: X | D18: X | E18: X | F18: X | G18: X | H18: X | I18: X | J18: X | K18: X | L18: X | M18: X | N18: X | O18: X
B19: 96'' | E19: X | F19: X | G19: X | H19: X | I19: X | J19: X | K19: X | L19: X | M19: X | N19: X | O19: X
A20: CRAFTSMAN | B20: 80'' | C20: X | D20: X | E20: X | F20: X | G20: X | H20: X | I20: X | J20: X | K20: X | L20: X | M20: X | N20: X | O20: X
B21: 84'' | C21: X | D21: X | E21: X | F21: X | G21: X | H21: X | I21: X | J21: X | K21: X | L21: X | M21: X | N21: X | O21: X
B22: 96''
A23: MADISON | B23: 80'' | C23: X | D23: X | E23: X | F23: X | G23: X | H23: X | I23: X | J23: X | K23: X | L23: X | M23: X | N23: X | O23: X
B24: 84'' | C24: X | D24: X | E24: X | F24: X | G24: X | H24: X | I24: X | J24: X | K24: X | L24: X | M24: X | N24: X | O24: X
B25: 96'' | E25: X | F25: X | G25: X | H25: X | I25: X | J25: X | K25: X | L25: X | M25: X | N25: X | O25: X
A26: MONROE | B26: 80'' | C26: X | D26: X | E26: X | F26: X | G26: X | H26: X | I26: X | J26: X | K26: X | L26: X | M26: X | N26: X | O26: X
B27: 84'' | C27: X | D27: X | E27: X | F27: X | G27: X | H27: X | I27: X | J27: X | K27: X | L27: X | M27: X | N27: X | O27: X
B28: 96'' | E28: X | F28: X | G28: X | H28: X | I28: X | J28: X | K28: X | L28: X | M28: X | N28: X | O28: X
A29: ROCKPORT | B29: 80'' | C29: X | D29: X | E29: X | F29: X | G29: X | H29: X | I29: X | J29: X | K29: X | L29: X | M29: X | N29: X | O29: X
B30: 84'' | E30: X | F30: X | G30: X | H30: X | I30: X | J30: X | K30: X | L30: X | M30: X | N30: X | O30: X
B31: 96'' | E31: X | F31: X | G31: X | H31: X | I31: X | J31: X | K31: X | L31: X | M31: X | N31: X | O31: X
A32: SANTA FE | B32: 80'' | C32: X | D32: X | E32: X | F32: X | G32: X | H32: X | I32: X | J32: X | K32: X | L32: X | M32: X | N32: X | O32: X
B33: 84'' | F33: X | G33: X | H33: X | I33: X | J33: X | K33: X | L33: X | M33: X | N33: X | O33: X
B34: 96'' | E34: X | F34: X | G34: X | H34: X | I34: X | J34: X | K34: X | L34: X | M34: X | N34: X | O34: X
C35: Non disponible / Not Available size
B36: x | C36: Disponible / Available
C41: notes internes
A43: 43174 | C43: ajot AVA 84'' x 18 à 36 incl, contl 16x84, rock 16x84''
A44: 43047 | C44: ajout carrara 80 84 96'', contl 28 et 32x96 , de 4 a 5, ajout coventry 84 et 96
A45: 42480 | C45: Avalon 26- de cmi à skin JW ( batt de 5,3/16 à 3,3/16)
A46: 42480 | C46: ajout Monroe, enlevé atherton ( Kathya ) , enlevé avalon 84'' ( Kathya )
A47: 42376 | C47: enlevé arl bostonian, stanford, ajouté colonist tex col smth, coventry, monroe a venir
...

Sheet Disponibilité Pliantes
A3: Pliantes - dimensions disponibles Bifolds - sizes available
B4: modèle / model | D4: 18'' | E4: 20'' | F4: 22'' | G4: 24'' | H4: 26'' | I4: 28'' | J4: 30'' | K4: 32'' | L4: 34'' | M4: 36''
B5: BIRKDALE | C5: 79'' | G5: X | H5: X | I5: X | J5: X | K5: X | L5: X | M5: X
C6: 84'' | G6: X | H6: X | I6: X | J6: X | K6: X | L6: X | M6: X
C7: 96''
B8: CAMDEN | C8: 79'' | D8: X | E8: X | F8: X | G8: X | H8: X | I8: X | J8: X | K8: X | L8: X | M8: X
C9: 84''
C10: 96''
B11: CARRARA | C11: 79'' | D11: X | E11: X | F11: X | G11: X | H11: X | I11: X | J11: X | K11: X | L11: X | M11: X
C12: 84'' | D12: X | E12: X | F12: X | G12: X | H12: X | I12: X | J12: X | K12: X | L12: X | M12: X
C13: 96'' | J13: X | K13: X | L13: X | M13: X
B14: COLONIST TEXT | C14: 79'' | D14: X | E14: X | F14: X | G14: X | H14: X | I14: X | J14: X | K14: X | L14: X | M14: X
C15: 84'' | D15: X | E15: X | F15: X | G15: X | H15: X | I15: X | J15: X | K15: X | L15: X | M15: X
C16: 96'' | J16: X | K16: X | L16: X | M16: X
B17: CONMORE | C17: 79'' | D17: X | E17: X | F17: X | G17: X | H17: X | I17: X | J17: X | K17: X | L17: X | M17: X
C18: 84'' | D18: X | E18: X | F18: X | G18: X | H18: X | I18: X | J18: X | K18: X | L18: X | M18: X
C19: 96''
B20: CRAFTSMAN | C20: 79'' | F20: X | G20: X | H20: X | I20: X | J20: X | K20: X | L20: X | M20: X
C21: 84'' | F21: X | G21: X | H21: X | I21: X | J21: X | K21: X | L21: X | M21: X
C22: 96''
B23: MADISON | C23: 79'' | F23: X | G23: X | H23: X | I23: X | J23: X | K23: X | L23: X | M23: X
C24: 84'' | F24: X | G24: X | H24: X | I24: X | J24: X | K24: X | L24: X | M24: X
C25: 96'' | J25: X | K25: X | L25: X | M25: X
B26: MONROE | C26: 79'' | F26: X | G26: X | H26: X | I26: X | J26: X | K26: X | L26: X | M26: X
C27: 84'' | F27: X | G27: X | H27: X | I27: X | J27: X | K27: X | L27: X | M27: X
C28: 96'' | J28: X | K28: X | L28: X | M28: X
B29: ROCKPORT | C29: 79'' | D29: X | E29: X | F29: X | G29: X | H29: X | I29: X | J29: X | K29: X | L29: X | M29: X
C30: 84'' | J30: X | K30: X | L30: X | M30: X
C31: 96'' | J31: X | K31: X | L31: X | M31: X
B32: SANTA FE | C32: 79'' | D32: X | E32: X | F32: X | G32: X | H32: X | I32: X | J32: X | K32: X | L32: X | M32: X
C33: 84'' | J33: X | K33: X | L33: X | M33: X
C34: 96'' | J34: X | K34: X | L34: X | M34: X
D35: Non disponible / Not Available
C36: x | D36: Disponible / Available
B43: 43174
B44: 43047
B45: 42480
B46: 42480
B47: 42376
B48: 41593
...
