Workbook
Name Print_Titles_MI: 'Colonist-6 Panel'!$2:$15
Name Print_Titles_MI: Conmore!$2:$12
Name Print_Titles_MI: 'Conmore (2)'!$2:$12
Name Print_Titles_MI: 'Conmore (3)'!$2:$12
Name Print_Titles_MI: 'Flat Panel (Elite)'!$2:$12
Name Print_Titles_MI: 'Flat Panel Elite (2)'!$2:$12
Name Print_Titles_MI: 'Flat Panel Elite (3)'!$2:$12
Name Print_Titles_MI: 'Moulded Panel'!$2:$12
Name Print_Titles_MI: 'Moulded Panel (2)'!$2:$12
Name Print_Titles_MI: 'Moulded Panel (3)'!$2:$12
Name Print_Titles_MI: 'Primed Hardboard'!$2:$14
Name Print_Titles_MI: 'Primed Hardboard (2)'!$2:$14
Name Print_Titles_MI: 'Primed Hardboard (3)'!$2:$14

Sheet Cover
A18: Interior Door Price List
A20: NET PRICE LIST (May 4, 2025)
B26: HOME HARDWARE NON COMMITTED DEALERS - WEST

Sheet Colonist-6 Panel
A1: PRICE LIST
A2: NET PRICE LIST (May 4, 2025)
A3: HOME HARDWARE - NON COMMITTED WEST
A5: WOOD GRAIN
B12: COLONIST TEXTURED
A13: Slab | B13: 6'8", 7'0", 8'0"
A14: Bifold | B14: 6'8", 7'0", 8'0"
A16: Size | E16: Net Price
A17: Slab 1 3/8 hollow core
A18: 12" x 80" | C18: (1'0" x 6'8") | E18: 59.693878
A19: 14" x 80" | C19: (1'2" x 6'8") | E19: 59.693878
A20: 16" x 80" | C20: (1'4" x 6'8") | E20: 59.693878
A21: 18" x 80" | C21: (1'6" x 6'8") | E21: 59.693878
A22: 20" x 80" | C22: (1'8" x 6'8") | E22: 63.010204
A23: 22" x 80" | C23: (1'10" x 6'8") | E23: 63.010204
A24: 24" x 80" | C24: (2'0" x 6'8") | E24: 63.010204
A25: 26" x 80" | C25: (2'2" x 6'8") | E25: 65.255102
A26: 28" x 80" | C26: (2'4" x 6'8") | E26: 65.255102
A27: 30" x 80" | C27: (2'6" x 6'8") | E27: 65.255102
A28: 32" x 80" | C28: (2'8" x 6'8") | E28: 67.602041
A29: 34" x 80" | C29: (2'10" x 6'8") | E29: 70.918367
A30: 36" x 80" | C30: (3'0" x 6'8") | E30: 70.918367
A31: HEIGHT 84" Add | E31: 35.7
A32: HEIGHT 96" Add | E32: 97.35
A37: Special Colonist (6-Panel) pricing is only for 1-3/8 HC Slabs
A38: For all other configurations (bifolds, procore, 1-3/4, pro-reversible, prehungs) refer to pages 3, 4 & 5 (moulded doors)
A40: “6 panel slab pricing is temporary, and subject to change at JELD-WEN’s discretion, with 30 days notice, depending on market conditions”

Sheet Moulded Panel
A1: PRICE LIST
A2: ='Colonist-6 Panel'!A2 -> NET PRICE LIST (May 4, 2025)
A3: ='Colonist-6 Panel'!A3 -> HOME HARDWARE - NON COMMITTED WEST
A6: Moulded
C13: CARRARA | D13: EURO Only available in 38" width | E13: CAMDEN | F13: SANTA FE | G13: ROCKPORT | H13: COLONIST TEXTURED
A14: Slab | C14: 6'8", 7'0", 8'0" | D14: 6'8", 7'0" | E14: 6'8" | F14: 6'8", 7'0", 8'0" | G14: 6'8", 7'0", 8'0" | H14: 6'8", 7'0", 8'0"
A15: Bifold | C15: 6'8", 7'0" | D15: N/A | E15: 6'8" | F15: 6'8" | G15: 6'8" | H15: 6'8", 7'0", 8'0"
C17: Size | G17: ='Colonist-6 Panel'!E16 -> Net Price
C18: Slab 1 3/8 hollow core
C19: 12" x 80" | E19: (1'0" x 6'8") | G19: =K19 -> 63.265306 | K19: 63.265306
C20: 14" x 80" | E20: (1'2" x 6'8") | G20: =K20 -> 63.265306 | K20: 63.265306
C21: 16" x 80" | E21: (1'4" x 6'8") | G21: =K21 -> 63.265306 | K21: 63.265306
C22: 18" x 80" | E22: (1'6" x 6'8") | G22: =K22 -> 63.265306 | K22: 63.265306
C23: 20" x 80" | E23: (1'8" x 6'8") | G23: =K23 -> 66.581633 | K23: 66.581633
C24: 22" x 80" | E24: (1'10" x 6'8") | G24: =K24 -> 66.581633 | K24: 66.581633
C25: 24" x 80" | E25: (2'0" x 6'8") | G25: =K25 -> 66.581633 | K25: 66.581633
C26: 26" x 80" | E26: (2'2" x 6'8") | G26: =K26 -> 68.826531 | K26: 68.826531
C27: 28" x 80" | E27: (2'4" x 6'8") | G27: =K27 -> 68.826531 | K27: 68.826531
C28: 30" x 80" | E28: (2'6" x 6'8") | G28: =K28 -> 68.826531 | K28: 68.826531
C29: 32" x 80" | E29: (2'8" x 6'8") | G29: =K29 -> 71.173469 | K29: 71.173469
C30: 34" x 80" | E30: (2'10" x 6'8") | G30: =K30 -> 74.489796 | K30: 74.489796
... C32: 38" x 80" | E32: (3'2" x 6'8") Euro | G32: =K32 -> 101.73469 | K32: 101.73469
C33: HEIGHT 84" Add | G33: =K33 -> 35.7 | K33: 35.7
C34: HEIGHT 96" Add | G34: =K34 -> 97.35 | K34: 97.35
C35: Bifold 1 3/8 c/w hardware
C36: 18" x 80" | E36: (1'6" x 6'8") | G36: =K36 -> 82.908163 | K36: 82.908163
C37: 20" x 80" | E37: (1'8" x 6'8") | G37: =K37 -> 82.908163 | K37: 82.908163
C38: 22" x 80" | E38: (1'10" x 6'8") | G38: =K38 -> 82.908163 | K38: 82.908163
C39: 24" x 80" | E39: (2'0" x 6'8") | G39: =K39 -> 82.908163 | K39: 82.908163
C40: 26" x 80" | E40: (2'2" x 6'8") | G40: =K40 -> 90.663265 | K40: 90.663265
C41: 28" x 80" | E41: (2'4" x 6'8") | G41: =K41 -> 90.663265 | K41: 90.663265
C42: 30" x 80" | E42: (2'6" x 6'8") | G42: =K42 -> 90.663265 | K42: 90.663265
C43: 32" x 80" | E43: (2'8" x 6'8") | G43: =K43 -> 95.612245 | K43: 95.612245
C44: 34" x 80" | E44: (2'10" x 6'8") | G44: =K44 -> 95.612245 | K44: 95.612245
C45: 36" x 80" | E45: (3'0" x 6'8") | G45: =K45 -> 95.612245 | K45: 95.612245
C46: HEIGHT 84" Add | G46: =K46 -> 35.7 | K46: 35.7
C47: HEIGHT 96" Add | G47: =K47 -> 97.35 | K47: 97.35
C48: Slab 1 3/8 solid core (Procore)
C49: 12" x 80" | E49: (1'0" x 6'8") | G49: =K49 -> 143.31633 | K49: 143.31633
C50: 14" x 80" | E50: (1'2" x 6'8") | G50: =K50 -> 143.31633 | K50: 143.31633
...

Sheet Moulded Panel (2)
A1: PRICE LIST
A2: ='Colonist-6 Panel'!A2 -> NET PRICE LIST (May 4, 2025)
A3: ='Colonist-6 Panel'!A3 -> HOME HARDWARE - NON COMMITTED WEST
A6: Moulded
C13: CARRARA | D13: EURO Only available in 38" width | E13: CAMDEN | F13: SANTA FE | G13: ROCKPORT | H13: COLONIST TEXTURED | L13: Adder 2022 | M13: % Increase | N13: Adder May 2025 (Rounded up)
A14: Slab | C14: 6'8", 7'0", 8'0" | D14: 6'8", 7'0" | E14: 6'8" | F14: 6'8", 7'0", 8'0" | G14: 6'8", 7'0", 8'0" | H14: 6'8", 7'0", 8'0" | K14: Easy In | L14: 62 | M14: 0.06 | N14: =ROUNDUP(L14*(1+M14),0) -> 66
A15: Bifold | C15: 6'8", 7'0" | D15: N/A | E15: 6'8" | F15: 6'8" | G15: 6'8" | H15: 6'8", 7'0", 8'0" | K15: Prehung | L15: 75 | M15: 0.06 | N15: =ROUNDUP(L15*(1+M15),0) -> 80
C17: Size | G17: ='Colonist-6 Panel'!E16 -> Net Price
C18: 1 3/8" HC Easy-Install MDF 4 9/16 x 9/16 (KD Unit) | K18: Slab | L18: Adder | M18: Total
C19: 12" x 80" | E19: (1'0" x 6'8") | G19: =M19 -> 129.26531 | K19: ='Moulded Panel'!K19 -> 63.265306 | L19: 66 | M19: =K19+L19 -> 129.26531
C20: 14" x 80" | E20: (1'2" x 6'8") | G20: =M20 -> 129.26531 | K20: ='Moulded Panel'!K20 -> 63.265306 | L20: 66 | M20: =K20+L20 -> 129.26531
C21: 16" x 80" | E21: (1'4" x 6'8") | G21: =M21 -> 129.26531 | K21: ='Moulded Panel'!K21 -> 63.265306 | L21: 66 | M21: =K21+L21 -> 129.26531
C22: 18" x 80" | E22: (1'6" x 6'8") | G22: =M22 -> 129.26531 | K22: ='Moulded Panel'!K22 -> 63.265306 | L22: 66 | M22: =K22+L22 -> 129.26531
C23: 20" x 80" | E23: (1'8" x 6'8") | G23: =M23 -> 132.58163 | K23: ='Moulded Panel'!K23 -> 66.581633 | L23: 66 | M23: =K23+L23 -> 132.58163
C24: 22" x 80" | E24: (1'10" x 6'8") | G24: =M24 -> 132.58163 | K24: ='Moulded Panel'!K24 -> 66.581633 | L24: 66 | M24: =K24+L24 -> 132.58163
C25: 24" x 80" | E25: (2'0" x 6'8") | G25: =M25 -> 132.58163 | K25: ='Moulded Panel'!K25 -> 66.581633 | L25: 66 | M25: =K25+L25 -> 132.58163
C26: 26" x 80" | E26: (2'2" x 6'8") | G26: =M26 -> 134.82653 | K26: ='Moulded Panel'!K26 -> 68.826531 | L26: 66 | M26: =K26+L26 -> 134.82653
C27: 28" x 80" | E27: (2'4" x 6'8") | G27: =M27 -> 134.82653 | K27: ='Moulded Panel'!K27 -> 68.826531 | L27: 66 | M27: =K27+L27 -> 134.82653
C28: 30" x 80" | E28: (2'6" x 6'8") | G28: =M28 -> 134.82653 | K28: ='Moulded Panel'!K28 -> 68.826531 | L28: 66 | M28: =K28+L28 -> 134.82653
C29: 32" x 80" | E29: (2'8" x 6'8") | G29: =M29 -> 137.17347 | K29: ='Moulded Panel'!K29 -> 71.173469 | L29: 66 | M29: =K29+L29 -> 137.17347
C30: 34" x 80" | E30: (2'10" x 6'8") | G30: =M30 -> 140.4898 | K30: ='Moulded Panel'!K30 -> 74.489796 | L30: 66 | M30: =K30+L30 -> 140.4898
C31: 36" x 80" | E31: (3'0" x 6'8") | G31: =M31 -> 140.4898 | K31: ='Moulded Panel'!K31 -> 74.489796 | L31: 66 | M31: =K31+L31 -> 140.4898
C32: HEIGHT 84" Add | G32: =M32 -> 35.7 | M32: 35.7
C33: HEIGHT 96" Add | G33: =M33 -> 97.35 | M33: 97.35
C34: 1 3/8" HC Prehung FJ Primed 4 5/8 x 11/16 (assembled unit)
C35: 12" x 80" | E35: (1'0" x 6'8") | G35: =M35 -> 143.26531 | K35: ='Moulded Panel'!K19 -> 63.265306 | L35: 80 | M35: =K35+L35 -> 143.26531
C36: 14" x 80" | E36: (1'2" x 6'8") | G36: =M36 -> 143.26531 | K36: ='Moulded Panel'!K20 -> 63.265306 | L36: 80 | M36: =K36+L36 -> 143.26531
C37: 16" x 80" | E37: (1'4" x 6'8") | G37: =M37 -> 143.26531 | K37: ='Moulded Panel'!K21 -> 63.265306 | L37: 80 | M37: =K37+L37 -> 143.26531
C38: 18" x 80" | E38: (1'6" x 6'8") | G38: =M38 -> 143.26531 | K38: ='Moulded Panel'!K22 -> 63.265306 | L38: 80 | M38: =K38+L38 -> 143.26531
C39: 20" x 80" | E39: (1'8" x 6'8") | G39: =M39 -> 146.58163 | K39: ='Moulded Panel'!K23 -> 66.581633 | L39: 80 | M39: =K39+L39 -> 146.58163
C40: 22" x 80" | E40: (1'10" x 6'8") | G40: =M40 -> 146.58163 | K40: ='Moulded Panel'!K24 -> 66.581633 | L40: 80 | M40: =K40+L40 -> 146.58163
C41: 24" x 80" | E41: (2'0" x 6'8") | G41: =M41 -> 146.58163 | K41: ='Moulded Panel'!K25 -> 66.581633 | L41: 80 | M41: =K41+L41 -> 146.58163
C42: 26" x 80" | E42: (2'2" x 6'8") | G42: =M42 -> 148.82653 | K42: ='Moulded Panel'!K26 -> 68.826531 | L42: 80 | M42: =K42+L42 -> 148.82653
C43: 28" x 80" | E43: (2'4" x 6'8") | G43: =M43 -> 148.82653 | K43: ='Moulded Panel'!K27 -> 68.826531 | L43: 80 | M43: =K43+L43 -> 148.82653
C44: 30" x 80" | E44: (2'6" x 6'8") | G44: =M44 -> 148.82653 | K44: ='Moulded Panel'!K28 -> 68.826531 | L44: 80 | M44: =K44+L44 -> 148.82653
C45: 32" x 80" | E45: (2'8" x 6'8") | G45: =M45 -> 151.17347 | K45: ='Moulded Panel'!K29 -> 71.173469 | L45: 80 | M45: =K45+L45 -> 151.17347
C46: 34" x 80" | E46: (2'10" x 6'8") | G46: =M46 -> 154.4898 | K46: ='Moulded Panel'!K30 -> 74.489796 | L46: 80 | M46: =K46+L46 -> 154.4898
C47: 36" x 80" | E47: (3'0" x 6'8") | G47: =M47 -> 154.4898 | K47: ='Moulded Panel'!K31 -> 74.489796 | L47: 80 | M47: =K47+L47 -> 154.4898
C48: HEIGHT 84" Add | G48: =M48 -> 35.7 | M48: 35.7
C49: HEIGHT 96" Add | G49: =M49 -> 97.35 | M49: 97.35
...

Sheet Moulded Panel (3)
A1: PRICE LIST
A2: ='Colonist-6 Panel'!A2 -> NET PRICE LIST (May 4, 2025)
A3: ='Colonist-6 Panel'!A3 -> HOME HARDWARE - NON COMMITTED WEST
A6: Moulded
C13: CARRARA | D13: EURO Only available in 38" width | E13: CAMDEN | F13: SANTA FE | G13: ROCKPORT | H13: COLONIST TEXTURED
A14: Slab | C14: 6'8", 7'0", 8'0" | D14: 6'8", 7'0" | E14: 6'8" | F14: 6'8", 7'0", 8'0" | G14: 6'8", 7'0", 8'0" | H14: 6'8", 7'0", 8'0"
A15: Bifold | C15: 6'8", 7'0" | D15: N/A | E15: 6'8" | F15: 6'8" | G15: 6'8" | H15: 6'8", 7'0", 8'0"
C17: Size | G17: ='Colonist-6 Panel'!E16 -> Net Price
C18: Slab 1 3/4 hollow core
C19: 12" x 80" | E19: (1'0" x 6'8") | G19: =K19 -> 98.979592 | H19: 93.38 | K19: 98.979592
C20: 14" x 80" | E20: (1'2" x 6'8") | G20: =K20 -> 98.979592 | H20: 93.38 | K20: 98.979592
C21: 16" x 80" | E21: (1'4" x 6'8") | G21: =K21 -> 98.979592 | H21: 93.38 | K21: 98.979592
C22: 18" x 80" | E22: (1'6" x 6'8") | G22: =K22 -> 98.979592 | H22: 93.38 | K22: 98.979592
C23: 20" x 80" | E23: (1'8" x 6'8") | G23: =K23 -> 102.29592 | H23: 93.38 | K23: 102.29592
C24: 22" x 80" | E24: (1'10" x 6'8") | G24: =K24 -> 102.29592 | H24: 93.38 | K24: 102.29592
C25: 24" x 80" | E25: (2'0" x 6'8") | G25: =K25 -> 102.29592 | H25: 93.38 | K25: 102.29592
C26: 26" x 80" | E26: (2'2" x 6'8") | G26: =K26 -> 104.54082 | H26: 93.38 | K26: 104.54082
C27: 28" x 80" | E27: (2'4" x 6'8") | G27: =K27 -> 104.54082 | H27: 93.38 | K27: 104.54082
C28: 30" x 80" | E28: (2'6" x 6'8") | G28: =K28 -> 104.54082 | H28: 93.38 | K28: 104.54082
C29: 32" x 80" | E29: (2'8" x 6'8") | G29: =K29 -> 106.88776 | H29: 93.38 | K29: 106.88776
C30: 34" x 80" | E30: (2'10" x 6'8") | G30: =K30 -> 110.20408 | H30: 93.38 | K30: 110.20408
C31: 36" x 80" | E31: (3'0" x 6'8") | G31: =K31 -> 110.20408 | H31: 93.38 | K31: 110.20408
C32: HEIGHT 84" Add | G32: =K32 -> 5.4 | H32: 93.38 | K32: 5.4
C33: Slab 1 3/4 solid core
C34: 12" x 80" | E34: (1'0" x 6'8") | G34: =K34 -> 201.73469 | H34: 190.32 | K34: 201.73469
C35: 14" x 80" | E35: (1'2" x 6'8") | G35: =K35 -> 201.73469 | H35: 190.32 | K35: 201.73469
C36: 16" x 80" | E36: (1'4" x 6'8") | G36: =K36 -> 201.73469 | H36: 190.32 | K36: 201.73469
C37: 18" x 80" | E37: (1'6" x 6'8") | G37: =K37 -> 201.73469 | H37: 190.32 | K37: 201.73469
C38: 20" x 80" | E38: (1'8" x 6'8") | G38: =K38 -> 205.05102 | H38: 190.32 | K38: 205.05102
C39: 22" x 80" | E39: (1'10" x 6'8") | G39: =K39 -> 205.05102 | H39: 190.32 | K39: 205.05102
C40: 24" x 80" | E40: (2'0" x 6'8") | G40: =K40 -> 205.05102 | H40: 190.32 | K40: 205.05102
C41: 26" x 80" | E41: (2'2" x 6'8") | G41: =K41 -> 207.29592 | H41: 190.32 | K41: 207.29592
C42: 28" x 80" | E42: (2'4" x 6'8") | G42: =K42 -> 207.29592 | H42: 190.32 | K42: 207.29592
C43: 30" x 80" | E43: (2'6" x 6'8") | G43: =K43 -> 207.29592 | H43: 190.32 | K43: 207.29592
C44: 32" x 80" | E44: (2'8" x 6'8") | G44: =K44 -> 209.64286 | H44: 190.32 | K44: 209.64286
C45: 34" x 80" | E45: (2'10" x 6'8") | G45: =K45 -> 212.95918 | H45: 190.32 | K45: 212.95918
... C47: 38" x 80" | E47: (3'2" x 6'8") Euro | G47: =K47 -> 240.20408 | H47: 190.32 | K47: 240.20408
C48: HEIGHT 84" Add | G48: =K48 -> 18.35 | H48: 93.38 | K48: 18.35
C49: HEIGHT 96" Add | G49: =K49 -> 116.85 | H49: 93.38 | K49: 116.85
C51: Carrara and Euro sticking is not identical

Sheet Conmore
A1: PRICE LIST
A2: ='Colonist-6 Panel'!A2 -> NET PRICE LIST (May 4, 2025)
A3: ='Colonist-6 Panel'!A3 -> HOME HARDWARE - NON COMMITTED WEST
A6: Flat Panel
B13: CONMORE
A14: Slab | B14: 6'8", 7'0", 8'0"
A15: Bifold | B15: 6'8", 7'0"
A17: Size | E17: ='Colonist-6 Panel'!E16 -> Net Price
A18: Slab 1 3/8 hollow core
A19: 12" x 80" | C19: (1'0" x 6'8") | E19: 68.112245
A20: 14" x 80" | C20: (1'2" x 6'8") | E20: 68.112245
A21: 16" x 80" | C21: (1'4" x 6'8") | E21: 68.112245
A22: 18" x 80" | C22: (1'6" x 6'8") | E22: 68.112245
A23: 20" x 80" | C23: (1'8" x 6'8") | E23: 71.428571
A24: 22" x 80" | C24: (1'10" x 6'8") | E24: 71.428571
A25: 24" x 80" | C25: (2'0" x 6'8") | E25: 71.428571
A26: 26" x 80" | C26: (2'2" x 6'8") | E26: 73.673469
A27: 28" x 80" | C27: (2'4" x 6'8") | E27: 73.673469
A28: 30" x 80" | C28: (2'6" x 6'8") | E28: 73.673469
A29: 32" x 80" | C29: (2'8" x 6'8") | E29: 76.020408
A30: 34" x 80" | C30: (2'10" x 6'8") | E30: 79.336735
A31: 36" x 80" | C31: (3'0" x 6'8") | E31: 79.336735
A32: HEIGHT 84" Add | E32: 35.7
A33: HEIGHT 96" Add | E33: 97.35
A34: Bifold 1 3/8 c/w hardware
A35: 18" x 80" | C35: (1'6" x 6'8") | E35: 87.755102
A36: 20" x 80" | C36: (1'8" x 6'8") | E36: 87.755102
A37: 22" x 80" | C37: (1'10" x 6'8") | E37: 87.755102
A38: 24" x 80" | C38: (2'0" x 6'8") | E38: 87.755102
A39: 26" x 80" | C39: (2'2" x 6'8") | E39: 95.510204
A40: 28" x 80" | C40: (2'4" x 6'8") | E40: 95.510204
A41: 30" x 80" | C41: (2'6" x 6'8") | E41: 95.510204
A42: 32" x 80" | C42: (2'8" x 6'8") | E42: 100.45918
A43: 34" x 80" | C43: (2'10" x 6'8") | E43: 100.45918
A44: 36" x 80" | C44: (3'0" x 6'8") | E44: 100.45918
A45: HEIGHT 84" Add | E45: 35.7
A46: Slab 1 3/8 solid core (Procore)
A47: 12" x 80" | C47: (1'0" x 6'8") | E47: 148.16327
A48: 14" x 80" | C48: (1'2" x 6'8") | E48: 148.16327
A49: 16" x 80" | C49: (1'4" x 6'8") | E49: 148.16327
...

Sheet Conmore (2)
A1: PRICE LIST
A2: ='Colonist-6 Panel'!A2 -> NET PRICE LIST (May 4, 2025)
A3: ='Colonist-6 Panel'!A3 -> HOME HARDWARE - NON COMMITTED WEST
A6: Flat Panel
B13: CONMORE
A14: Slab | B14: 6'8", 7'0", 8'0" | I14: Adder 2022 | J14: % Increase | K14: Adder May 2025 (Rounded up)
A15: Bifold | B15: 6'8", 7'0" | H15: Easy In | I15: 62 | J15: 0.06 | K15: =ROUNDUP(I15*(1+J15),0) -> 66
H16: Prehung | I16: 75 | J16: 0.06 | K16: =ROUNDUP(I16*(1+J16),0) -> 80
A17: Size | E17: ='Colonist-6 Panel'!E16 -> Net Price
A18: 1 3/8" HC Easy-Install MDF 4 9/16 x 9/16 (KD Unit) | H18: Slab | I18: Adder | J18: Total
A19: 12" x 80" | C19: (1'0" x 6'8") | E19: =J19 -> 134.11224 | H19: =Conmore!E19 -> 68.112245 | I19: 66 | J19: =H19+I19 -> 134.11224
A20: 14" x 80" | C20: (1'2" x 6'8") | E20: =J20 -> 134.11224 | H20: =Conmore!E20 -> 68.112245 | I20: 66 | J20: =H20+I20 -> 134.11224
A21: 16" x 80" | C21: (1'4" x 6'8") | E21: =J21 -> 134.11224 | H21: =Conmore!E21 -> 68.112245 | I21: 66 | J21: =H21+I21 -> 134.11224
A22: 18" x 80" | C22: (1'6" x 6'8") | E22: =J22 -> 134.11224 | H22: =Conmore!E22 -> 68.112245 | I22: 66 | J22: =H22+I22 -> 134.11224
A23: 20" x 80" | C23: (1'8" x 6'8") | E23: =J23 -> 137.42857 | H23: =Conmore!E23 -> 71.428571 | I23: 66 | J23: =H23+I23 -> 137.42857
A24: 22" x 80" | C24: (1'10" x 6'8") | E24: =J24 -> 137.42857 | H24: =Conmore!E24 -> 71.428571 | I24: 66 | J24: =H24+I24 -> 137.42857
A25: 24" x 80" | C25: (2'0" x 6'8") | E25: =J25 -> 137.42857 | H25: =Conmore!E25 -> 71.428571 | I25: 66 | J25: =H25+I25 -> 137.42857
A26: 26" x 80" | C26: (2'2" x 6'8") | E26: =J26 -> 139.67347 | H26: =Conmore!E26 -> 73.673469 | I26: 66 | J26: =H26+I26 -> 139.67347
A27: 28" x 80" | C27: (2'4" x 6'8") | E27: =J27 -> 139.67347 | H27: =Conmore!E27 -> 73.673469 | I27: 66 | J27: =H27+I27 -> 139.67347
A28: 30" x 80" | C28: (2'6" x 6'8") | E28: =J28 -> 139.67347 | H28: =Conmore!E28 -> 73.673469 | I28: 66 | J28: =H28+I28 -> 139.67347
A29: 32" x 80" | C29: (2'8" x 6'8") | E29: =J29 -> 142.02041 | H29: =Conmore!E29 -> 76.020408 | I29: 66 | J29: =H29+I29 -> 142.02041
A30: 34" x 80" | C30: (2'10" x 6'8") | E30: =J30 -> 145.33673 | H30: =Conmore!E30 -> 79.336735 | I30: 66 | J30: =H30+I30 -> 145.33673
A31: 36" x 80" | C31: (3'0" x 6'8") | E31: =J31 -> 145.33673 | H31: =Conmore!E31 -> 79.336735 | I31: 66 | J31: =H31+I31 -> 145.33673
A32: HEIGHT 84" Add | E32: =J32 -> 35.7 | J32: 35.7
A33: HEIGHT 96" Add | E33: =J33 -> 97.35 | J33: 97.35
A34: 1 3/8" HC Prehung FJ Primed 4 5/8 x 11/16 (assembled unit)
A35: 12" x 80" | C35: (1'0" x 6'8") | E35: =J35 -> 148.11224 | H35: =H19 -> 68.112245 | I35: 80 | J35: =H35+I35 -> 148.11224
A36: 14" x 80" | C36: (1'2" x 6'8") | E36: =J36 -> 148.11224 | H36: =H20 -> 68.112245 | I36: 80 | J36: =H36+I36 -> 148.11224
A37: 16" x 80" | C37: (1'4" x 6'8") | E37: =J37 -> 148.11224 | H37: =H21 -> 68.112245 | I37: 80 | J37: =H37+I37 -> 148.11224
A38: 18" x 80" | C38: (1'6" x 6'8") | E38: =J38 -> 148.11224 | H38: =H22 -> 68.112245 | I38: 80 | J38: =H38+I38 -> 148.11224
A39: 20" x 80" | C39: (1'8" x 6'8") | E39: =J39 -> 151.42857 | H39: =H23 -> 71.428571 | I39: 80 | J39: =H39+I39 -> 151.42857
A40: 22" x 80" | C40: (1'10" x 6'8") | E40: =J40 -> 151.42857 | H40: =H24 -> 71.428571 | I40: 80 | J40: =H40+I40 -> 151.42857
A41: 24" x 80" | C41: (2'0" x 6'8") | E41: =J41 -> 151.42857 | H41: =H25 -> 71.428571 | I41: 80 | J41: =H41+I41 -> 151.42857
A42: 26" x 80" | C42: (2'2" x 6'8") | E42: =J42 -> 153.67347 | H42: =H26 -> 73.673469 | I42: 80 | J42: =H42+I42 -> 153.67347
A43: 28" x 80" | C43: (2'4" x 6'8") | E43: =J43 -> 153.67347 | H43: =H27 -> 73.673469 | I43: 80 | J43: =H43+I43 -> 153.67347
A44: 30" x 80" | C44: (2'6" x 6'8") | E44: =J44 -> 153.67347 | H44: =H28 -> 73.673469 | I44: 80 | J44: =H44+I44 -> 153.67347
A45: 32" x 80" | C45: (2'8" x 6'8") | E45: =J45 -> 156.02041 | H45: =H29 -> 76.020408 | I45: 80 | J45: =H45+I45 -> 156.02041
A46: 34" x 80" | C46: (2'10" x 6'8") | E46: =J46 -> 159.33673 | H46: =H30 -> 79.336735 | I46: 80 | J46: =H46+I46 -> 159.33673
A47: 36" x 80" | C47: (3'0" x 6'8") | E47: =J47 -> 159.33673 | H47: =H31 -> 79.336735 | I47: 80 | J47: =H47+I47 -> 159.33673
A48: HEIGHT 84" Add | E48: =J48 -> 35.7 | J48: 35.7
...

Sheet Conmore (3)
A1: PRICE LIST
A2: ='Colonist-6 Panel'!A2 -> NET PRICE LIST (May 4, 2025)
A3: ='Colonist-6 Panel'!A3 -> HOME HARDWARE - NON COMMITTED WEST
A6: Flat Panel
B13: CONMORE
A14: Slab | B14: 6'8", 7'0", 8'0"
A15: Bifold | B15: 6'8", 7'0"
A17: Size | E17: ='Colonist-6 Panel'!E16 -> Net Price
A18: Slab 1 3/4 hollow core
A19: 12" x 80" | C19: (1'0" x 6'8") | E19: N/A
A20: 14" x 80" | C20: (1'2" x 6'8") | E20: N/A
A21: 16" x 80" | C21: (1'4" x 6'8") | E21: N/A
A22: 18" x 80" | C22: (1'6" x 6'8") | E22: N/A
A23: 20" x 80" | C23: (1'8" x 6'8") | E23: N/A
A24: 22" x 80" | C24: (1'10" x 6'8") | E24: N/A
A25: 24" x 80" | C25: (2'0" x 6'8") | E25: N/A
A26: 26" x 80" | C26: (2'2" x 6'8") | E26: N/A
A27: 28" x 80" | C27: (2'4" x 6'8") | E27: N/A
A28: 30" x 80" | C28: (2'6" x 6'8") | E28: N/A
A29: 32" x 80" | C29: (2'8" x 6'8") | E29: N/A
A30: 34" x 80" | C30: (2'10" x 6'8") | E30: N/A
A31: 36" x 80" | C31: (3'0" x 6'8") | E31: N/A
A32: Slab 1 3/4 solid core
A33: 12" x 80" | C33: (1'0" x 6'8") | E33: 206.58163
A34: 14" x 80" | C34: (1'2" x 6'8") | E34: 206.58163
A35: 16" x 80" | C35: (1'4" x 6'8") | E35: 206.58163
A36: 18" x 80" | C36: (1'6" x 6'8") | E36: 206.58163
A37: 20" x 80" | C37: (1'8" x 6'8") | E37: 209.89796
A38: 22" x 80" | C38: (1'10" x 6'8") | E38: 209.89796
A39: 24" x 80" | C39: (2'0" x 6'8") | E39: 209.89796
A40: 26" x 80" | C40: (2'2" x 6'8") | E40: 212.14286
A41: 28" x 80" | C41: (2'4" x 6'8") | E41: 212.14286
A42: 30" x 80" | C42: (2'6" x 6'8") | E42: 212.14286
A43: 32" x 80" | C43: (2'8" x 6'8") | E43: 214.4898
A44: 34" x 80" | C44: (2'10" x 6'8") | E44: 217.80612
A45: 36" x 80" | C45: (3'0" x 6'8") | E45: 217.80612
A46: HEIGHT 84" Add | E46: 18.35
A47: HEIGHT 96" Add | E47: 116.85

Sheet Flat Panel (Elite)
A1: PRICE LIST
A2: ='Colonist-6 Panel'!A2 -> NET PRICE LIST (May 4, 2025)
A3: ='Colonist-6 Panel'!A3 -> HOME HARDWARE - NON COMMITTED WEST
A6: Flat Panel
B13: CRAFTSMAN | C13: MADISON | D13: MONROE | E13: BIRKDALE
A14: Slab | B14: 6'8", 7'0" | C14: 6'8", 7'0", 8'0" | D14: 6'8", 7'0", 8'0" | E14: 6'8", 7'0", 8'0"
A15: Bifold | B15: 6'8", 7'0" | C15: 6'8", 7'0" | D15: 6'8", 7'0" | E15: 6'8", 7'0"
A17: Size | E17: ='Colonist-6 Panel'!E16 -> Net Price
A18: Slab 1 3/8 hollow core
A19: 12" x 80" | C19: (1'0" x 6'8") | E19: =H19 -> 75.153061 | F19: 70.93 | H19: 75.153061
A20: 14" x 80" | C20: (1'2" x 6'8") | E20: =H20 -> 75.153061 | F20: 70.93 | H20: 75.153061
A21: 16" x 80" | C21: (1'4" x 6'8") | E21: =H21 -> 75.153061 | F21: 70.93 | H21: 75.153061
A22: 18" x 80" | C22: (1'6" x 6'8") | E22: =H22 -> 75.153061 | F22: 70.93 | H22: 75.153061
A23: 20" x 80" | C23: (1'8" x 6'8") | E23: =H23 -> 78.469388 | F23: 70.93 | H23: 78.469388
A24: 22" x 80" | C24: (1'10" x 6'8") | E24: =H24 -> 78.469388 | F24: 70.93 | H24: 78.469388
A25: 24" x 80" | C25: (2'0" x 6'8") | E25: =H25 -> 78.469388 | F25: 70.93 | H25: 78.469388
A26: 26" x 80" | C26: (2'2" x 6'8") | E26: =H26 -> 80.714286 | F26: 70.93 | H26: 80.714286
A27: 28" x 80" | C27: (2'4" x 6'8") | E27: =H27 -> 80.714286 | F27: 70.93 | H27: 80.714286
A28: 30" x 80" | C28: (2'6" x 6'8") | E28: =H28 -> 80.714286 | F28: 70.93 | H28: 80.714286
A29: 32" x 80" | C29: (2'8" x 6'8") | E29: =H29 -> 83.061224 | F29: 70.93 | H29: 83.061224
A30: 34" x 80" | C30: (2'10" x 6'8") | E30: =H30 -> 86.377551 | F30: 70.93 | H30: 86.377551
A31: 36" x 80" | C31: (3'0" x 6'8") | E31: =H31 -> 86.377551 | F31: 70.93 | H31: 86.377551
A32: HEIGHT 84" Add | E32: =H32 -> 35.7 | F32: 70.93 | H32: 35.7
A33: HEIGHT 96" Add | E33: =H33 -> 97.35 | F33: 70.93 | H33: 97.35
A34: Bifold 1 3/8 c/w hardware
A35: 18" x 80" | C35: (1'6" x 6'8") | E35: =H35 -> 94.795918 | F35: 70.93 | H35: 94.795918
A36: 20" x 80" | C36: (1'8" x 6'8") | E36: =H36 -> 94.795918 | F36: 70.93 | H36: 94.795918
A37: 22" x 80" | C37: (1'10" x 6'8") | E37: =H37 -> 94.795918 | F37: 70.93 | H37: 94.795918
A38: 24" x 80" | C38: (2'0" x 6'8") | E38: =H38 -> 94.795918 | F38: 70.93 | H38: 94.795918
A39: 26" x 80" | C39: (2'2" x 6'8") | E39: =H39 -> 102.55102 | F39: 70.93 | H39: 102.55102
A40: 28" x 80" | C40: (2'4" x 6'8") | E40: =H40 -> 102.55102 | F40: 70.93 | H40: 102.55102
A41: 30" x 80" | C41: (2'6" x 6'8") | E41: =H41 -> 102.55102 | F41: 70.93 | H41: 102.55102
A42: 32" x 80" | C42: (2'8" x 6'8") | E42: =H42 -> 107.5 | F42: 70.93 | H42: 107.5
A43: 34" x 80" | C43: (2'10" x 6'8") | E43: =H43 -> 107.5 | F43: 70.93 | H43: 107.5
A44: 36" x 80" | C44: (3'0" x 6'8") | E44: =H44 -> 107.5 | F44: 70.93 | H44: 107.5
A45: HEIGHT 84" Add | E45: =H45 -> 35.7 | F45: 70.93 | H45: 35.7
A46: HEIGHT 96" Add | E46: =H46 -> 97.35 | F46: 70.93 | H46: 97.35
A47: Slab 1 3/8 solid core (Procore)
A48: 12" x 80" | C48: (1'0" x 6'8") | E48: =H48 -> 155.20408 | F48: 70.93 | H48: 155.20408
A49: 14" x 80" | C49: (1'2" x 6'8") | E49: =H49 -> 155.20408 | F49: 70.93 | H49: 155.20408
...

Sheet Flat Panel Elite (2)
A1: PRICE LIST
A2: ='Colonist-6 Panel'!A2 -> NET PRICE LIST (May 4, 2025)
A3: ='Colonist-6 Panel'!A3 -> HOME HARDWARE - NON COMMITTED WEST
A6: Flat Panel
B13: CRAFTSMAN | C13: MADISON | D13: MONROE | E13: BIRKDALE | I13: Adder 2022 | J13: % Increase | K13: Adder May 2025 (Rounded up)
A14: Slab | B14: 6'8", 7'0" | C14: 6'8", 7'0", 8'0" | D14: 6'8", 7'0", 8'0" | E14: 6'8", 7'0", 8'0" | H14: Easy In | I14: 62 | J14: 0.06 | K14: =ROUNDUP(I14*(1+J14),0) -> 66
A15: Bifold | B15: 6'8", 7'0" | C15: 6'8", 7'0" | D15: 6'8", 7'0" | E15: 6'8", 7'0" | H15: Prehung | I15: 75 | J15: 0.06 | K15: =ROUNDUP(I15*(1+J15),0) -> 80
A17: Size | E17: ='Colonist-6 Panel'!E16 -> Net Price
A18: 1 3/8" HC Easy-Install MDF 4 9/16 x 9/16 (KD Unit) | H18: Slab | I18: Adder | J18: Total
A19: 12" x 80" | C19: (1'0" x 6'8") | E19: =J19 -> 141.15306 | H19: ='Flat Panel (Elite)'!H19 -> 75.153061 | I19: 66 | J19: =H19+I19 -> 141.15306
A20: 14" x 80" | C20: (1'2" x 6'8") | E20: =J20 -> 141.15306 | H20: ='Flat Panel (Elite)'!H20 -> 75.153061 | I20: 66 | J20: =H20+I20 -> 141.15306
A21: 16" x 80" | C21: (1'4" x 6'8") | E21: =J21 -> 141.15306 | H21: ='Flat Panel (Elite)'!H21 -> 75.153061 | I21: 66 | J21: =H21+I21 -> 141.15306
A22: 18" x 80" | C22: (1'6" x 6'8") | E22: =J22 -> 141.15306 | H22: ='Flat Panel (Elite)'!H22 -> 75.153061 | I22: 66 | J22: =H22+I22 -> 141.15306
A23: 20" x 80" | C23: (1'8" x 6'8") | E23: =J23 -> 144.46939 | H23: ='Flat Panel (Elite)'!H23 -> 78.469388 | I23: 66 | J23: =H23+I23 -> 144.46939
A24: 22" x 80" | C24: (1'10" x 6'8") | E24: =J24 -> 144.46939 | H24: ='Flat Panel (Elite)'!H24 -> 78.469388 | I24: 66 | J24: =H24+I24 -> 144.46939
A25: 24" x 80" | C25: (2'0" x 6'8") | E25: =J25 -> 144.46939 | H25: ='Flat Panel (Elite)'!H25 -> 78.469388 | I25: 66 | J25: =H25+I25 -> 144.46939
A26: 26" x 80" | C26: (2'2" x 6'8") | E26: =J26 -> 146.71429 | H26: ='Flat Panel (Elite)'!H26 -> 80.714286 | I26: 66 | J26: =H26+I26 -> 146.71429
A27: 28" x 80" | C27: (2'4" x 6'8") | E27: =J27 -> 146.71429 | H27: ='Flat Panel (Elite)'!H27 -> 80.714286 | I27: 66 | J27: =H27+I27 -> 146.71429
A28: 30" x 80" | C28: (2'6" x 6'8") | E28: =J28 -> 146.71429 | H28: ='Flat Panel (Elite)'!H28 -> 80.714286 | I28: 66 | J28: =H28+I28 -> 146.71429
A29: 32" x 80" | C29: (2'8" x 6'8") | E29: =J29 -> 149.06122 | H29: ='Flat Panel (Elite)'!H29 -> 83.061224 | I29: 66 | J29: =H29+I29 -> 149.06122
A30: 34" x 80" | C30: (2'10" x 6'8") | E30: =J30 -> 152.37755 | H30: ='Flat Panel (Elite)'!H30 -> 86.377551 | I30: 66 | J30: =H30+I30 -> 152.37755
A31: 36" x 80" | C31: (3'0" x 6'8") | E31: =J31 -> 152.37755 | H31: ='Flat Panel (Elite)'!H31 -> 86.377551 | I31: 66 | J31: =H31+I31 -> 152.37755
A32: HEIGHT 84" Add | E32: =J32 -> 35.7 | J32: 35.7
A33: HEIGHT 96" Add | E33: =J33 -> 97.35 | J33: 97.35
A34: 1 3/8" HC Prehung FJ Primed 4 5/8 x 11/16 (assembled unit)
A35: 12" x 80" | C35: (1'0" x 6'8") | E35: =J35 -> 155.15306 | H35: =H19 -> 75.153061 | I35: 80 | J35: =H35+I35 -> 155.15306
A36: 14" x 80" | C36: (1'2" x 6'8") | E36: =J36 -> 155.15306 | H36: =H20 -> 75.153061 | I36: 80 | J36: =H36+I36 -> 155.15306
A37: 16" x 80" | C37: (1'4" x 6'8") | E37: =J37 -> 155.15306 | H37: =H21 -> 75.153061 | I37: 80 | J37: =H37+I37 -> 155.15306
A38: 18" x 80" | C38: (1'6" x 6'8") | E38: =J38 -> 155.15306 | H38: =H22 -> 75.153061 | I38: 80 | J38: =H38+I38 -> 155.15306
A39: 20" x 80" | C39: (1'8" x 6'8") | E39: =J39 -> 158.46939 | H39: =H23 -> 78.469388 | I39: 80 | J39: =H39+I39 -> 158.46939
A40: 22" x 80" | C40: (1'10" x 6'8") | E40: =J40 -> 158.46939 | H40: =H24 -> 78.469388 | I40: 80 | J40: =H40+I40 -> 158.46939
A41: 24" x 80" | C41: (2'0" x 6'8") | E41: =J41 -> 158.46939 | H41: =H25 -> 78.469388 | I41: 80 | J41: =H41+I41 -> 158.46939
A42: 26" x 80" | C42: (2'2" x 6'8") | E42: =J42 -> 160.71429 | H42: =H26 -> 80.714286 | I42: 80 | J42: =H42+I42 -> 160.71429
A43: 28" x 80" | C43: (2'4" x 6'8") | E43: =J43 -> 160.71429 | H43: =H27 -> 80.714286 | I43: 80 | J43: =H43+I43 -> 160.71429
A44: 30" x 80" | C44: (2'6" x 6'8") | E44: =J44 -> 160.71429 | H44: =H28 -> 80.714286 | I44: 80 | J44: =H44+I44 -> 160.71429
A45: 32" x 80" | C45: (2'8" x 6'8") | E45: =J45 -> 163.06122 | H45: =H29 -> 83.061224 | I45: 80 | J45: =H45+I45 -> 163.06122
A46: 34" x 80" | C46: (2'10" x 6'8") | E46: =J46 -> 166.37755 | H46: =H30 -> 86.377551 | I46: 80 | J46: =H46+I46 -> 166.37755
A47: 36" x 80" | C47: (3'0" x 6'8") | E47: =J47 -> 166.37755 | H47: =H31 -> 86.377551 | I47: 80 | J47: =H47+I47 -> 166.37755
A48: HEIGHT 84" Add | E48: =J48 -> 35.7 | J48: 35.7
A49: HEIGHT 96" Add | E49: =J49 -> 97.35 | J49: 97.35

Sheet Flat Panel Elite (3)
A1: PRICE LIST
A2: ='Colonist-6 Panel'!A2 -> NET PRICE LIST (May 4, 2025)
A3: ='Colonist-6 Panel'!A3 -> HOME HARDWARE - NON COMMITTED WEST
A6: Flat Panel
B13: CRAFTSMAN | C13: MADISON | D13: MONROE | E13: BIRKDALE
A14: Slab | B14: 6'8", 7'0" | C14: 6'8", 7'0", 8'0" | D14: 6'8", 7'0", 8'0" | E14: 6'8", 7'0", 8'0"
A15: Bifold | B15: 6'8", 7'0" | C15: 6'8", 7'0" | D15: 6'8", 7'0" | E15: 6'8", 7'0"
A17: Size | E17: ='Colonist-6 Panel'!E16 -> Net Price
A18: Slab 1 3/4 hollow core
A19: 12" x 80" | C19: (1'0" x 6'8") | E19: N/A
A20: 14" x 80" | C20: (1'2" x 6'8") | E20: N/A
A21: 16" x 80" | C21: (1'4" x 6'8") | E21: N/A
A22: 18" x 80" | C22: (1'6" x 6'8") | E22: N/A
A23: 20" x 80" | C23: (1'8" x 6'8") | E23: N/A
A24: 22" x 80" | C24: (1'10" x 6'8") | E24: N/A
A25: 24" x 80" | C25: (2'0" x 6'8") | E25: N/A
A26: 26" x 80" | C26: (2'2" x 6'8") | E26: N/A
A27: 28" x 80" | C27: (2'4" x 6'8") | E27: N/A
A28: 30" x 80" | C28: (2'6" x 6'8") | E28: N/A
A29: 32" x 80" | C29: (2'8" x 6'8") | E29: N/A
A30: 34" x 80" | C30: (2'10" x 6'8") | E30: N/A
A31: 36" x 80" | C31: (3'0" x 6'8") | E31: N/A
A32: Slab 1 3/4 solid core
A33: 12" x 80" | C33: (1'0" x 6'8") | E33: =H33 -> 213.62245 | F33: 201.54 | H33: 213.62245
A34: 14" x 80" | C34: (1'2" x 6'8") | E34: =H34 -> 213.62245 | F34: 201.54 | H34: 213.62245
A35: 16" x 80" | C35: (1'4" x 6'8") | E35: =H35 -> 213.62245 | F35: 201.54 | H35: 213.62245
A36: 18" x 80" | C36: (1'6" x 6'8") | E36: =H36 -> 213.62245 | F36: 201.54 | H36: 213.62245
A37: 20" x 80" | C37: (1'8" x 6'8") | E37: =H37 -> 216.93878 | F37: 201.54 | H37: 216.93878
A38: 22" x 80" | C38: (1'10" x 6'8") | E38: =H38 -> 216.93878 | F38: 201.54 | H38: 216.93878
A39: 24" x 80" | C39: (2'0" x 6'8") | E39: =H39 -> 216.93878 | F39: 201.54 | H39: 216.93878
A40: 26" x 80" | C40: (2'2" x 6'8") | E40: =H40 -> 219.18367 | F40: 201.54 | H40: 219.18367
A41: 28" x 80" | C41: (2'4" x 6'8") | E41: =H41 -> 219.18367 | F41: 201.54 | H41: 219.18367
A42: 30" x 80" | C42: (2'6" x 6'8") | E42: =H42 -> 219.18367 | F42: 201.54 | H42: 219.18367
A43: 32" x 80" | C43: (2'8" x 6'8") | E43: =H43 -> 221.53061 | F43: 201.54 | H43: 221.53061
A44: 34" x 80" | C44: (2'10" x 6'8") | E44: =H44 -> 224.84694 | F44: 201.54 | H44: 224.84694
A45: 36" x 80" | C45: (3'0" x 6'8") | E45: =H45 -> 224.84694 | F45: 201.54 | H45: 224.84694
A46: HEIGHT 84" Add | E46: =H46 -> 18.35 | F46: 201.54 | H46: 18.35
A47: HEIGHT 96" Add | E47: =H47 -> 116.85 | F47: 201.54 | H47: 116.85

Sheet Primed Hardboard
A1: PRICE LIST
A2: ='Colonist-6 Panel'!A2 -> NET PRICE LIST (May 4, 2025)
A3: ='Colonist-6 Panel'!A3 -> HOME HARDWARE - NON COMMITTED WEST
A5: PRIMED HARDBOARD
A12: Slab | B12: 6'8", 7'0", 8'0"
A13: Bifold | B13: 6'8", 7'0", 8'0"
A15: Size | E15: ='Colonist-6 Panel'!E16 -> Net Price
A16: Slab 1 3/8 hollow core
A17: 12" x 80" | C17: (1'0" x 6'8") | E17: 50.204082
A18: 14" x 80" | C18: (1'2" x 6'8") | E18: 50.204082
A19: 16" x 80" | C19: (1'4" x 6'8") | E19: 50.204082
A20: 18" x 80" | C20: (1'6" x 6'8") | E20: 50.204082
A21: 20" x 80" | C21: (1'8" x 6'8") | E21: 51.377551
A22: 22" x 80" | C22: (1'10" x 6'8") | E22: 51.377551
A23: 24" x 80" | C23: (2'0" x 6'8") | E23: 51.377551
A24: 26" x 80" | C24: (2'2" x 6'8") | E24: 54.642857
A25: 28" x 80" | C25: (2'4" x 6'8") | E25: 54.642857
A26: 30" x 80" | C26: (2'6" x 6'8") | E26: 54.642857
A27: 32" x 80" | C27: (2'8" x 6'8") | E27: 56.632653
A28: 34" x 80" | C28: (2'10" x 6'8") | E28: 61.326531
... A30: 38" x 80" | C30: (3'2" x 6'8") | E30: 88.877551
A31: HEIGHT 84" Add | E31: 35.7
A32: HEIGHT 96" Add | E32: 83.25
A33: Bifold 1 3/8 c/w hardware
A34: 18" x 80" | C34: (1'6" x 6'8") | E34: 66.887755
A35: 20" x 80" | C35: (1'8" x 6'8") | E35: 66.887755
A36: 22" x 80" | C36: (1'10" x 6'8") | E36: 66.887755
A37: 24" x 80" | C37: (2'0" x 6'8") | E37: 66.887755
A38: 26" x 80" | C38: (2'2" x 6'8") | E38: 72.908163
A39: 28" x 80" | C39: (2'4" x 6'8") | E39: 72.908163
A40: 30" x 80" | C40: (2'6" x 6'8") | E40: 72.908163
A41: 32" x 80" | C41: (2'8" x 6'8") | E41: 78.265306
A42: 34" x 80" | C42: (2'10" x 6'8") | E42: 78.265306
A43: 36" x 80" | C43: (3'0" x 6'8") | E43: 78.265306
A44: HEIGHT 84" Add | E44: 35.7
A45: HEIGHT 96" Add | E45: 83.25
A46: Slab 1 3/8 solid core (Procore)
A47: 12" x 80" | C47: (1'0" x 6'8") | E47: 119.43878
A48: 14" x 80" | C48: (1'2" x 6'8") | E48: 119.43878
A49: 16" x 80" | C49: (1'4" x 6'8") | E49: 119.43878
...

Sheet Primed Hardboard (2)
A1: PRICE LIST
A2: ='Colonist-6 Panel'!A2 -> NET PRICE LIST (May 4, 2025)
A3: ='Colonist-6 Panel'!A3 -> HOME HARDWARE - NON COMMITTED WEST
A5: PRIMED HARDBOARD
A12: Slab | B12: 6'8", 7'0", 8'0"
A13: Bifold | B13: 6'8", 7'0", 8'0" | I13: Adder 2022 | J13: % Increase | K13: Adder May 2025 (Rounded up)
H14: Easy In | I14: 62 | J14: 0.06 | K14: =ROUNDUP(I14*(1+J14),0) -> 66
A15: Size | E15: ='Colonist-6 Panel'!E16 -> Net Price | H15: Prehung | I15: 75 | J15: 0.06 | K15: =ROUNDUP(I15*(1+J15),0) -> 80
A16: 1 3/8" HC Easy-Install MDF 4 9/16 x 9/16 (KD Unit)
A17: 12" x 80" | C17: (1'0" x 6'8") | E17: =J17 -> 116.20408 | H17: ='Primed Hardboard'!E17 -> 50.204082 | I17: 66 | J17: =H17+I17 -> 116.20408
A18: 14" x 80" | C18: (1'2" x 6'8") | E18: =J18 -> 116.20408 | H18: ='Primed Hardboard'!E18 -> 50.204082 | I18: 66 | J18: =H18+I18 -> 116.20408
A19: 16" x 80" | C19: (1'4" x 6'8") | E19: =J19 -> 116.20408 | H19: ='Primed Hardboard'!E19 -> 50.204082 | I19: 66 | J19: =H19+I19 -> 116.20408
A20: 18" x 80" | C20: (1'6" x 6'8") | E20: =J20 -> 116.20408 | H20: ='Primed Hardboard'!E20 -> 50.204082 | I20: 66 | J20: =H20+I20 -> 116.20408
A21: 20" x 80" | C21: (1'8" x 6'8") | E21: =J21 -> 117.37755 | H21: ='Primed Hardboard'!E21 -> 51.377551 | I21: 66 | J21: =H21+I21 -> 117.37755
A22: 22" x 80" | C22: (1'10" x 6'8") | E22: =J22 -> 117.37755 | H22: ='Primed Hardboard'!E22 -> 51.377551 | I22: 66 | J22: =H22+I22 -> 117.37755
A23: 24" x 80" | C23: (2'0" x 6'8") | E23: =J23 -> 117.37755 | H23: ='Primed Hardboard'!E23 -> 51.377551 | I23: 66 | J23: =H23+I23 -> 117.37755
A24: 26" x 80" | C24: (2'2" x 6'8") | E24: =J24 -> 120.64286 | H24: ='Primed Hardboard'!E24 -> 54.642857 | I24: 66 | J24: =H24+I24 -> 120.64286
A25: 28" x 80" | C25: (2'4" x 6'8") | E25: =J25 -> 120.64286 | H25: ='Primed Hardboard'!E25 -> 54.642857 | I25: 66 | J25: =H25+I25 -> 120.64286
A26: 30" x 80" | C26: (2'6" x 6'8") | E26: =J26 -> 120.64286 | H26: ='Primed Hardboard'!E26 -> 54.642857 | I26: 66 | J26: =H26+I26 -> 120.64286
A27: 32" x 80" | C27: (2'8" x 6'8") | E27: =J27 -> 122.63265 | H27: ='Primed Hardboard'!E27 -> 56.632653 | I27: 66 | J27: =H27+I27 -> 122.63265
A28: 34" x 80" | C28: (2'10" x 6'8") | E28: =J28 -> 127.32653 | H28: ='Primed Hardboard'!E28 -> 61.326531 | I28: 66 | J28: =H28+I28 -> 127.32653
A29: 36" x 80" | C29: (3'0" x 6'8") | E29: =J29 -> 127.32653 | H29: ='Primed Hardboard'!E29 -> 61.326531 | I29: 66 | J29: =H29+I29 -> 127.32653
A30: HEIGHT 84" Add | E30: =J30 -> 35.7 | J30: 35.7
A31: HEIGHT 96" Add | E31: =J31 -> 83.25 | J31: 83.25
A32: 1 3/8" HC Prehung FJ Primed 4 5/8 x 11/16 (assembled unit)
A33: 12" x 80" | C33: (1'0" x 6'8") | E33: =J33 -> 130.20408 | H33: =H17 -> 50.204082 | I33: 80 | J33: =H33+I33 -> 130.20408
A34: 14" x 80" | C34: (1'2" x 6'8") | E34: =J34 -> 130.20408 | H34: =H18 -> 50.204082 | I34: 80 | J34: =H34+I34 -> 130.20408
A35: 16" x 80" | C35: (1'4" x 6'8") | E35: =J35 -> 130.20408 | H35: =H19 -> 50.204082 | I35: 80 | J35: =H35+I35 -> 130.20408
A36: 18" x 80" | C36: (1'6" x 6'8") | E36: =J36 -> 130.20408 | H36: =H20 -> 50.204082 | I36: 80 | J36: =H36+I36 -> 130.20408
A37: 20" x 80" | C37: (1'8" x 6'8") | E37: =J37 -> 131.37755 | H37: =H21 -> 51.377551 | I37: 80 | J37: =H37+I37 -> 131.37755
A38: 22" x 80" | C38: (1'10" x 6'8") | E38: =J38 -> 131.37755 | H38: =H22 -> 51.377551 | I38: 80 | J38: =H38+I38 -> 131.37755
A39: 24" x 80" | C39: (2'0" x 6'8") | E39: =J39 -> 131.37755 | H39: =H23 -> 51.377551 | I39: 80 | J39: =H39+I39 -> 131.37755
A40: 26" x 80" | C40: (2'2" x 6'8") | E40: =J40 -> 134.64286 | H40: =H24 -> 54.642857 | I40: 80 | J40: =H40+I40 -> 134.64286
A41: 28" x 80" | C41: (2'4" x 6'8") | E41: =J41 -> 134.64286 | H41: =H25 -> 54.642857 | I41: 80 | J41: =H41+I41 -> 134.64286
A42: 30" x 80" | C42: (2'6" x 6'8") | E42: =J42 -> 134.64286 | H42: =H26 -> 54.642857 | I42: 80 | J42: =H42+I42 -> 134.64286
A43: 32" x 80" | C43: (2'8" x 6'8") | E43: =J43 -> 136.63265 | H43: =H27 -> 56.632653 | I43: 80 | J43: =H43+I43 -> 136.63265
A44: 34" x 80" | C44: (2'10" x 6'8") | E44: =J44 -> 141.32653 | H44: =H28 -> 61.326531 | I44: 80 | J44: =H44+I44 -> 141.32653
A45: 36" x 80" | C45: (3'0" x 6'8") | E45: =J45 -> 141.32653 | H45: =H29 -> 61.326531 | I45: 80 | J45: =H45+I45 -> 141.32653
A46: HEIGHT 84" Add | E46: =J46 -> 35.7 | J46: 35.7
A47: HEIGHT 96" Add | E47: =J47 -> 83.25 | J47: 83.25

Sheet Primed Hardboard (3)
A1: PRICE LIST
A2: ='Colonist-6 Panel'!A2 -> NET PRICE LIST (May 4, 2025)
A3: ='Colonist-6 Panel'!A3 -> HOME HARDWARE - NON COMMITTED WEST
A5: PRIMED HARDBOARD
A12: Slab | B12: 6'8", 7'0", 8'0"
A13: Bifold | B13: 6'8", 7'0", 8'0"
A15: Size | E15: ='Colonist-6 Panel'!E16 -> Net Price
A16: Slab 1 3/4 hollow core
A17: 12" x 80" | C17: (1'0" x 6'8") | E17: 84.795918
A18: 14" x 80" | C18: (1'2" x 6'8") | E18: 84.795918
A19: 16" x 80" | C19: (1'4" x 6'8") | E19: 84.795918
A20: 18" x 80" | C20: (1'6" x 6'8") | E20: 84.795918
A21: 20" x 80" | C21: (1'8" x 6'8") | E21: 85.969388
A22: 22" x 80" | C22: (1'10" x 6'8") | E22: 85.969388
A23: 24" x 80" | C23: (2'0" x 6'8") | E23: 85.969388
A24: 26" x 80" | C24: (2'2" x 6'8") | E24: 89.234694
A25: 28" x 80" | C25: (2'4" x 6'8") | E25: 89.234694
A26: 30" x 80" | C26: (2'6" x 6'8") | E26: 89.234694
A27: 32" x 80" | C27: (2'8" x 6'8") | E27: 91.22449
A28: 34" x 80" | C28: (2'10" x 6'8") | E28: 95.918367
A29: 36" x 80" | C29: (3'0" x 6'8") | E29: 95.918367
A30: HEIGHT 84" Add | E30: 6.5
A31: Slab 1 3/4 solid core
A32: 12" x 80" | C32: (1'0" x 6'8") | E32: 143.21429
A33: 14" x 80" | C33: (1'2" x 6'8") | E33: 143.21429
A34: 16" x 80" | C34: (1'4" x 6'8") | E34: 143.21429
A35: 18" x 80" | C35: (1'6" x 6'8") | E35: 143.21429
A36: 20" x 80" | C36: (1'8" x 6'8") | E36: 144.38776
A37: 22" x 80" | C37: (1'10" x 6'8") | E37: 144.38776
A38: 24" x 80" | C38: (2'0" x 6'8") | E38: 144.38776
A39: 26" x 80" | C39: (2'2" x 6'8") | E39: 147.65306
A40: 28" x 80" | C40: (2'4" x 6'8") | E40: 147.65306
A41: 30" x 80" | C41: (2'6" x 6'8") | E41: 147.65306
A42: 32" x 80" | C42: (2'8" x 6'8") | E42: 149.64286
A43: 34" x 80" | C43: (2'10" x 6'8") | E43: 154.33673
... A45: 38" x 80" | C45: (3'2" x 6'8") | E45: 181.88776
A46: HEIGHT 84" Add | E46: 23.8
A47: HEIGHT 96" Add | E47: 71.4

Sheet Adders
A3: ='Colonist-6 Panel'!A3 -> HOME HARDWARE - NON COMMITTED WEST
A4: Adders | B4: HH Non-Committed West
A5: Additional Options
A6: Machining for 1 3/8": 2, 3 or 4 Hinges and Lock | B6: 12.25
A7: Machining for 1 3/4": 3 or 4 Hinges and Lock | B7: 33.65
A8: 20 Minute Fire Rated Slab Only (machining 3 or 4 hinges & cyl lock) | B8: 43.9
A9: 45 Min Fire Rated Flush (includes prep for 3 hinges & cyl lock) | B9: 346.95
A10: 45 Min Fire Rated Moulded (includes prep for 3 hinges & cyl lock) | B10: 509.2
A11: 60 - 90 Min Fire Rated Flush (includes prep for 3 hinges & cyl lock) | B11: 471.45
A12: Machining - Dead Bolt | B12: 10.2
A13: Machining - Viewer | B13: 10.2
A14: Non-Standard Charge (20 of the same size/style or more=$0.00) | B14: 87.75
A15: Double Door Price = single prehung price x2, Plus Adder price (Includes 2 ball catches or 1 flushbolt) | B15: 18.35
A17: Jamb Add-ons: add to Hollow Core or Solid Core Slabs | E17: Jan 2022 Price | F17: % Increase | G17: May 2025 Price
A18: 4-9/16" MDF jamb for an Easy IN | B18: =G18 -> 66.45 | E18: 62.7 | F18: 0.06 | G18: =MROUND(E18*(1+F18),0.05) -> 66.45
A19: 6-9/16" MDF jamb for an Easy IN | B19: =G19 -> 78.35 | E19: 73.9 | F19: 0.06 | G19: =MROUND(E19*(1+F19),0.05) -> 78.35
A20: 4-9/16" FJP jamb for Easy IN | B20: =G20 -> 79.55 | E20: 75.05 | F20: 0.06 | G20: =MROUND(E20*(1+F20),0.05) -> 79.55
A21: 6-9/16" FJP jamb for Easy IN | B21: =G21 -> 92.6 | E21: 87.35 | F21: 0.06 | G21: =MROUND(E21*(1+F21),0.05) -> 92.6
A22: 4-9/16" FJ Primed for Prehung | B22: =G22 -> 79.55 | E22: 75.05 | F22: 0.06 | G22: =MROUND(E22*(1+F22),0.05) -> 79.55
A23: 4-9/16" FJP jamb Rabbeted Prehung | B23: =G23 -> 79.55 | E23: 75.05 | F23: 0.06 | G23: =MROUND(E23*(1+F23),0.05) -> 79.55
A24: 6-9/16" FJP jamb Rabbeted Prehung | B24: =G24 -> 92.6 | E24: 87.35 | F24: 0.06 | G24: =MROUND(E24*(1+F24),0.05) -> 92.6
A26: Options
A27: Hinge Finish | B27: 66.45 | E27: 8.4 | F27: 0.06 | G27: =MROUND(E27*(1+F27),0.05) -> 8.9
A28: Ball Catch | B28: 66.45 | E28: 16 | F28: 0.06 | G28: =MROUND(E28*(1+F28),0.05) -> 16.95
A29: Flush Bolt | B29: 66.45 | E29: 16 | F29: 0.06 | G29: =MROUND(E29*(1+F29),0.05) -> 16.95
A30: BB Hinges | B30: 66.45 | E30: 20.15 | F30: 0.06 | G30: =MROUND(E30*(1+F30),0.05) -> 21.35

Sheet Doors Availability
D2: Willmar
A3: Doors - sizes available
A4: modèle / model | C4: 12'' | D4: 14'' | E4: 16'' | F4: 18'' | G4: 20'' | H4: 22'' | I4: 24'' | J4: 26'' | K4: 28'' | L4: 30'' | M4: 32'' | N4: 34'' | O4: 36''
A5: BIRKDALE | B5: 80'' | C5: X | D5: X | E5: X | F5: X | G5: X | H5: X | I5: X | J5: X | K5: X | L5: X | M5: X | N5: X | O5: X
B6: 84'' | E6: X | F6: X | G6: X | H6: X | I6: X | J6: X | K6: X | L6: X | M6: X | N6: X | O6: X
B7: 96'' | E7: X | F7: X | G7: X | H7: X | I7: X | J7: X | K7: X | L7: X | M7: X | N7: X | O7: X
A8: CAMDEN | B8: 80'' | C8: X | D8: X | E8: X | F8: X | G8: X | H8: X | I8: X | J8: X | K8: X | L8: X | M8: X | N8: X | O8: X
B9: 84''
B10: 96''
A11: CARRARA | B11: 80'' | C11: X | D11: X | E11: X | F11: X | G11: X | H11: X | I11: X | J11: X | K11: X | L11: X | M11: X | N11: X | O11: X
B12: 84'' | C12: X | D12: X | E12: X | F12: X | G12: X | H12: X | I12: X | J12: X | K12: X | L12: X | M12: X | N12: X | O12: X
B13: 96'' | E13: X | F13: X | G13: X | H13: X | I13: X | J13: X | K13: X | L13: X | M13: X | N13: X | O13: X
A14: COLONIST TEXT | B14: 80'' | C14: X | D14: X | E14: X | F14: X | G14: X | H14: X | I14: X | J14: X | K14: X | L14: X | M14: X | N14: X | O14: X
B15: 84'' | C15: X | D15: X | E15: X | F15: X | G15: X | H15: X | I15: X | J15: X | K15: X | L15: X | M15: X | N15: X | O15: X
B16: 96'' | E16: X | F16: X | G16: X | H16: X | I16: X | J16: X | K16: X | L16: X | M16: X | N16: X | O16: X
A17: CONMORE | B17: 80'' | C17: X | D17: X | E17: X | F17: X | G17: X | H17: X | I17: X | J17: X | K17: X | L17: X | M17: X | N17: X | O17: X
B18: 84'' | C18: X | D18: X | E18: X | F18: X | G18: X | H18: X | I18: X | J18: X | K18: X | L18: X | M18: X | N18: X | O18: X
B19: 96'' | E19: X | F19: X | G19: X | H19: X | I19: X | J19: X | K19: X | L19: X | M19: X | N19: X | O19: X
A20: CRAFTSMAN | B20: 80'' | C20: X | D20: X | E20: X | F20: X | G20: X | H20: X | I20: X | J20: X | K20: X | L20: X | M20: X | N20: X | O20: X
B21: 84'' | C21: X | D21: X | E21: X | F21: X | G21: X | H21: X | I21: X | J21: X | K21: X | L21: X | M21: X | N21: X | O21: X
B22: 96''
A23: MADISON | B23: 80'' | C23: X | D23: X | E23: X | F23: X | G23: X | H23: X | I23: X | J23: X | K23: X | L23: X | M23: X | N23: X | O23: X
B24: 84'' | C24: X | D24: X | E24: X | F24: X | G24: X | H24: X | I24: X | J24: X | K24: X | L24: X | M24: X | N24: X | O24: X
B25: 96'' | E25: X | F25: X | G25: X | H25: X | I25: X | J25: X | K25: X | L25: X | M25: X | N25: X | O25: X
A26: MONROE | B26: 80'' | C26: X | D26: X | E26: X | F26: X | G26: X | H26: X | I26: X | J26: X | K26: X | L26: X | M26: X | N26: X | O26: X
B27: 84'' | C27: X | D27: X | E27: X | F27: X | G27: X | H27: X | I27: X | J27: X | K27: X | L27: X | M27: X | N27: X | O27: X
B28: 96'' | E28: X | F28: X | G28: X | H28: X | I28: X | J28: X | K28: X | L28: X | M28: X | N28: X | O28: X
A29: ROCKPORT | B29: 80'' | C29: X | D29: X | E29: X | F29: X | G29: X | H29: X | I29: X | J29: X | K29: X | L29: X | M29: X | N29: X | O29: X
B30: 84'' | E30: X | F30: X | G30: X | H30: X | I30: X | J30: X | K30: X | L30: X | M30: X | N30: X | O30: X
B31: 96'' | E31: X | F31: X | G31: X | H31: X | I31: X | J31: X | K31: X | L31: X | M31: X | N31: X | O31: X
A32: SANTA FE | B32: 80'' | C32: X | D32: X | E32: X | F32: X | G32: X | H32: X | I32: X | J32: X | K32: X | L32: X | M32: X | N32: X | O32: X
B33: 84'' | F33: X | G33: X | H33: X | I33: X | J33: X | K33: X | L33: X | M33: X | N33: X | O33: X
B34: 96'' | E34: X | F34: X | G34: X | H34: X | I34: X | J34: X | K34: X | L34: X | M34: X | N34: X | O34: X
C35: Non disponible / Not Available size
B36: x | C36: Disponible / Available
C41: notes internes
A43: 43174 | C43: ajot AVA 84'' x 18 à 36 incl, contl 16x84, rock 16x84''
A44: 43047 | C44: ajout carrara 80 84 96'', contl 28 et 32x96 , de 4 a 5, ajout coventry 84 et 96
A45: 42480 | C45: Avalon 26- de cmi à skin JW ( batt de 5,3/16 à 3,3/16)
A46: 42480 | C46: ajout Monroe, enlevé atherton ( Kathya ) , enlevé avalon 84'' ( Kathya )
...

Sheet Bifold Availability
D2: Willmar
A3: Bifolds - sizes available
B4: modèle / model | D4: 18'' | E4: 20'' | F4: 22'' | G4: 24'' | H4: 26'' | I4: 28'' | J4: 30'' | K4: 32'' | L4: 34'' | M4: 36''
B5: BIRKDALE | C5: 79'' | G5: X | H5: X | I5: X | J5: X | K5: X | L5: X | M5: X
C6: 84'' | G6: X | H6: X | I6: X | J6: X | K6: X | L6: X | M6: X
C7: 96''
B8: CAMDEN | C8: 79'' | D8: X | E8: X | F8: X | G8: X | H8: X | I8: X | J8: X | K8: X | L8: X | M8: X
C9: 84''
C10: 96''
B11: CARRARA | C11: 79'' | D11: X | E11: X | F11: X | G11: X | H11: X | I11: X | J11: X | K11: X | L11: X | M11: X
C12: 84'' | D12: X | E12: X | F12: X | G12: X | H12: X | I12: X | J12: X | K12: X | L12: X | M12: X
C13: 96'' | J13: X | K13: X | L13: X | M13: X
B14: COLONIST TEXT | C14: 79'' | D14: X | E14: X | F14: X | G14: X | H14: X | I14: X | J14: X | K14: X | L14: X | M14: X
C15: 84'' | D15: X | E15: X | F15: X | G15: X | H15: X | I15: X | J15: X | K15: X | L15: X | M15: X
C16: 96'' | J16: X | K16: X | L16: X | M16: X
B17: CONMORE | C17: 79'' | D17: X | E17: X | F17: X | G17: X | H17: X | I17: X | J17: X | K17: X | L17: X | M17: X
C18: 84'' | D18: X | E18: X | F18: X | G18: X | H18: X | I18: X | J18: X | K18: X | L18: X | M18: X
C19: 96''
B20: CRAFTSMAN | C20: 79'' | F20: X | G20: X | H20: X | I20: X | J20: X | K20: X | L20: X | M20: X
C21: 84'' | F21: X | G21: X | H21: X | I21: X | J21: X | K21: X | L21: X | M21: X
C22: 96''
B23: MADISON | C23: 79'' | F23: X | G23: X | H23: X | I23: X | J23: X | K23: X | L23: X | M23: X
C24: 84'' | F24: X | G24: X | H24: X | I24: X | J24: X | K24: X | L24: X | M24: X
C25: 96'' | J25: X | K25: X | L25: X | M25: X
B26: MONROE | C26: 79'' | F26: X | G26: X | H26: X | I26: X | J26: X | K26: X | L26: X | M26: X
C27: 84'' | F27: X | G27: X | H27: X | I27: X | J27: X | K27: X | L27: X | M27: X
C28: 96'' | J28: X | K28: X | L28: X | M28: X
B29: ROCKPORT | C29: 79'' | D29: X | E29: X | F29: X | G29: X | H29: X | I29: X | J29: X | K29: X | L29: X | M29: X
C30: 84'' | J30: X | K30: X | L30: X | M30: X
C31: 96'' | J31: X | K31: X | L31: X | M31: X
B32: SANTA FE | C32: 79'' | D32: X | E32: X | F32: X | G32: X | H32: X | I32: X | J32: X | K32: X | L32: X | M32: X
C33: 84'' | J33: X | K33: X | L33: X | M33: X
C34: 96'' | J34: X | K34: X | L34: X | M34: X
D35: Non disponible / Not Available
C36: x | D36: Disponible / Available
B43: 43174
B44: 43047
B45: 42480
B46: 42480
B47: 42376
...
