Workbook
Name Print_Titles_MI: Conmore!$2:$12
Name Print_Titles_MI: 'Conmore (2)'!$2:$12
Name Print_Titles_MI: 'Conmore (3)'!$2:$12
Name Print_Titles_MI: 'Flat Panel'!$2:$12
Name Print_Titles_MI: 'Flat Panel (2)'!$2:$12
Name Print_Titles_MI: 'Flat Panel (3)'!$2:$12
Name Print_Titles_MI: 'Moulded Panel'!$2:$12
Name Print_Titles_MI: 'Moulded Panel (2)'!$2:$12
Name Print_Titles_MI: 'Moulded Panel (3)'!$2:$12
Name Print_Titles_MI: 'Primed Hardboard'!$2:$14
Name Print_Titles_MI: 'Primed Hardboard (2)'!$2:$14
Name Print_Titles_MI: 'Primed Hardboard (3)'!$2:$14

Sheet Cover
A18: Interior Door Price List
A20: NET PRICE LIST (April 4, 2025)
B26: SEXTON WEST

Sheet Moulded Panel
A1: PRICE LIST
A2: NET PRICE LIST (April 4, 2025)
A3: SEXTON WEST
A6: Moulded
C13: CARRARA | D13: EURO Only available in 38" width | E13: SANTA FE | F13: ROCKPORT | G13: CAMDEN | H13: COLONIST TEXTURED
B14: Slab | C14: 6'8", 7'0", 8'0" | D14: 6'8", 7'0" | E14: 6'8", 7'0", 8'0" | F14: 6'8", 7'0", 8'0" | G14: 6'8" | H14: 6'8", 7'0", 8'0"
B15: Bifold | C15: 6'8", 7'0", 8'0" | D15: N/A | E15: 6'8", 7'0", 8'0" | F15: 6'8", 7'0", 8'0" | G15: 6'8" | H15: 6'8", 7'0", 8'0"
C17: Size | G17: List qty (1 to 1099) | H17: List qty (1100)
C18: Slab 1 3/8 hollow core
C19: 12" x 80" | E19: (1'0" x 6'8") | G19: 72.5 | H19: 62.7 | L19: =H19/G19 -> 0.86482759
C20: 14" x 80" | E20: (1'2" x 6'8") | G20: 72.5 | H20: 62.7 | L20: =H20/G20 -> 0.86482759
C21: 16" x 80" | E21: (1'4" x 6'8") | G21: 72.5 | H21: 62.7 | L21: =H21/G21 -> 0.86482759
C22: 18" x 80" | E22: (1'6" x 6'8") | G22: 72.5 | H22: 62.7 | L22: =H22/G22 -> 0.86482759
C23: 20" x 80" | E23: (1'8" x 6'8") | G23: 76.35 | H23: 66.05 | L23: =H23/G23 -> 0.86509496
C24: 22" x 80" | E24: (1'10" x 6'8") | G24: 76.35 | H24: 66.05 | L24: =H24/G24 -> 0.86509496
C25: 24" x 80" | E25: (2'0" x 6'8") | G25: 76.35 | H25: 66.05 | L25: =H25/G25 -> 0.86509496
C26: 26" x 80" | E26: (2'2" x 6'8") | G26: 79.2 | H26: 68.5 | L26: =H26/G26 -> 0.86489899
C27: 28" x 80" | E27: (2'4" x 6'8") | G27: 79.2 | H27: 68.5 | L27: =H27/G27 -> 0.86489899
C28: 30" x 80" | E28: (2'6" x 6'8") | G28: 79.2 | H28: 68.5 | L28: =H28/G28 -> 0.86489899
C29: 32" x 80" | E29: (2'8" x 6'8") | G29: 82 | H29: 70.95 | L29: =H29/G29 -> 0.8652439
C30: 34" x 80" | E30: (2'10" x 6'8") | G30: 86 | H30: 74.4 | L30: =H30/G30 -> 0.86511628
... C32: 38" x 80" | E32: (3'2" x 6'8") EURO | G32: 119.05 | H32: 103 | L32: =H32/G32 -> 0.8651827
C33: HEIGHT 84" Add | G33: 30.75 | H33: 26.6 | L33: =H33/G33 -> 0.86504065 | M33: =G33*0.865 -> 26.59875
C34: HEIGHT 96" Add | G34: 85.35 | H34: 73.85 | L34: =H34/G34 -> 0.86526069 | M34: =G34*0.865 -> 73.82775
C35: Bifold 1 3/8 c/w hardware
C36: 18" x 80" | E36: (1'6" x 6'8") | G36: 92.85 | H36: 80.3 | L36: =H36/G36 -> 0.86483576
C37: 20" x 80" | E37: (1'8" x 6'8") | G37: 92.85 | H37: 80.3 | L37: =H37/G37 -> 0.86483576
C38: 22" x 80" | E38: (1'10" x 6'8") | G38: 92.85 | H38: 80.3 | L38: =H38/G38 -> 0.86483576
C39: 24" x 80" | E39: (2'0" x 6'8") | G39: 92.85 | H39: 80.3 | L39: =H39/G39 -> 0.86483576
C40: 26" x 80" | E40: (2'2" x 6'8") | G40: 102.2 | H40: 88.4 | L40: =H40/G40 -> 0.86497065
C41: 28" x 80" | E41: (2'4" x 6'8") | G41: 102.2 | H41: 88.4 | L41: =H41/G41 -> 0.86497065
C42: 30" x 80" | E42: (2'6" x 6'8") | G42: 102.2 | H42: 88.4 | L42: =H42/G42 -> 0.86497065
C43: 32" x 80" | E43: (2'8" x 6'8") | G43: 108.25 | H43: 93.65 | L43: =H43/G43 -> 0.86512702
C44: 34" x 80" | E44: (2'10" x 6'8") | G44: 108.25 | H44: 93.65 | L44: =H44/G44 -> 0.86512702
C45: 36" x 80" | E45: (3'0" x 6'8") | G45: 108.25 | H45: 93.65 | L45: =H45/G45 -> 0.86512702
C46: HEIGHT 84" Add | G46: 30.75 | H46: 26.6 | L46: =H46/G46 -> 0.86504065 | M46: =G46*0.865 -> 26.59875
C47: HEIGHT 96" Add | G47: 85.35 | H47: 73.85 | L47: =H47/G47 -> 0.86526069 | M47: =G47*0.865 -> 73.82775
C48: Slab 1 3/8 solid core (Procore)
C49: 12" x 80" | E49: (1'0" x 6'8") | G49: 160.5 | H49: 138.85 | L49: =H49/G49 -> 0.86510903
C50: 14" x 80" | E50: (1'2" x 6'8") | G50: 160.5 | H50: 138.85 | L50: =H50/G50 -> 0.86510903
...

Sheet Moulded Panel (2)
A1: PRICE LIST
A2: ='Moulded Panel'!A2 -> NET PRICE LIST (April 4, 2025)
A3: ='Moulded Panel'!A3 -> SEXTON WEST
A6: Moulded
C13: CARRARA | D13: EURO Only available in 38" width | E13: SANTA FE | F13: ROCKPORT | G13: CAMDEN | H13: COLONIST TEXTURED
B14: Slab | C14: 6'8", 7'0", 8'0" | D14: 6'8", 7'0" | E14: 6'8", 7'0", 8'0" | F14: 6'8", 7'0", 8'0" | G14: 6'8" | H14: 6'8", 7'0", 8'0"
B15: Bifold | C15: 6'8", 7'0", 8'0" | D15: N/A | E15: 6'8", 7'0", 8'0" | F15: 6'8", 7'0", 8'0" | G15: 6'8" | H15: 6'8", 7'0", 8'0"
C17: Size | G17: List qty (1 to 1099) | H17: List qty (1100)
C18: Slab 1 3/4 hollow core
C19: 12" x 80" | E19: (1'0" x 6'8") | G19: 104.3 | H19: 90.2 | L19: =H19/G19 -> 0.86481304
C20: 14" x 80" | E20: (1'2" x 6'8") | G20: 104.3 | H20: 90.2 | L20: =H20/G20 -> 0.86481304
C21: 16" x 80" | E21: (1'4" x 6'8") | G21: 104.3 | H21: 90.2 | L21: =H21/G21 -> 0.86481304
C22: 18" x 80" | E22: (1'6" x 6'8") | G22: 104.3 | H22: 90.2 | L22: =H22/G22 -> 0.86481304
C23: 20" x 80" | E23: (1'8" x 6'8") | G23: 108.15 | H23: 93.55 | L23: =H23/G23 -> 0.86500231
C24: 22" x 80" | E24: (1'10" x 6'8") | G24: 108.15 | H24: 93.55 | L24: =H24/G24 -> 0.86500231
C25: 24" x 80" | E25: (2'0" x 6'8") | G25: 108.15 | H25: 93.55 | L25: =H25/G25 -> 0.86500231
C26: 26" x 80" | E26: (2'2" x 6'8") | G26: 111 | H26: 96 | L26: =H26/G26 -> 0.86486486
C27: 28" x 80" | E27: (2'4" x 6'8") | G27: 111 | H27: 96 | L27: =H27/G27 -> 0.86486486
C28: 30" x 80" | E28: (2'6" x 6'8") | G28: 111 | H28: 96 | L28: =H28/G28 -> 0.86486486
C29: 32" x 80" | E29: (2'8" x 6'8") | G29: 113.8 | H29: 98.45 | L29: =H29/G29 -> 0.86511424
C30: 34" x 80" | E30: (2'10" x 6'8") | G30: 117.8 | H30: 101.9 | L30: =H30/G30 -> 0.86502547
C31: 36" x 80" | E31: (3'0" x 6'8") | G31: 117.8 | H31: 101.9 | L31: =H31/G31 -> 0.86502547
C32: HEIGHT 84" Add | G32: 4.75 | H32: 4.1 | L32: =H32/G32 -> 0.86315789 | N32: 4.75 | O32: =N32*0.865 -> 4.10875
C33: Slab 1 3/4 solid core
C34: 12" x 80" | E34: (1'0" x 6'8") | G34: 199.7 | H34: 172.75 | L34: =H34/G34 -> 0.86504757
C35: 14" x 80" | E35: (1'2" x 6'8") | G35: 199.7 | H35: 172.75 | L35: =H35/G35 -> 0.86504757
C36: 16" x 80" | E36: (1'4" x 6'8") | G36: 199.7 | H36: 172.75 | L36: =H36/G36 -> 0.86504757
C37: 18" x 80" | E37: (1'6" x 6'8") | G37: 199.7 | H37: 172.75 | L37: =H37/G37 -> 0.86504757
C38: 20" x 80" | E38: (1'8" x 6'8") | G38: 203.55 | H38: 176.05 | L38: =H38/G38 -> 0.86489806
C39: 22" x 80" | E39: (1'10" x 6'8") | G39: 203.55 | H39: 176.05 | L39: =H39/G39 -> 0.86489806
C40: 24" x 80" | E40: (2'0" x 6'8") | G40: 203.55 | H40: 176.05 | L40: =H40/G40 -> 0.86489806
C41: 26" x 80" | E41: (2'2" x 6'8") | G41: 206.4 | H41: 178.55 | L41: =H41/G41 -> 0.86506783
C42: 28" x 80" | E42: (2'4" x 6'8") | G42: 206.4 | H42: 178.55 | L42: =H42/G42 -> 0.86506783
C43: 30" x 80" | E43: (2'6" x 6'8") | G43: 206.4 | H43: 178.55 | L43: =H43/G43 -> 0.86506783
C44: 32" x 80" | E44: (2'8" x 6'8") | G44: 209.2 | H44: 180.95 | L44: =H44/G44 -> 0.86496176
C45: 34" x 80" | E45: (2'10" x 6'8") | G45: 213.2 | H45: 184.4 | L45: =H45/G45 -> 0.86491557
... C47: 38" x 80" | E47: (3'2" x 6'8") EURO | G47: 246.25 | H47: 213 | L47: =H47/G47 -> 0.86497462
C48: HEIGHT 84" Add | G48: 13.8 | H48: 11.95 | L48: =H48/G48 -> 0.86594203 | M48: 13.8 | N48: =M48*0.865 -> 11.937
C49: HEIGHT 96" Add | G49: 102.8 | H49: 88.9 | L49: =H49/G49 -> 0.86478599 | M49: 102.8 | N49: =M49*0.865 -> 88.922

Sheet Moulded Panel (3)
A1: PRICE LIST
A2: ='Moulded Panel'!A2 -> NET PRICE LIST (April 4, 2025)
A3: ='Moulded Panel'!A3 -> SEXTON WEST
A6: Moulded
C13: CARRARA | D13: SANTA FE | E13: ROCKPORT | F13: CAMDEN | G13: COLONIST TEXTURED
B14: Slab | C14: 6'8", 7'0", 8'0" | D14: 6'8", 7'0", 8'0" | E14: 6'8", 7'0", 8'0" | F14: 6'8" | G14: 6'8", 7'0", 8'0"
B15: Bifold | C15: 6'8", 7'0", 8'0" | D15: 6'8", 7'0", 8'0" | E15: 6'8", 7'0", 8'0" | F15: 6'8" | G15: 6'8", 7'0", 8'0"
C17: Size | G17: List qty (1 to 1099) | H17: List qty (1100)
C18: 1 3/8" HC Easy-Install FJ Pine 4 9/16 x 9/16 (KD Unit)
C19: 12" x 80" | E19: (1'0" x 6'8") | G19: 138.2 | H19: 119.55 | K19: =H19/G19 -> 0.86505065
C20: 14" x 80" | E20: (1'2" x 6'8") | G20: 138.2 | H20: 119.55 | K20: =H20/G20 -> 0.86505065
C21: 16" x 80" | E21: (1'4" x 6'8") | G21: 138.2 | H21: 119.55 | K21: =H21/G21 -> 0.86505065
C22: 18" x 80" | E22: (1'6" x 6'8") | G22: 138.2 | H22: 119.55 | K22: =H22/G22 -> 0.86505065
C23: 20" x 80" | E23: (1'8" x 6'8") | G23: 142.05 | H23: 122.85 | K23: =H23/G23 -> 0.86483633
C24: 22" x 80" | E24: (1'10" x 6'8") | G24: 142.05 | H24: 122.85 | K24: =H24/G24 -> 0.86483633
C25: 24" x 80" | E25: (2'0" x 6'8") | G25: 142.05 | H25: 122.85 | K25: =H25/G25 -> 0.86483633
C26: 26" x 80" | E26: (2'2" x 6'8") | G26: 144.9 | H26: 125.35 | K26: =H26/G26 -> 0.86507937
C27: 28" x 80" | E27: (2'4" x 6'8") | G27: 144.9 | H27: 125.35 | K27: =H27/G27 -> 0.86507937
C28: 30" x 80" | E28: (2'6" x 6'8") | G28: 144.9 | H28: 125.35 | K28: =H28/G28 -> 0.86507937
C29: 32" x 80" | E29: (2'8" x 6'8") | G29: 147.7 | H29: 127.75 | K29: =H29/G29 -> 0.86492891
C30: 34" x 80" | E30: (2'10" x 6'8") | G30: 151.7 | H30: 131.2 | K30: =H30/G30 -> 0.86486486
C31: 36" x 80" | E31: (3'0" x 6'8") | G31: 151.7 | H31: 131.2 | K31: =H31/G31 -> 0.86486486
C32: HEIGHT 84" Add | G32: 30.75 | H32: 26.6 | K32: =H32/G32 -> 0.86504065
C33: HEIGHT 96" Add | G33: 85.35 | H33: 73.85 | K33: =H33/G33 -> 0.86526069
C34: 1 3/8" HC Prehung FJ Primed 4 5/8 x 11/16 (assembled unit)
C35: 12" x 80" | E35: (1'0" x 6'8") | G35: 152 | H35: 131.5 | K35: =H35/G35 -> 0.86513158
C36: 14" x 80" | E36: (1'2" x 6'8") | G36: 152 | H36: 131.5 | K36: =H36/G36 -> 0.86513158
C37: 16" x 80" | E37: (1'4" x 6'8") | G37: 152 | H37: 131.5 | K37: =H37/G37 -> 0.86513158
C38: 18" x 80" | E38: (1'6" x 6'8") | G38: 152 | H38: 131.5 | K38: =H38/G38 -> 0.86513158
C39: 20" x 80" | E39: (1'8" x 6'8") | G39: 155.85 | H39: 134.8 | K39: =H39/G39 -> 0.86493423
C40: 22" x 80" | E40: (1'10" x 6'8") | G40: 155.85 | H40: 134.8 | K40: =H40/G40 -> 0.86493423
C41: 24" x 80" | E41: (2'0" x 6'8") | G41: 155.85 | H41: 134.8 | K41: =H41/G41 -> 0.86493423
C42: 26" x 80" | E42: (2'2" x 6'8") | G42: 158.7 | H42: 137.3 | K42: =H42/G42 -> 0.86515438
C43: 28" x 80" | E43: (2'4" x 6'8") | G43: 158.7 | H43: 137.3 | K43: =H43/G43 -> 0.86515438
C44: 30" x 80" | E44: (2'6" x 6'8") | G44: 158.7 | H44: 137.3 | K44: =H44/G44 -> 0.86515438
C45: 32" x 80" | E45: (2'8" x 6'8") | G45: 161.5 | H45: 139.7 | K45: =H45/G45 -> 0.86501548
C46: 34" x 80" | E46: (2'10" x 6'8") | G46: 165.5 | H46: 143.15 | K46: =H46/G46 -> 0.86495468
C47: 36" x 80" | E47: (3'0" x 6'8") | G47: 165.5 | H47: 143.15 | K47: =H47/G47 -> 0.86495468
C48: HEIGHT 84" Add | G48: 30.75 | H48: 26.6 | K48: =H48/G48 -> 0.86504065
C49: HEIGHT 96" Add | G49: 85.35 | H49: 73.85 | K49: =H49/G49 -> 0.86526069

Sheet Conmore
A1: PRICE LIST
A2: ='Moulded Panel'!A2 -> NET PRICE LIST (April 4, 2025)
A3: ='Moulded Panel'!A3 -> SEXTON WEST
A6: Flat Panel
B13: CONMORE
A14: Slab | B14: 6'8", 7'0", 8'0"
A15: Bifold | B15: 6'8", 7'0"
A17: Size | E17: List qty (1 to 1099) | F17: List qty (1100)
A18: Slab 1 3/8 hollow core
A19: 12" x 80" | C19: (1'0" x 6'8") | E19: 77.25 | F19: 66.8 | I19: =F19/E19 -> 0.86472492
A20: 14" x 80" | C20: (1'2" x 6'8") | E20: 77.25 | F20: 66.8 | I20: =F20/E20 -> 0.86472492
A21: 16" x 80" | C21: (1'4" x 6'8") | E21: 77.25 | F21: 66.8 | I21: =F21/E21 -> 0.86472492
A22: 18" x 80" | C22: (1'6" x 6'8") | E22: 77.25 | F22: 66.8 | I22: =F22/E22 -> 0.86472492
A23: 20" x 80" | C23: (1'8" x 6'8") | E23: 81.1 | F23: 70.15 | I23: =F23/E23 -> 0.8649815
A24: 22" x 80" | C24: (1'10" x 6'8") | E24: 81.1 | F24: 70.15 | I24: =F24/E24 -> 0.8649815
A25: 24" x 80" | C25: (2'0" x 6'8") | E25: 81.1 | F25: 70.15 | I25: =F25/E25 -> 0.8649815
A26: 26" x 80" | C26: (2'2" x 6'8") | E26: 83.95 | F26: 72.6 | I26: =F26/E26 -> 0.86480048
A27: 28" x 80" | C27: (2'4" x 6'8") | E27: 83.95 | F27: 72.6 | I27: =F27/E27 -> 0.86480048
A28: 30" x 80" | C28: (2'6" x 6'8") | E28: 83.95 | F28: 72.6 | I28: =F28/E28 -> 0.86480048
A29: 32" x 80" | C29: (2'8" x 6'8") | E29: 86.75 | F29: 75.05 | I29: =F29/E29 -> 0.86512968
A30: 34" x 80" | C30: (2'10" x 6'8") | E30: 90.75 | F30: 78.5 | I30: =F30/E30 -> 0.86501377
A31: 36" x 80" | C31: (3'0" x 6'8") | E31: 90.75 | F31: 78.5 | I31: =F31/E31 -> 0.86501377
A32: HEIGHT 84" Add | E32: 30.75 | F32: 26.6 | I32: =F32/E32 -> 0.86504065
A33: HEIGHT 96" Add | E33: 85.35 | F33: 73.85 | I33: =F33/E33 -> 0.86526069
A34: Bifold 1 3/8 c/w hardware
A35: 18" x 80" | C35: (1'6" x 6'8") | E35: 97.6 | F35: 84.4 | I35: =F35/E35 -> 0.8647541
A36: 20" x 80" | C36: (1'8" x 6'8") | E36: 97.6 | F36: 84.4 | I36: =F36/E36 -> 0.8647541
A37: 22" x 80" | C37: (1'10" x 6'8") | E37: 97.6 | F37: 84.4 | I37: =F37/E37 -> 0.8647541
A38: 24" x 80" | C38: (2'0" x 6'8") | E38: 97.6 | F38: 84.4 | I38: =F38/E38 -> 0.8647541
A39: 26" x 80" | C39: (2'2" x 6'8") | E39: 106.95 | F39: 92.5 | I39: =F39/E39 -> 0.86489014
A40: 28" x 80" | C40: (2'4" x 6'8") | E40: 106.95 | F40: 92.5 | I40: =F40/E40 -> 0.86489014
A41: 30" x 80" | C41: (2'6" x 6'8") | E41: 106.95 | F41: 92.5 | I41: =F41/E41 -> 0.86489014
A42: 32" x 80" | C42: (2'8" x 6'8") | E42: 113 | F42: 97.75 | I42: =F42/E42 -> 0.86504425
A43: 34" x 80" | C43: (2'10" x 6'8") | E43: 113 | F43: 97.75 | I43: =F43/E43 -> 0.86504425
A44: 36" x 80" | C44: (3'0" x 6'8") | E44: 113 | F44: 97.75 | I44: =F44/E44 -> 0.86504425
A45: HEIGHT 84" Add | E45: 30.75 | F45: 26.6
A46: Slab 1 3/8 solid core (Procore)
A47: 12" x 80" | C47: (1'0" x 6'8") | E47: 165.25 | F47: 142.95 | I47: =F47/E47 -> 0.86505295
A48: 14" x 80" | C48: (1'2" x 6'8") | E48: 165.25 | F48: 142.95 | I48: =F48/E48 -> 0.86505295
A49: 16" x 80" | C49: (1'4" x 6'8") | E49: 165.25 | F49: 142.95 | I49: =F49/E49 -> 0.86505295
...

Sheet Conmore (2)
A1: PRICE LIST
A2: ='Moulded Panel'!A2 -> NET PRICE LIST (April 4, 2025)
A3: ='Moulded Panel'!A3 -> SEXTON WEST
A6: Flat Panel
B13: CONMORE
A14: Slab | B14: 6'8", 7'0", 8'0"
A15: Bifold | B15: 6'8", 7'0"
A17: Size | E17: List qty (1 to 1099) | F17: List qty (1100)
A18: Slab 1 3/4 hollow core
A19: 12" x 80" | C19: (1'0" x 6'8") | E19: N/A | F19: N/A
A20: 14" x 80" | C20: (1'2" x 6'8") | E20: N/A | F20: N/A
A21: 16" x 80" | C21: (1'4" x 6'8") | E21: N/A | F21: N/A
A22: 18" x 80" | C22: (1'6" x 6'8") | E22: N/A | F22: N/A
A23: 20" x 80" | C23: (1'8" x 6'8") | E23: N/A | F23: N/A
A24: 22" x 80" | C24: (1'10" x 6'8") | E24: N/A | F24: N/A
A25: 24" x 80" | C25: (2'0" x 6'8") | E25: N/A | F25: N/A
A26: 26" x 80" | C26: (2'2" x 6'8") | E26: N/A | F26: N/A
A27: 28" x 80" | C27: (2'4" x 6'8") | E27: N/A | F27: N/A
A28: 30" x 80" | C28: (2'6" x 6'8") | E28: N/A | F28: N/A
A29: 32" x 80" | C29: (2'8" x 6'8") | E29: N/A | F29: N/A
A30: 34" x 80" | C30: (2'10" x 6'8") | E30: N/A | F30: N/A
A31: 36" x 80" | C31: (3'0" x 6'8") | E31: N/A | F31: N/A
A32: Slab 1 3/4 solid core
A33: 12" x 80" | C33: (1'0" x 6'8") | E33: 204.45 | F33: 176.85 | I33: =F33/E33 -> 0.86500367
A34: 14" x 80" | C34: (1'2" x 6'8") | E34: 204.45 | F34: 176.85 | I34: =F34/E34 -> 0.86500367
A35: 16" x 80" | C35: (1'4" x 6'8") | E35: 204.45 | F35: 176.85 | I35: =F35/E35 -> 0.86500367
A36: 18" x 80" | C36: (1'6" x 6'8") | E36: 204.45 | F36: 176.85 | I36: =F36/E36 -> 0.86500367
A37: 20" x 80" | C37: (1'8" x 6'8") | E37: 208.3 | F37: 180.2 | I37: =F37/E37 -> 0.86509842
A38: 22" x 80" | C38: (1'10" x 6'8") | E38: 208.3 | F38: 180.2 | I38: =F38/E38 -> 0.86509842
A39: 24" x 80" | C39: (2'0" x 6'8") | E39: 208.3 | F39: 180.2 | I39: =F39/E39 -> 0.86509842
A40: 26" x 80" | C40: (2'2" x 6'8") | E40: 211.15 | F40: 182.65 | I40: =F40/E40 -> 0.86502486
A41: 28" x 80" | C41: (2'4" x 6'8") | E41: 211.15 | F41: 182.65 | I41: =F41/E41 -> 0.86502486
A42: 30" x 80" | C42: (2'6" x 6'8") | E42: 211.15 | F42: 182.65 | I42: =F42/E42 -> 0.86502486
A43: 32" x 80" | C43: (2'8" x 6'8") | E43: 213.95 | F43: 185.05 | I43: =F43/E43 -> 0.86492171
A44: 34" x 80" | C44: (2'10" x 6'8") | E44: 217.95 | F44: 188.55 | I44: =F44/E44 -> 0.86510668
A45: 36" x 80" | C45: (3'0" x 6'8") | E45: 217.95 | F45: 188.55 | I45: =F45/E45 -> 0.86510668
A46: HEIGHT 84" Add | E46: 13.8 | F46: 11.95 | I46: =F46/E46 -> 0.86594203
A47: HEIGHT 96" Add | E47: 102.8 | F47: 88.9 | I47: =F47/E47 -> 0.86478599

Sheet Conmore (3)
A1: PRICE LIST
A2: ='Moulded Panel'!A2 -> NET PRICE LIST (April 4, 2025)
A3: ='Moulded Panel'!A3 -> SEXTON WEST
A6: Flat Panel
B13: CONMORE
A14: Slab | B14: 6'8", 7'0", 8'0"
A15: Bifold | B15: 6'8", 7'0"
A17: Size | E17: List qty (1 to 1099) | F17: List qty (1100)
A18: 1 3/8" HC Easy-Install FJ Pine 4 9/16 x 9/16 (KD Unit)
A19: 12" x 80" | C19: (1'0" x 6'8") | E19: 142.95 | F19: 123.65 | I19: =F19/E19 -> 0.86498776
A20: 14" x 80" | C20: (1'2" x 6'8") | E20: 142.95 | F20: 123.65 | I20: =F20/E20 -> 0.86498776
A21: 16" x 80" | C21: (1'4" x 6'8") | E21: 142.95 | F21: 123.65 | I21: =F21/E21 -> 0.86498776
A22: 18" x 80" | C22: (1'6" x 6'8") | E22: 142.95 | F22: 123.65 | I22: =F22/E22 -> 0.86498776
A23: 20" x 80" | C23: (1'8" x 6'8") | E23: 146.8 | F23: 127 | I23: =F23/E23 -> 0.86512262
A24: 22" x 80" | C24: (1'10" x 6'8") | E24: 146.8 | F24: 127 | I24: =F24/E24 -> 0.86512262
A25: 24" x 80" | C25: (2'0" x 6'8") | E25: 146.8 | F25: 127 | I25: =F25/E25 -> 0.86512262
A26: 26" x 80" | C26: (2'2" x 6'8") | E26: 149.65 | F26: 129.45 | I26: =F26/E26 -> 0.86501838
A27: 28" x 80" | C27: (2'4" x 6'8") | E27: 149.65 | F27: 129.45 | I27: =F27/E27 -> 0.86501838
A28: 30" x 80" | C28: (2'6" x 6'8") | E28: 149.65 | F28: 129.45 | I28: =F28/E28 -> 0.86501838
A29: 32" x 80" | C29: (2'8" x 6'8") | E29: 152.45 | F29: 131.85 | I29: =F29/E29 -> 0.86487373
A30: 34" x 80" | C30: (2'10" x 6'8") | E30: 156.45 | F30: 135.35 | I30: =F30/E30 -> 0.86513263
A31: 36" x 80" | C31: (3'0" x 6'8") | E31: 156.45 | F31: 135.35 | I31: =F31/E31 -> 0.86513263
A32: HEIGHT 84" Add | E32: 30.75 | F32: 26.6 | I32: =F32/E32 -> 0.86504065
A33: HEIGHT 96" Add | E33: 85.35 | F33: 73.85 | I33: =F33/E33 -> 0.86526069
A34: 1 3/8" HC Prehung FJ Primed 4 5/8 x 11/16 (assembled unit)
A35: 12" x 80" | C35: (1'0" x 6'8") | E35: 156.75 | F35: 135.6 | I35: =F35/E35 -> 0.86507177
A36: 14" x 80" | C36: (1'2" x 6'8") | E36: 156.75 | F36: 135.6 | I36: =F36/E36 -> 0.86507177
A37: 16" x 80" | C37: (1'4" x 6'8") | E37: 156.75 | F37: 135.6 | I37: =F37/E37 -> 0.86507177
A38: 18" x 80" | C38: (1'6" x 6'8") | E38: 156.75 | F38: 135.6 | I38: =F38/E38 -> 0.86507177
A39: 20" x 80" | C39: (1'8" x 6'8") | E39: 160.6 | F39: 138.9 | I39: =F39/E39 -> 0.86488169
A40: 22" x 80" | C40: (1'10" x 6'8") | E40: 160.6 | F40: 138.9 | I40: =F40/E40 -> 0.86488169
A41: 24" x 80" | C41: (2'0" x 6'8") | E41: 160.6 | F41: 138.9 | I41: =F41/E41 -> 0.86488169
A42: 26" x 80" | C42: (2'2" x 6'8") | E42: 163.45 | F42: 141.4 | I42: =F42/E42 -> 0.86509636
A43: 28" x 80" | C43: (2'4" x 6'8") | E43: 163.45 | F43: 141.4 | I43: =F43/E43 -> 0.86509636
A44: 30" x 80" | C44: (2'6" x 6'8") | E44: 163.45 | F44: 141.4 | I44: =F44/E44 -> 0.86509636
A45: 32" x 80" | C45: (2'8" x 6'8") | E45: 166.25 | F45: 143.8 | I45: =F45/E45 -> 0.86496241
A46: 34" x 80" | C46: (2'10" x 6'8") | E46: 170.25 | F46: 147.25 | I46: =F46/E46 -> 0.86490455
A47: 36" x 80" | C47: (3'0" x 6'8") | E47: 170.25 | F47: 147.25 | I47: =F47/E47 -> 0.86490455
A48: HEIGHT 84" Add | E48: 30.75 | F48: 26.6 | I48: =F48/E48 -> 0.86504065
A49: HEIGHT 96" Add | E49: 85.35 | F49: 73.85 | I49: =F49/E49 -> 0.86526069

Sheet Flat Panel
A1: PRICE LIST
A2: ='Moulded Panel'!A2 -> NET PRICE LIST (April 4, 2025)
A3: ='Moulded Panel'!A3 -> SEXTON WEST
A6: Flat Panel
B13: CRAFTSMAN | C13: MADISON | D13: MONROE | E13: BIRKDALE
A14: Slab | B14: 6'8", 7'0" | C14: 6'8", 7'0", 8'0" | D14: 6'8", 7'0", 8'0" | E14: 6'8", 7'0", 8'0"
A15: Bifold | B15: 6'8", 7'0" | C15: 6'8", 7'0", 8'0" | D15: 6'8", 7'0", 8'0" | E15: 6'8", 7'0"
A17: Size | E17: List qty (1 to 1099) | F17: List qty (1100)
A18: Slab 1 3/8 hollow core
A19: 12" x 80" | C19: (1'0" x 6'8") | E19: 84.15 | F19: 72.8 | H19: =F19/E19 -> 0.86512181
A20: 14" x 80" | C20: (1'2" x 6'8") | E20: 84.15 | F20: 72.8 | H20: =F20/E20 -> 0.86512181
A21: 16" x 80" | C21: (1'4" x 6'8") | E21: 84.15 | F21: 72.8 | H21: =F21/E21 -> 0.86512181
A22: 18" x 80" | C22: (1'6" x 6'8") | E22: 84.15 | F22: 72.8 | H22: =F22/E22 -> 0.86512181
A23: 20" x 80" | C23: (1'8" x 6'8") | E23: 88 | F23: 76.1 | H23: =F23/E23 -> 0.86477273
A24: 22" x 80" | C24: (1'10" x 6'8") | E24: 88 | F24: 76.1 | H24: =F24/E24 -> 0.86477273
A25: 24" x 80" | C25: (2'0" x 6'8") | E25: 88 | F25: 76.1 | H25: =F25/E25 -> 0.86477273
A26: 26" x 80" | C26: (2'2" x 6'8") | E26: 90.85 | F26: 78.6 | H26: =F26/E26 -> 0.86516236
A27: 28" x 80" | C27: (2'4" x 6'8") | E27: 90.85 | F27: 78.6 | H27: =F27/E27 -> 0.86516236
A28: 30" x 80" | C28: (2'6" x 6'8") | E28: 90.85 | F28: 78.6 | H28: =F28/E28 -> 0.86516236
A29: 32" x 80" | C29: (2'8" x 6'8") | E29: 93.65 | F29: 81 | H29: =F29/E29 -> 0.86492258
A30: 34" x 80" | C30: (2'10" x 6'8") | E30: 97.65 | F30: 84.45 | H30: =F30/E30 -> 0.86482335
A31: 36" x 80" | C31: (3'0" x 6'8") | E31: 97.65 | F31: 84.45 | H31: =F31/E31 -> 0.86482335
A32: HEIGHT 84" Add | E32: 30.75 | F32: 26.6 | H32: =F32/E32 -> 0.86504065
A33: HEIGHT 96" Add | E33: 85.35 | F33: 73.85 | H33: =F33/E33 -> 0.86526069
A34: Bifold 1 3/8 c/w hardware
A35: 18" x 80" | C35: (1'6" x 6'8") | E35: 104.5 | F35: 90.4 | H35: =F35/E35 -> 0.86507177
A36: 20" x 80" | C36: (1'8" x 6'8") | E36: 104.5 | F36: 90.4 | H36: =F36/E36 -> 0.86507177
A37: 22" x 80" | C37: (1'10" x 6'8") | E37: 104.5 | F37: 90.4 | H37: =F37/E37 -> 0.86507177
A38: 24" x 80" | C38: (2'0" x 6'8") | E38: 104.5 | F38: 90.4 | H38: =F38/E38 -> 0.86507177
A39: 26" x 80" | C39: (2'2" x 6'8") | E39: 113.85 | F39: 98.5 | H39: =F39/E39 -> 0.86517347
A40: 28" x 80" | C40: (2'4" x 6'8") | E40: 113.85 | F40: 98.5 | H40: =F40/E40 -> 0.86517347
A41: 30" x 80" | C41: (2'6" x 6'8") | E41: 113.85 | F41: 98.5 | H41: =F41/E41 -> 0.86517347
A42: 32" x 80" | C42: (2'8" x 6'8") | E42: 119.9 | F42: 103.7 | H42: =F42/E42 -> 0.86488741
A43: 34" x 80" | C43: (2'10" x 6'8") | E43: 119.9 | F43: 103.7 | H43: =F43/E43 -> 0.86488741
A44: 36" x 80" | C44: (3'0" x 6'8") | E44: 119.9 | F44: 103.7 | H44: =F44/E44 -> 0.86488741
A45: HEIGHT 84" Add | E45: 30.75 | F45: 26.6 | H45: =F45/E45 -> 0.86504065
A46: HEIGHT 96" Add | E46: 85.35 | F46: 73.85 | H46: =F46/E46 -> 0.86526069
A47: Slab 1 3/8 solid core (Procore)
A48: 12" x 80" | C48: (1'0" x 6'8") | E48: 172.15 | F48: 148.9 | H48: =F48/E48 -> 0.86494336
A49: 14" x 80" | C49: (1'2" x 6'8") | E49: 172.15 | F49: 148.9 | H49: =F49/E49 -> 0.86494336
...

Sheet Flat Panel (2)
A1: PRICE LIST
A2: ='Moulded Panel'!A2 -> NET PRICE LIST (April 4, 2025)
A3: ='Moulded Panel'!A3 -> SEXTON WEST
A6: Flat Panel
B13: CRAFTSMAN | C13: MADISON | D13: MONROE | E13: BIRKDALE
A14: Slab | B14: 6'8", 7'0" | C14: 6'8", 7'0", 8'0" | D14: 6'8", 7'0", 8'0" | E14: 6'8", 7'0", 8'0"
A15: Bifold | B15: 6'8", 7'0" | C15: 6'8", 7'0", 8'0" | D15: 6'8", 7'0", 8'0" | E15: 6'8", 7'0"
A17: Size | E17: List qty (1 to 1099) | F17: List qty (1100)
A18: Slab 1 3/4 hollow core
A19: 12" x 80" | C19: (1'0" x 6'8") | E19: N/A | F19: N/A
A20: 14" x 80" | C20: (1'2" x 6'8") | E20: N/A | F20: N/A
A21: 16" x 80" | C21: (1'4" x 6'8") | E21: N/A | F21: N/A
A22: 18" x 80" | C22: (1'6" x 6'8") | E22: N/A | F22: N/A
A23: 20" x 80" | C23: (1'8" x 6'8") | E23: N/A | F23: N/A
A24: 22" x 80" | C24: (1'10" x 6'8") | E24: N/A | F24: N/A
A25: 24" x 80" | C25: (2'0" x 6'8") | E25: N/A | F25: N/A
A26: 26" x 80" | C26: (2'2" x 6'8") | E26: N/A | F26: N/A
A27: 28" x 80" | C27: (2'4" x 6'8") | E27: N/A | F27: N/A
A28: 30" x 80" | C28: (2'6" x 6'8") | E28: N/A | F28: N/A
A29: 32" x 80" | C29: (2'8" x 6'8") | E29: N/A | F29: N/A
A30: 34" x 80" | C30: (2'10" x 6'8") | E30: N/A | F30: N/A
A31: 36" x 80" | C31: (3'0" x 6'8") | E31: N/A | F31: N/A
A32: Slab 1 3/4 solid core
A33: 12" x 80" | C33: (1'0" x 6'8") | E33: 211.35 | F33: 182.8 | H33: =F33/E33 -> 0.86491602
A34: 14" x 80" | C34: (1'2" x 6'8") | E34: 211.35 | F34: 182.8 | H34: =F34/E34 -> 0.86491602
A35: 16" x 80" | C35: (1'4" x 6'8") | E35: 211.35 | F35: 182.8 | H35: =F35/E35 -> 0.86491602
A36: 18" x 80" | C36: (1'6" x 6'8") | E36: 211.35 | F36: 182.8 | H36: =F36/E36 -> 0.86491602
A37: 20" x 80" | C37: (1'8" x 6'8") | E37: 215.2 | F37: 186.15 | H37: =F37/E37 -> 0.86500929
A38: 22" x 80" | C38: (1'10" x 6'8") | E38: 215.2 | F38: 186.15 | H38: =F38/E38 -> 0.86500929
A39: 24" x 80" | C39: (2'0" x 6'8") | E39: 215.2 | F39: 186.15 | H39: =F39/E39 -> 0.86500929
A40: 26" x 80" | C40: (2'2" x 6'8") | E40: 218.05 | F40: 188.6 | H40: =F40/E40 -> 0.86493923
A41: 28" x 80" | C41: (2'4" x 6'8") | E41: 218.05 | F41: 188.6 | H41: =F41/E41 -> 0.86493923
A42: 30" x 80" | C42: (2'6" x 6'8") | E42: 218.05 | F42: 188.6 | H42: =F42/E42 -> 0.86493923
A43: 32" x 80" | C43: (2'8" x 6'8") | E43: 220.85 | F43: 191.05 | H43: =F43/E43 -> 0.86506679
A44: 34" x 80" | C44: (2'10" x 6'8") | E44: 224.85 | F44: 194.5 | H44: =F44/E44 -> 0.86502113
A45: 36" x 80" | C45: (3'0" x 6'8") | E45: 224.85 | F45: 194.5 | H45: =F45/E45 -> 0.86502113
A46: HEIGHT 84" Add | E46: 13.8 | F46: 11.95 | H46: =F46/E46 -> 0.86594203
A47: HEIGHT 96" Add | E47: 102.8 | F47: 88.9 | H47: =F47/E47 -> 0.86478599

Sheet Flat Panel (3)
A1: PRICE LIST
A2: ='Moulded Panel'!A2 -> NET PRICE LIST (April 4, 2025)
A3: ='Moulded Panel'!A3 -> SEXTON WEST
A6: Flat Panel
B13: CRAFTSMAN | C13: MADISON | D13: MONROE | E13: BIRKDALE
A14: Slab | B14: 6'8", 7'0" | C14: 6'8", 7'0", 8'0" | D14: 6'8", 7'0", 8'0" | E14: 6'8", 7'0", 8'0"
A15: Bifold | B15: 6'8", 7'0" | C15: 6'8", 7'0", 8'0" | D15: 6'8", 7'0", 8'0" | E15: 6'8", 7'0"
A17: Size | E17: List qty (1 to 1099) | F17: List qty (1100)
A18: 1 3/8" HC Easy-Install FJ Pine 4 9/16 x 9/16 (KD Unit)
A19: 12" x 80" | C19: (1'0" x 6'8") | E19: 149.85 | F19: 129.6 | H19: =F19/E19 -> 0.86486486 | I19: =E19-'Flat Panel'!E19 -> 65.7
A20: 14" x 80" | C20: (1'2" x 6'8") | E20: 149.85 | F20: 129.6 | H20: =F20/E20 -> 0.86486486 | I20: =E20-'Flat Panel'!E20 -> 65.7
A21: 16" x 80" | C21: (1'4" x 6'8") | E21: 149.85 | F21: 129.6 | H21: =F21/E21 -> 0.86486486 | I21: =E21-'Flat Panel'!E21 -> 65.7
A22: 18" x 80" | C22: (1'6" x 6'8") | E22: 149.85 | F22: 129.6 | H22: =F22/E22 -> 0.86486486 | I22: =E22-'Flat Panel'!E22 -> 65.7
A23: 20" x 80" | C23: (1'8" x 6'8") | E23: 153.7 | F23: 132.95 | H23: =F23/E23 -> 0.86499675 | I23: =E23-'Flat Panel'!E23 -> 65.7
A24: 22" x 80" | C24: (1'10" x 6'8") | E24: 153.7 | F24: 132.95 | H24: =F24/E24 -> 0.86499675 | I24: =E24-'Flat Panel'!E24 -> 65.7
A25: 24" x 80" | C25: (2'0" x 6'8") | E25: 153.7 | F25: 132.95 | H25: =F25/E25 -> 0.86499675 | I25: =E25-'Flat Panel'!E25 -> 65.7
A26: 26" x 80" | C26: (2'2" x 6'8") | E26: 156.55 | F26: 135.4 | H26: =F26/E26 -> 0.86489939 | I26: =E26-'Flat Panel'!E26 -> 65.7
A27: 28" x 80" | C27: (2'4" x 6'8") | E27: 156.55 | F27: 135.4 | H27: =F27/E27 -> 0.86489939 | I27: =E27-'Flat Panel'!E27 -> 65.7
A28: 30" x 80" | C28: (2'6" x 6'8") | E28: 156.55 | F28: 135.4 | H28: =F28/E28 -> 0.86489939 | I28: =E28-'Flat Panel'!E28 -> 65.7
A29: 32" x 80" | C29: (2'8" x 6'8") | E29: 159.35 | F29: 137.85 | H29: =F29/E29 -> 0.86507687 | I29: =E29-'Flat Panel'!E29 -> 65.7
A30: 34" x 80" | C30: (2'10" x 6'8") | E30: 163.35 | F30: 141.3 | H30: =F30/E30 -> 0.86501377 | I30: =E30-'Flat Panel'!E30 -> 65.7
A31: 36" x 80" | C31: (3'0" x 6'8") | E31: 163.35 | F31: 141.3 | H31: =F31/E31 -> 0.86501377 | I31: =E31-'Flat Panel'!E31 -> 65.7
A32: HEIGHT 84" Add | E32: 30.75 | F32: 26.6 | H32: =F32/E32 -> 0.86504065
A33: HEIGHT 96" Add | E33: 85.35 | F33: 73.85 | H33: =F33/E33 -> 0.86526069
A34: 1 3/8" HC Prehung FJ Primed 4 5/8 x 11/16 (assembled unit)
A35: 12" x 80" | C35: (1'0" x 6'8") | E35: 163.65 | F35: 141.55 | H35: =F35/E35 -> 0.8649557
A36: 14" x 80" | C36: (1'2" x 6'8") | E36: 163.65 | F36: 141.55 | H36: =F36/E36 -> 0.8649557
A37: 16" x 80" | C37: (1'4" x 6'8") | E37: 163.65 | F37: 141.55 | H37: =F37/E37 -> 0.8649557
A38: 18" x 80" | C38: (1'6" x 6'8") | E38: 163.65 | F38: 141.55 | H38: =F38/E38 -> 0.8649557
A39: 20" x 80" | C39: (1'8" x 6'8") | E39: 167.5 | F39: 144.9 | H39: =F39/E39 -> 0.86507463
A40: 22" x 80" | C40: (1'10" x 6'8") | E40: 167.5 | F40: 144.9 | H40: =F40/E40 -> 0.86507463
A41: 24" x 80" | C41: (2'0" x 6'8") | E41: 167.5 | F41: 144.9 | H41: =F41/E41 -> 0.86507463
A42: 26" x 80" | C42: (2'2" x 6'8") | E42: 170.35 | F42: 147.35 | H42: =F42/E42 -> 0.86498386
A43: 28" x 80" | C43: (2'4" x 6'8") | E43: 170.35 | F43: 147.35 | H43: =F43/E43 -> 0.86498386
A44: 30" x 80" | C44: (2'6" x 6'8") | E44: 170.35 | F44: 147.35 | H44: =F44/E44 -> 0.86498386
A45: 32" x 80" | C45: (2'8" x 6'8") | E45: 173.15 | F45: 149.75 | H45: =F45/E45 -> 0.86485706
A46: 34" x 80" | C46: (2'10" x 6'8") | E46: 177.15 | F46: 153.25 | H46: =F46/E46 -> 0.86508609
A47: 36" x 80" | C47: (3'0" x 6'8") | E47: 177.15 | F47: 153.25 | H47: =F47/E47 -> 0.86508609
A48: HEIGHT 84" Add | E48: 30.75 | F48: 26.6 | H48: =F48/E48 -> 0.86504065
A49: HEIGHT 96" Add | E49: 85.35 | F49: 73.85 | H49: =F49/E49 -> 0.86526069

Sheet Primed Hardboard
A1: PRICE LIST
A2: ='Moulded Panel'!A2 -> NET PRICE LIST (April 4, 2025)
A3: ='Moulded Panel'!A3 -> SEXTON WEST
A5: PRIMED HARDBOARD
A12: Slab | B12: 6'8", 7'0", 8'0"
A13: Bifold | B13: 6'8", 7'0", 8'0"
A15: Size | E15: List qty (1 to 1099) | F15: List qty (1100)
A16: Slab 1 3/8 hollow core
A17: 12" x 80" | C17: (1'0" x 6'8") | E17: 59.75 | F17: 51.7 | H17: =F17/E17 -> 0.86527197
A18: 14" x 80" | C18: (1'2" x 6'8") | E18: 59.75 | F18: 51.7 | H18: =F18/E18 -> 0.86527197
A19: 16" x 80" | C19: (1'4" x 6'8") | E19: 59.75 | F19: 51.7 | H19: =F19/E19 -> 0.86527197
A20: 18" x 80" | C20: (1'6" x 6'8") | E20: 59.75 | F20: 51.7 | H20: =F20/E20 -> 0.86527197
A21: 20" x 80" | C21: (1'8" x 6'8") | E21: 61 | F21: 52.75 | H21: =F21/E21 -> 0.8647541
A22: 22" x 80" | C22: (1'10" x 6'8") | E22: 61 | F22: 52.75 | H22: =F22/E22 -> 0.8647541
A23: 24" x 80" | C23: (2'0" x 6'8") | E23: 61 | F23: 52.75 | H23: =F23/E23 -> 0.8647541
A24: 26" x 80" | C24: (2'2" x 6'8") | E24: 65.1 | F24: 56.3 | H24: =F24/E24 -> 0.86482335
A25: 28" x 80" | C25: (2'4" x 6'8") | E25: 65.1 | F25: 56.3 | H25: =F25/E25 -> 0.86482335
A26: 30" x 80" | C26: (2'6" x 6'8") | E26: 65.1 | F26: 56.3 | H26: =F26/E26 -> 0.86482335
A27: 32" x 80" | C27: (2'8" x 6'8") | E27: 67.25 | F27: 58.15 | H27: =F27/E27 -> 0.86468401
A28: 34" x 80" | C28: (2'10" x 6'8") | E28: 72.8 | F28: 62.95 | H28: =F28/E28 -> 0.8646978
... A30: 38" x 80" | C30: (3'2" x 6'8") | E30: 105.3 | F30: 91.1 | H30: =F30/E30 -> 0.8651472
A31: HEIGHT 84" Add | E31: 30.75 | F31: 26.6 | H31: =F31/E31 -> 0.86504065 | I31: 30.75 | J31: =I31*0.865 -> 26.59875
A32: HEIGHT 96" Add | E32: 73.15 | F32: 63.25 | H32: =F32/E32 -> 0.86466165 | I32: 73.15 | J32: =I32*0.865 -> 63.27475
A33: Bifold 1 3/8 c/w hardware
A34: 18" x 80" | C34: (1'6" x 6'8") | E34: 83.4 | F34: 72.15 | H34: =F34/E34 -> 0.86510791
A35: 20" x 80" | C35: (1'8" x 6'8") | E35: 83.4 | F35: 72.15 | H35: =F35/E35 -> 0.86510791
A36: 22" x 80" | C36: (1'10" x 6'8") | E36: 83.4 | F36: 72.15 | H36: =F36/E36 -> 0.86510791
A37: 24" x 80" | C37: (2'0" x 6'8") | E37: 83.4 | F37: 72.15 | H37: =F37/E37 -> 0.86510791
A38: 26" x 80" | C38: (2'2" x 6'8") | E38: 90.6 | F38: 78.35 | H38: =F38/E38 -> 0.86479029
A39: 28" x 80" | C39: (2'4" x 6'8") | E39: 90.6 | F39: 78.35 | H39: =F39/E39 -> 0.86479029
A40: 30" x 80" | C40: (2'6" x 6'8") | E40: 90.6 | F40: 78.35 | H40: =F40/E40 -> 0.86479029
A41: 32" x 80" | C41: (2'8" x 6'8") | E41: 96.95 | F41: 83.85 | H41: =F41/E41 -> 0.8648788
A42: 34" x 80" | C42: (2'10" x 6'8") | E42: 96.95 | F42: 83.85 | H42: =F42/E42 -> 0.8648788
A43: 36" x 80" | C43: (3'0" x 6'8") | E43: 96.95 | F43: 83.85 | H43: =F43/E43 -> 0.8648788
A44: HEIGHT 84" Add | E44: 30.75 | F44: 26.6 | H44: =F44/E44 -> 0.86504065
A45: HEIGHT 96" Add | E45: 73.15 | F45: 63.25 | H45: =F45/E45 -> 0.86466165
A46: Slab 1 3/8 solid core (Procore)
A47: 12" x 80" | C47: (1'0" x 6'8") | E47: 124.95 | F47: 108.1 | H47: =F47/E47 -> 0.86514606
A48: 14" x 80" | C48: (1'2" x 6'8") | E48: 124.95 | F48: 108.1 | H48: =F48/E48 -> 0.86514606
A49: 16" x 80" | C49: (1'4" x 6'8") | E49: 124.95 | F49: 108.1 | H49: =F49/E49 -> 0.86514606
...

Sheet Primed Hardboard (2)
A1: PRICE LIST
A2: ='Moulded Panel'!A2 -> NET PRICE LIST (April 4, 2025)
A3: ='Moulded Panel'!A3 -> SEXTON WEST
A5: PRIMED HARDBOARD
A12: Slab | B12: 6'8", 7'0", 8'0"
A13: Bifold | B13: 6'8", 7'0", 8'0"
A15: Size | E15: List qty (1 to 1099) | F15: List qty (1100)
A16: Slab 1 3/4 hollow core
A17: 12" x 80" | C17: (1'0" x 6'8") | E17: 90.5 | F17: 78.3 | H17: =F17/E17 -> 0.86519337
A18: 14" x 80" | C18: (1'2" x 6'8") | E18: 90.5 | F18: 78.3 | H18: =F18/E18 -> 0.86519337
A19: 16" x 80" | C19: (1'4" x 6'8") | E19: 90.5 | F19: 78.3 | H19: =F19/E19 -> 0.86519337
A20: 18" x 80" | C20: (1'6" x 6'8") | E20: 90.5 | F20: 78.3 | H20: =F20/E20 -> 0.86519337
A21: 20" x 80" | C21: (1'8" x 6'8") | E21: 91.75 | F21: 79.35 | H21: =F21/E21 -> 0.86485014
A22: 22" x 80" | C22: (1'10" x 6'8") | E22: 91.75 | F22: 79.35 | H22: =F22/E22 -> 0.86485014
A23: 24" x 80" | C23: (2'0" x 6'8") | E23: 91.75 | F23: 79.35 | H23: =F23/E23 -> 0.86485014
A24: 26" x 80" | C24: (2'2" x 6'8") | E24: 95.85 | F24: 82.9 | H24: =F24/E24 -> 0.86489306
A25: 28" x 80" | C25: (2'4" x 6'8") | E25: 95.85 | F25: 82.9 | H25: =F25/E25 -> 0.86489306
A26: 30" x 80" | C26: (2'6" x 6'8") | E26: 95.85 | F26: 82.9 | H26: =F26/E26 -> 0.86489306
A27: 32" x 80" | C27: (2'8" x 6'8") | E27: 98 | F27: 84.75 | H27: =F27/E27 -> 0.86479592
A28: 34" x 80" | C28: (2'10" x 6'8") | E28: 103.55 | F28: 89.55 | H28: =F28/E28 -> 0.86479961
A29: 36" x 80" | C29: (3'0" x 6'8") | E29: 103.55 | F29: 89.55 | H29: =F29/E29 -> 0.86479961
A30: HEIGHT 84" Add | E30: 5.8 | F30: 5 | H30: =F30/E30 -> 0.86206897 | I30: 5.8 | J30: =I30*0.865 -> 5.017
A31: Slab 1 3/4 solid core
A32: 12" x 80" | C32: (1'0" x 6'8") | E32: 145.1 | F32: 125.5 | H32: =F32/E32 -> 0.86492074
A33: 14" x 80" | C33: (1'2" x 6'8") | E33: 145.1 | F33: 125.5 | H33: =F33/E33 -> 0.86492074
A34: 16" x 80" | C34: (1'4" x 6'8") | E34: 145.1 | F34: 125.5 | H34: =F34/E34 -> 0.86492074
A35: 18" x 80" | C35: (1'6" x 6'8") | E35: 145.1 | F35: 125.5 | H35: =F35/E35 -> 0.86492074
A36: 20" x 80" | C36: (1'8" x 6'8") | E36: 146.35 | F36: 126.6 | H36: =F36/E36 -> 0.86504954
A37: 22" x 80" | C37: (1'10" x 6'8") | E37: 146.35 | F37: 126.6 | H37: =F37/E37 -> 0.86504954
A38: 24" x 80" | C38: (2'0" x 6'8") | E38: 146.35 | F38: 126.6 | H38: =F38/E38 -> 0.86504954
A39: 26" x 80" | C39: (2'2" x 6'8") | E39: 150.45 | F39: 130.15 | H39: =F39/E39 -> 0.86507145
A40: 28" x 80" | C40: (2'4" x 6'8") | E40: 150.45 | F40: 130.15 | H40: =F40/E40 -> 0.86507145
A41: 30" x 80" | C41: (2'6" x 6'8") | E41: 150.45 | F41: 130.15 | H41: =F41/E41 -> 0.86507145
A42: 32" x 80" | C42: (2'8" x 6'8") | E42: 152.6 | F42: 132 | H42: =F42/E42 -> 0.86500655
A43: 34" x 80" | C43: (2'10" x 6'8") | E43: 158.15 | F43: 136.8 | H43: =F43/E43 -> 0.86500158
... A45: 38" x 80" | C45: (3'2" x 6'8") | E45: 190.65 | F45: 164.9 | H45: =F45/E45 -> 0.86493575
A46: HEIGHT 84" Add | E46: 19.1 | F46: 16.5 | H46: =F46/E46 -> 0.86387435 | I46: 19.1 | J46: =I46*0.865 -> 16.5215
A47: HEIGHT 96" Add | E47: 61.5 | F47: 53.2 | H47: =F47/E47 -> 0.86504065 | I47: 61.5 | J47: =I47*0.865 -> 53.1975

Sheet Primed Hardboard (3)
A1: PRICE LIST
A2: ='Moulded Panel'!A2 -> NET PRICE LIST (April 4, 2025)
A3: ='Moulded Panel'!A3 -> SEXTON WEST
A5: PRIMED HARDBOARD
A12: Slab | B12: 6'8", 7'0", 8'0"
A13: Bifold | B13: 6'8", 7'0", 8'0"
A15: Size | E15: List qty (1 to 1099) | F15: List qty (1100)
A16: 1 3/8" HC Easy-Install FJ Pine 4 9/16 x 9/16 (KD Unit)
A17: 12" x 80" | C17: (1'0" x 6'8") | E17: 125.45 | F17: 108.5 | H17: =F17/E17 -> 0.86488641
A18: 14" x 80" | C18: (1'2" x 6'8") | E18: 125.45 | F18: 108.5 | H18: =F18/E18 -> 0.86488641
A19: 16" x 80" | C19: (1'4" x 6'8") | E19: 125.45 | F19: 108.5 | H19: =F19/E19 -> 0.86488641
A20: 18" x 80" | C20: (1'6" x 6'8") | E20: 125.45 | F20: 108.5 | H20: =F20/E20 -> 0.86488641
A21: 20" x 80" | C21: (1'8" x 6'8") | E21: 126.7 | F21: 109.6 | H21: =F21/E21 -> 0.86503552
A22: 22" x 80" | C22: (1'10" x 6'8") | E22: 126.7 | F22: 109.6 | H22: =F22/E22 -> 0.86503552
A23: 24" x 80" | C23: (2'0" x 6'8") | E23: 126.7 | F23: 109.6 | H23: =F23/E23 -> 0.86503552
A24: 26" x 80" | C24: (2'2" x 6'8") | E24: 130.8 | F24: 113.15 | H24: =F24/E24 -> 0.86506116
A25: 28" x 80" | C25: (2'4" x 6'8") | E25: 130.8 | F25: 113.15 | H25: =F25/E25 -> 0.86506116
A26: 30" x 80" | C26: (2'6" x 6'8") | E26: 130.8 | F26: 113.15 | H26: =F26/E26 -> 0.86506116
A27: 32" x 80" | C27: (2'8" x 6'8") | E27: 132.95 | F27: 115 | H27: =F27/E27 -> 0.86498684
A28: 34" x 80" | C28: (2'10" x 6'8") | E28: 138.5 | F28: 119.8 | H28: =F28/E28 -> 0.86498195
A29: 36" x 80" | C29: (3'0" x 6'8") | E29: 138.5 | F29: 119.8 | H29: =F29/E29 -> 0.86498195
A30: HEIGHT 84" Add | E30: 30.75 | F30: 26.6 | H30: =F30/E30 -> 0.86504065
A31: HEIGHT 96" Add | E31: 73.15 | F31: 63.25 | H31: =F31/E31 -> 0.86466165
A32: 1 3/8" HC Prehung FJ Primed 4 5/8 x 11/16 (assembled unit)
A33: 12" x 80" | C33: (1'0" x 6'8") | E33: 139.25 | F33: 120.45 | H33: =F33/E33 -> 0.86499102
A34: 14" x 80" | C34: (1'2" x 6'8") | E34: 139.25 | F34: 120.45 | H34: =F34/E34 -> 0.86499102
A35: 16" x 80" | C35: (1'4" x 6'8") | E35: 139.25 | F35: 120.45 | H35: =F35/E35 -> 0.86499102
A36: 18" x 80" | C36: (1'6" x 6'8") | E36: 139.25 | F36: 120.45 | H36: =F36/E36 -> 0.86499102
A37: 20" x 80" | C37: (1'8" x 6'8") | E37: 140.5 | F37: 121.55 | H37: =F37/E37 -> 0.86512456
A38: 22" x 80" | C38: (1'10" x 6'8") | E38: 140.5 | F38: 121.55 | H38: =F38/E38 -> 0.86512456
A39: 24" x 80" | C39: (2'0" x 6'8") | E39: 140.5 | F39: 121.55 | H39: =F39/E39 -> 0.86512456
A40: 26" x 80" | C40: (2'2" x 6'8") | E40: 144.6 | F40: 125.1 | H40: =F40/E40 -> 0.86514523
A41: 28" x 80" | C41: (2'4" x 6'8") | E41: 144.6 | F41: 125.1 | H41: =F41/E41 -> 0.86514523
A42: 30" x 80" | C42: (2'6" x 6'8") | E42: 144.6 | F42: 125.1 | H42: =F42/E42 -> 0.86514523
A43: 32" x 80" | C43: (2'8" x 6'8") | E43: 146.75 | F43: 126.95 | H43: =F43/E43 -> 0.86507666
A44: 34" x 80" | C44: (2'10" x 6'8") | E44: 152.3 | F44: 131.75 | H44: =F44/E44 -> 0.86506894
A45: 36" x 80" | C45: (3'0" x 6'8") | E45: 152.3 | F45: 131.75 | H45: =F45/E45 -> 0.86506894
A46: HEIGHT 84" Add | E46: 30.75 | F46: 26.6 | H46: =F46/E46 -> 0.86504065
A47: HEIGHT 96" Add | E47: 73.15 | F47: 63.25 | H47: =F47/E47 -> 0.86466165

Sheet Adders
A4: Adders | B4: Sexton Ontario (1 to 1099) | C4: Sexton Ontario TL
A5: Additional Options
A6: Machining 2 or 3 hinges & cyl. Lock (1 3/8) | B6: 9.55 | C6: 8.25 | D6: =C6/B6 -> 0.86387435
A7: Machining 3 hinges & cyl. Lock (1 3/4) | B7: 30.2 | C7: 26.1 | D7: =C7/B7 -> 0.86423841
A8: Machining 3 hinges & cyl. Lock (1 3/4) for 20 min | B8: 33.15 | C8: 28.65 | D8: =C8/B8 -> 0.86425339
A9: 45 Min Fire Rated Flush (includes prep for 3 hinges & cyl lock) | B9: 320.1 | C9: 276.9 | D9: =C9/B9 -> 0.86504217
A10: 45 Min Fire Rated Moulded (includes prep for 3 hinges & cyl lock) | B10: 473.8 | C10: 409.85 | D10: =C10/B10 -> 0.86502744
A11: 60 - 90 Min Fire Rated Flush (includes prep for 3 hinges & cyl lock) | B11: 432.5 | C11: 374.1 | D11: =C11/B11 -> 0.8649711
A12: Machining lock 1 side for slider | B12: 7.6 | C12: 6.55 | D12: =C12/B12 -> 0.86184211
A13: Jamb Add-ons: add to Hollow Core or Solid Core Slabs
A14: 4-9/16" MDF jamb for an Easy IN | B14: 65.7 | C14: 56.85 | D14: =C14/B14 -> 0.8652968
A15: 6-9/16" MDF jamb for an Easy IN | B15: 78.45 | C15: 67.85 | D15: =C15/B15 -> 0.86488209
A16: 4-9/16" FJP jamb for Easy IN | B16: 79.5 | C16: 68.75 | D16: =C16/B16 -> 0.86477987
A17: 6-9/16" FJP jamb for Easy IN | B17: 92.75 | C17: 80.25 | D17: =C17/B17 -> 0.86522911
A18: 4-9/16" FJ Primed for Prehung | B18: 79.5 | C18: 68.75 | D18: =C18/B18 -> 0.86477987
A19: 4-9/16" FJP jamb Rabbeted Prehung | B19: 79.5 | C19: 68.75 | D19: =C19/B19 -> 0.86477987
A20: 6-9/16" FJP jamb Rabbeted Prehung | B20: 92.5 | C20: 80 | D20: =C20/B20 -> 0.86486486
A21: Options
A22: Hinge Finish | B22: 9 | C22: 7.8 | D22: =C22/B22 -> 0.86666667
A23: Ball Catch | B23: 21.2 | C23: 18.35 | D23: =C23/B23 -> 0.86556604
A24: Flush Bolt | B24: 21.2 | C24: 18.35 | D24: =C24/B24 -> 0.86556604
A25: BB Hinges | B25: 21.2 | C25: 18.35 | D25: =C25/B25 -> 0.86556604
A26: Double Door = (EASY-IN x 2) + Flushbolt or Ball Catches | B26: 21.2 | C26: 18.35 | D26: =C26/B26 -> 0.86556604
A27: Non-Standard Charge | B27: 79.5 | C27: 68.75 | D27: =C27/B27 -> 0.86477987
A28: (20 of the same size/style or more=$0.00)
A31: Regional Freight Rates Apply

Sheet Door Availability
D2: Willmar
A3: Doors - sizes available
A4: modèle / model | C4: 12'' | D4: 14'' | E4: 16'' | F4: 18'' | G4: 20'' | H4: 22'' | I4: 24'' | J4: 26'' | K4: 28'' | L4: 30'' | M4: 32'' | N4: 34'' | O4: 36''
A5: BIRKDALE | B5: 80'' | C5: X | D5: X | E5: X | F5: X | G5: X | H5: X | I5: X | J5: X | K5: X | L5: X | M5: X | N5: X | O5: X
B6: 84'' | E6: X | F6: X | G6: X | H6: X | I6: X | J6: X | K6: X | L6: X | M6: X | N6: X | O6: X
B7: 96'' | E7: X | F7: X | G7: X | H7: X | I7: X | J7: X | K7: X | L7: X | M7: X | N7: X | O7: X
A8: CAMDEN | B8: 80'' | C8: X | D8: X | E8: X | F8: X | G8: X | H8: X | I8: X | J8: X | K8: X | L8: X | M8: X | N8: X | O8: X
B9: 84''
B10: 96''
A11: CARRARA | B11: 80'' | C11: X | D11: X | E11: X | F11: X | G11: X | H11: X | I11: X | J11: X | K11: X | L11: X | M11: X | N11: X | O11: X
B12: 84'' | C12: X | D12: X | E12: X | F12: X | G12: X | H12: X | I12: X | J12: X | K12: X | L12: X | M12: X | N12: X | O12: X
B13: 96'' | E13: X | F13: X | G13: X | H13: X | I13: X | J13: X | K13: X | L13: X | M13: X | N13: X | O13: X
A14: COLONIST TEXT | B14: 80'' | C14: X | D14: X | E14: X | F14: X | G14: X | H14: X | I14: X | J14: X | K14: X | L14: X | M14: X | N14: X | O14: X
B15: 84'' | C15: X | D15: X | E15: X | F15: X | G15: X | H15: X | I15: X | J15: X | K15: X | L15: X | M15: X | N15: X | O15: X
B16: 96'' | E16: X | F16: X | G16: X | H16: X | I16: X | J16: X | K16: X | L16: X | M16: X | N16: X | O16: X
A17: CONMORE | B17: 80'' | C17: X | D17: X | E17: X | F17: X | G17: X | H17: X | I17: X | J17: X | K17: X | L17: X | M17: X | N17: X | O17: X
B18: 84'' | C18: X | D18: X | E18: X | F18: X | G18: X | H18: X | I18: X | J18: X | K18: X | L18: X | M18: X | N18: X | O18: X
B19: 96'' | E19: X | F19: X | G19: X | H19: X | I19: X | J19: X | K19: X | L19: X | M19: X | N19: X | O19: X
A20: CRAFTSMAN | B20: 80'' | C20: X | D20: X | E20: X | F20: X | G20: X | H20: X | I20: X | J20: X | K20: X | L20: X | M20: X | N20: X | O20: X
B21: 84'' | C21: X | D21: X | E21: X | F21: X | G21: X | H21: X | I21: X | J21: X | K21: X | L21: X | M21: X | N21: X | O21: X
B22: 96''
A23: MADISON | B23: 80'' | C23: X | D23: X | E23: X | F23: X | G23: X | H23: X | I23: X | J23: X | K23: X | L23: X | M23: X | N23: X | O23: X
B24: 84'' | C24: X | D24: X | E24: X | F24: X | G24: X | H24: X | I24: X | J24: X | K24: X | L24: X | M24: X | N24: X | O24: X
B25: 96'' | E25: X | F25: X | G25: X | H25: X | I25: X | J25: X | K25: X | L25: X | M25: X | N25: X | O25: X
A26: MONROE | B26: 80'' | C26: X | D26: X | E26: X | F26: X | G26: X | H26: X | I26: X | J26: X | K26: X | L26: X | M26: X | N26: X | O26: X
B27: 84'' | C27: X | D27: X | E27: X | F27: X | G27: X | H27: X | I27: X | J27: X | K27: X | L27: X | M27: X | N27: X | O27: X
B28: 96'' | E28: X | F28: X | G28: X | H28: X | I28: X | J28: X | K28: X | L28: X | M28: X | N28: X | O28: X
A29: ROCKPORT | B29: 80'' | C29: X | D29: X | E29: X | F29: X | G29: X | H29: X | I29: X | J29: X | K29: X | L29: X | M29: X | N29: X | O29: X
B30: 84'' | E30: X | F30: X | G30: X | H30: X | I30: X | J30: X | K30: X | L30: X | M30: X | N30: X | O30: X
B31: 96'' | E31: X | F31: X | G31: X | H31: X | I31: X | J31: X | K31: X | L31: X | M31: X | N31: X | O31: X
A32: SANTA FE | B32: 80'' | C32: X | D32: X | E32: X | F32: X | G32: X | H32: X | I32: X | J32: X | K32: X | L32: X | M32: X | N32: X | O32: X
B33: 84'' | F33: X | G33: X | H33: X | I33: X | J33: X | K33: X | L33: X | M33: X | N33: X | O33: X
B34: 96'' | E34: X | F34: X | G34: X | H34: X | I34: X | J34: X | K34: X | L34: X | M34: X | N34: X | O34: X
C35: Non disponible / Not Available size
B36: x | C36: Disponible / Available
C41: notes internes
A43: 43174 | C43: ajot AVA 84'' x 18 à 36 incl, contl 16x84, rock 16x84''
A44: 43047 | C44: ajout carrara 80 84 96'', contl 28 et 32x96 , de 4 a 5, ajout coventry 84 et 96
A45: 42480 | C45: Avalon 26- de cmi à skin JW ( batt de 5,3/16 à 3,3/16)
A46: 42480 | C46: ajout Monroe, enlevé atherton ( Kathya ) , enlevé avalon 84'' ( Kathya )
...

Sheet Bifold Availability
D2: St-Henri, QC
A3: Bifolds - sizes available
B4: modèle / model | D4: 18'' | E4: 20'' | F4: 22'' | G4: 24'' | H4: 26'' | I4: 28'' | J4: 30'' | K4: 32'' | L4: 34'' | M4: 36''
B5: BIRKDALE | C5: 79'' | G5: X | H5: X | I5: X | J5: X | K5: X | L5: X | M5: X
C6: 84'' | G6: X | H6: X | I6: X | J6: X | K6: X | L6: X | M6: X
C7: 96''
B8: CAMDEN | C8: 79'' | D8: X | E8: X | F8: X | G8: X | H8: X | I8: X | J8: X | K8: X | L8: X | M8: X
C9: 84''
C10: 96''
B11: CARRARA | C11: 79'' | D11: X | E11: X | F11: X | G11: X | H11: X | I11: X | J11: X | K11: X | L11: X | M11: X
C12: 84'' | D12: X | E12: X | F12: X | G12: X | H12: X | I12: X | J12: X | K12: X | L12: X | M12: X
C13: 96'' | J13: X | K13: X | L13: X | M13: X
B14: COLONIST TEXT | C14: 79'' | D14: X | E14: X | F14: X | G14: X | H14: X | I14: X | J14: X | K14: X | L14: X | M14: X
C15: 84'' | D15: X | E15: X | F15: X | G15: X | H15: X | I15: X | J15: X | K15: X | L15: X | M15: X
C16: 96'' | J16: X | K16: X | L16: X | M16: X
B17: CONMORE | C17: 79'' | D17: X | E17: X | F17: X | G17: X | H17: X | I17: X | J17: X | K17: X | L17: X | M17: X
C18: 84'' | D18: X | E18: X | F18: X | G18: X | H18: X | I18: X | J18: X | K18: X | L18: X | M18: X
C19: 96''
B20: CRAFTSMAN | C20: 79'' | F20: X | G20: X | H20: X | I20: X | J20: X | K20: X | L20: X | M20: X
C21: 84'' | F21: X | G21: X | H21: X | I21: X | J21: X | K21: X | L21: X | M21: X
C22: 96''
B23: MADISON | C23: 79'' | F23: X | G23: X | H23: X | I23: X | J23: X | K23: X | L23: X | M23: X
C24: 84'' | F24: X | G24: X | H24: X | I24: X | J24: X | K24: X | L24: X | M24: X
C25: 96'' | J25: X | K25: X | L25: X | M25: X
B26: MONROE | C26: 79'' | F26: X | G26: X | H26: X | I26: X | J26: X | K26: X | L26: X | M26: X
C27: 84'' | F27: X | G27: X | H27: X | I27: X | J27: X | K27: X | L27: X | M27: X
C28: 96'' | J28: X | K28: X | L28: X | M28: X
B29: ROCKPORT | C29: 79'' | D29: X | E29: X | F29: X | G29: X | H29: X | I29: X | J29: X | K29: X | L29: X | M29: X
C30: 84'' | J30: X | K30: X | L30: X | M30: X
C31: 96'' | J31: X | K31: X | L31: X | M31: X
B32: SANTA FE | C32: 79'' | D32: X | E32: X | F32: X | G32: X | H32: X | I32: X | J32: X | K32: X | L32: X | M32: X
C33: 84'' | J33: X | K33: X | L33: X | M33: X
C34: 96'' | J34: X | K34: X | L34: X | M34: X
D35: Non disponible / Not Available
C36: x | D36: Disponible / Available
B43: 43174
B44: 43047
B45: 42480
B46: 42480
B47: 42376
...
